Workbook
Name Louisa_wConduits_Risk_Table_wPipes_Nominal_Flow: InstallDate!$A$1:$BF$389

Sheet Louisa_wConduits_Input_CSV
A1: OBJECTID | B1: MOID | C1: MOTYPE | D1: SELCODE | E1: DSPCODE | F1: UDFTYPE | G1: LDMTYPE | H1: ID | I1: DESCRIPT | J1: YR_INST | K1: YR_RETIRE | L1: ZONE | M1: MATERIAL | N1: LINING | O1: COST_ID | P1: PHASE | Q1: ID_1 | R1: LENGTH | S1: DIAMETER | T1: ROUGHNESS | U1: MINORLOSS | V1: TOTALIZER | W1: CHK_VALVE | X1: ID_12 | Y1: DIRECTION | Z1: RUN_DIAM | AA1: RUN_LENGTH | AB1: RUN_ROUGH | AC1: FLOW | AD1: VELOCITY | AE1: HEADLOSS | AF1: HL1000 | AG1: STATUS | AH1: MAX_FLOW | AI1: MIN_FLOW | AJ1: AVE_FLOW | AK1: MAX_VELOC | AL1: MIN_VELOC | AM1: AVE_VELOC | AN1: MAX_HDLOSS | AO1: MIN_HDLOSS | AP1: AVE_HDLOSS | AQ1: SHAPE_Length | AR1: Crtical_Xing | AS1: Critical_Pipe | AT1: Critical_final | AU1: Hyd Risk | AV1: =0.9 -> 0.9 | AW1: 0.78 | AX1: 0.5 | AY1: 0.1625 | AZ1: Risk_Label
A2: 1 | B2: P787 | C2: 0 | H2: P787 | I2: Ductile Iron | Q2: P787 | R2: 49.271155 | S2: 6 | T2: 130 | V2: 0 | W2: 0 | X2: P787 | Y2: 0 | Z2: 6 | AA2: 49.27 | AB2: 130 | AC2: 0 | AD2: 0 | AE2: 0 | AF2: 0 | AG2: 1 | AH2: 0 | AI2: 0 | AJ2: 0 | AK2: 0 | AL2: 0 | AM2: 0 | AN2: 0 | AO2: 0 | AP2: 0 | AQ2: 49.271155 | AR2: 0 | AS2: =_xlfn.XLOOKUP(B2,InstallDate!$H$2:$H$389,InstallDate!$BE$2:$BE$389) -> 0 | AT2: =IF(COUNTIF(AR2:AS2,1)=0,0,SUM(AR2:AS2)/COUNTIF(AR2:AS2,1)) -> 0 | AU2: =AC2/MAX($AC$2:$AC$389) -> 0 | AV2: =IF($AU2>=_xlfn.PERCENTILE.INC($AU$2:$AU$369,AV$1),4,0) -> 0 | AW2: =IF($AU2>=_xlfn.PERCENTILE.INC($AU$2:$AU$369,AW$1),3,0) -> 0 | AX2: =IF($AU2>=_xlfn.PERCENTILE.INC($AU$2:$AU$369,AX$1),2,0) -> 0 | AY2: =IF(SUM(AV2:AX2)<1,1,0) -> 1 | AZ2: =IF(AND(MAX(AV2:AY2)>2,AS2=1),3,IF(AND(MAX(AV2:AY2)<=2,AS2=1),2,IF(AND(MAX(AV2:AY2)>1,AS2=0),2,1))) -> 1
A3: 2 | B3: P789 | C3: 0 | H3: P789 | I3: Ductile Iron | Q3: P789 | R3: 37.541067 | S3: 6 | T3: 130 | V3: 0 | W3: 0 | X3: P789 | Y3: 0 | Z3: 6 | AA3: 37.54 | AB3: 130 | AC3: 0 | AD3: 0 | AE3: 0 | AF3: 0 | AG3: 1 | AH3: 0 | AI3: 0 | AJ3: 0 | AK3: 0 | AL3: 0 | AM3: 0 | AN3: 0 | AO3: 0 | AP3: 0 | AQ3: 37.541067 | AR3: 0 | AS3: =_xlfn.XLOOKUP(B3,InstallDate!$H$2:$H$389,InstallDate!$BE$2:$BE$389) -> 0 | AT3: =IF(COUNTIF(AR3:AS3,1)=0,0,SUM(AR3:AS3)/COUNTIF(AR3:AS3,1)) -> 0 | AU3: =AC3/MAX($AC$2:$AC$389) -> 0 | AV3: =IF($AU3>=_xlfn.PERCENTILE.INC($AU$2:$AU$369,AV$1),4,0) -> 0 | AW3: =IF($AU3>=_xlfn.PERCENTILE.INC($AU$2:$AU$369,AW$1),3,0) -> 0 | AX3: =IF($AU3>=_xlfn.PERCENTILE.INC($AU$2:$AU$369,AX$1),2,0) -> 0 | AY3: =IF(SUM(AV3:AX3)<1,1,0) -> 1 | AZ3: =IF(AND(MAX(AV3:AY3)>2,AS3=1),3,IF(AND(MAX(AV3:AY3)<=2,AS3=1),2,IF(AND(MAX(AV3:AY3)>1,AS3=0),2,1))) -> 1 | BF3: 0 | BG3: 1
A4: 3 | B4: P791 | C4: 0 | H4: P791 | I4: Ductile Iron | Q4: P791 | R4: 22.046684 | S4: 6 | T4: 130 | V4: 0 | W4: 0 | X4: P791 | Y4: 0 | Z4: 6 | AA4: 22.05 | AB4: 130 | AC4: 0 | AD4: 0 | AE4: 0 | AF4: 0 | AG4: 1 | AH4: 0 | AI4: 0 | AJ4: 0 | AK4: 0 | AL4: 0 | AM4: 0 | AN4: 0 | AO4: 0 | AP4: 0 | AQ4: 22.046684 | AR4: 0 | AS4: =_xlfn.XLOOKUP(B4,InstallDate!$H$2:$H$389,InstallDate!$BE$2:$BE$389) -> 0 | AT4: =IF(COUNTIF(AR4:AS4,1)=0,0,SUM(AR4:AS4)/COUNTIF(AR4:AS4,1)) -> 0 | AU4: =AC4/MAX($AC$2:$AC$389) -> 0 | AV4: =IF($AU4>=_xlfn.PERCENTILE.INC($AU$2:$AU$369,AV$1),4,0) -> 0 | AW4: =IF($AU4>=_xlfn.PERCENTILE.INC($AU$2:$AU$369,AW$1),3,0) -> 0 | AX4: =IF($AU4>=_xlfn.PERCENTILE.INC($AU$2:$AU$369,AX$1),2,0) -> 0 | AY4: =IF(SUM(AV4:AX4)<1,1,0) -> 1 | AZ4: =IF(AND(MAX(AV4:AY4)>2,AS4=1),3,IF(AND(MAX(AV4:AY4)<=2,AS4=1),2,IF(AND(MAX(AV4:AY4)>1,AS4=0),2,1))) -> 1 | BG4: =COUNTIF($AZ$2:$AZ$389,3) -> 45 | BH4: =0.9 -> 0.9
A5: 4 | B5: P793 | C5: 0 | H5: P793 | I5: Ductile Iron | Q5: P793 | R5: 25.52698 | S5: 6 | T5: 130 | V5: 0 | W5: 0 | X5: P793 | Y5: 0 | Z5: 6 | AA5: 25.53 | AB5: 130 | AC5: 0 | AD5: 0 | AE5: 0 | AF5: 0 | AG5: 1 | AH5: 0 | AI5: 0 | AJ5: 0 | AK5: 0 | AL5: 0 | AM5: 0 | AN5: 0 | AO5: 0 | AP5: 0 | AQ5: 25.52698 | AR5: 0 | AS5: =_xlfn.XLOOKUP(B5,InstallDate!$H$2:$H$389,InstallDate!$BE$2:$BE$389) -> 0 | AT5: =IF(COUNTIF(AR5:AS5,1)=0,0,SUM(AR5:AS5)/COUNTIF(AR5:AS5,1)) -> 0 | AU5: =AC5/MAX($AC$2:$AC$389) -> 0 | AV5: =IF($AU5>=_xlfn.PERCENTILE.INC($AU$2:$AU$369,AV$1),4,0) -> 0 | AW5: =IF($AU5>=_xlfn.PERCENTILE.INC($AU$2:$AU$369,AW$1),3,0) -> 0 | AX5: =IF($AU5>=_xlfn.PERCENTILE.INC($AU$2:$AU$369,AX$1),2,0) -> 0 | AY5: =IF(SUM(AV5:AX5)<1,1,0) -> 1 | AZ5: =IF(AND(MAX(AV5:AY5)>2,AS5=1),3,IF(AND(MAX(AV5:AY5)<=2,AS5=1),2,IF(AND(MAX(AV5:AY5)>1,AS5=0),2,1))) -> 1 | BH5: 0.78
A6: 5 | B6: P795 | C6: 0 | H6: P795 | I6: Ductile Iron | Q6: P795 | R6: 30.261047 | S6: 6 | T6: 130 | V6: 0 | W6: 0 | X6: P795 | Y6: 0 | Z6: 6 | AA6: 30.26 | AB6: 130 | AC6: 0 | AD6: 0 | AE6: 0 | AF6: 0 | AG6: 1 | AH6: 0 | AI6: 0 | AJ6: 0 | AK6: 0 | AL6: 0 | AM6: 0 | AN6: 0 | AO6: 0 | AP6: 0 | AQ6: 30.261047 | AR6: 0 | AS6: =_xlfn.XLOOKUP(B6,InstallDate!$H$2:$H$389,InstallDate!$BE$2:$BE$389) -> 0 | AT6: =IF(COUNTIF(AR6:AS6,1)=0,0,SUM(AR6:AS6)/COUNTIF(AR6:AS6,1)) -> 0 | AU6: =AC6/MAX($AC$2:$AC$389) -> 0 | AV6: =IF($AU6>=_xlfn.PERCENTILE.INC($AU$2:$AU$369,AV$1),4,0) -> 0 | AW6: =IF($AU6>=_xlfn.PERCENTILE.INC($AU$2:$AU$369,AW$1),3,0) -> 0 | AX6: =IF($AU6>=_xlfn.PERCENTILE.INC($AU$2:$AU$369,AX$1),2,0) -> 0 | AY6: =IF(SUM(AV6:AX6)<1,1,0) -> 1 | AZ6: =IF(AND(MAX(AV6:AY6)>2,AS6=1),3,IF(AND(MAX(AV6:AY6)<=2,AS6=1),2,IF(AND(MAX(AV6:AY6)>1,AS6=0),2,1))) -> 1 | BG6: =COUNTIF($AZ$2:$AZ$389,2) -> 173 | BH6: 0.5
A7: 6 | B7: P797 | C7: 0 | H7: P797 | I7: Ductile Iron | Q7: P797 | R7: 28.800563 | S7: 6 | T7: 130 | V7: 0 | W7: 0 | X7: P797 | Y7: 0 | Z7: 6 | AA7: 28.8 | AB7: 130 | AC7: 0 | AD7: 0 | AE7: 0 | AF7: 0 | AG7: 1 | AH7: 0 | AI7: 0 | AJ7: 0 | AK7: 0 | AL7: 0 | AM7: 0 | AN7: 0 | AO7: 0 | AP7: 0 | AQ7: 28.800563 | AR7: 0 | AS7: =_xlfn.XLOOKUP(B7,InstallDate!$H$2:$H$389,InstallDate!$BE$2:$BE$389) -> 0 | AT7: =IF(COUNTIF(AR7:AS7,1)=0,0,SUM(AR7:AS7)/COUNTIF(AR7:AS7,1)) -> 0 | AU7: =AC7/MAX($AC$2:$AC$389) -> 0 | AV7: =IF($AU7>=_xlfn.PERCENTILE.INC($AU$2:$AU$369,AV$1),4,0) -> 0 | AW7: =IF($AU7>=_xlfn.PERCENTILE.INC($AU$2:$AU$369,AW$1),3,0) -> 0 | AX7: =IF($AU7>=_xlfn.PERCENTILE.INC($AU$2:$AU$369,AX$1),2,0) -> 0 | AY7: =IF(SUM(AV7:AX7)<1,1,0) -> 1 | AZ7: =IF(AND(MAX(AV7:AY7)>2,AS7=1),3,IF(AND(MAX(AV7:AY7)<=2,AS7=1),2,IF(AND(MAX(AV7:AY7)>1,AS7=0),2,1))) -> 1 | BG7: =COUNTIF($AZ$2:$AZ$389,1) -> 170 | BH7: 0.1625
A8: 7 | B8: P799 | C8: 0 | H8: P799 | I8: Ductile Iron | Q8: P799 | R8: 29.686093 | S8: 6 | T8: 130 | V8: 0 | W8: 0 | X8: P799 | Y8: 0 | Z8: 6 | AA8: 29.69 | AB8: 130 | AC8: 0 | AD8: 0 | AE8: 0 | AF8: 0 | AG8: 1 | AH8: 0 | AI8: 0 | AJ8: 0 | AK8: 0 | AL8: 0 | AM8: 0 | AN8: 0 | AO8: 0 | AP8: 0 | AQ8: 29.686093 | AR8: 0 | AS8: =_xlfn.XLOOKUP(B8,InstallDate!$H$2:$H$389,InstallDate!$BE$2:$BE$389) -> 0 | AT8: =IF(COUNTIF(AR8:AS8,1)=0,0,SUM(AR8:AS8)/COUNTIF(AR8:AS8,1)) -> 0 | AU8: =AC8/MAX($AC$2:$AC$389) -> 0 | AV8: =IF($AU8>=_xlfn.PERCENTILE.INC($AU$2:$AU$369,AV$1),4,0) -> 0 | AW8: =IF($AU8>=_xlfn.PERCENTILE.INC($AU$2:$AU$369,AW$1),3,0) -> 0 | AX8: =IF($AU8>=_xlfn.PERCENTILE.INC($AU$2:$AU$369,AX$1),2,0) -> 0 | AY8: =IF(SUM(AV8:AX8)<1,1,0) -> 1 | AZ8: =IF(AND(MAX(AV8:AY8)>2,AS8=1),3,IF(AND(MAX(AV8:AY8)<=2,AS8=1),2,IF(AND(MAX(AV8:AY8)>1,AS8=0),2,1))) -> 1 | BG8: =SUM(BG6:BG7) -> 343
A9: 8 | B9: P801 | C9: 0 | H9: P801 | I9: Ductile Iron | Q9: P801 | R9: 23.980235 | S9: 6 | T9: 130 | V9: 0 | W9: 0 | X9: P801 | Y9: 0 | Z9: 6 | AA9: 23.98 | AB9: 130 | AC9: 0 | AD9: 0 | AE9: 0 | AF9: 0 | AG9: 1 | AH9: 0 | AI9: 0 | AJ9: 0 | AK9: 0 | AL9: 0 | AM9: 0 | AN9: 0 | AO9: 0 | AP9: 0 | AQ9: 23.980235 | AR9: 0 | AS9: =_xlfn.XLOOKUP(B9,InstallDate!$H$2:$H$389,InstallDate!$BE$2:$BE$389) -> 0 | AT9: =IF(COUNTIF(AR9:AS9,1)=0,0,SUM(AR9:AS9)/COUNTIF(AR9:AS9,1)) -> 0 | AU9: =AC9/MAX($AC$2:$AC$389) -> 0 | AV9: =IF($AU9>=_xlfn.PERCENTILE.INC($AU$2:$AU$369,AV$1),4,0) -> 0 | AW9: =IF($AU9>=_xlfn.PERCENTILE.INC($AU$2:$AU$369,AW$1),3,0) -> 0 | AX9: =IF($AU9>=_xlfn.PERCENTILE.INC($AU$2:$AU$369,AX$1),2,0) -> 0 | AY9: =IF(SUM(AV9:AX9)<1,1,0) -> 1 | AZ9: =IF(AND(MAX(AV9:AY9)>2,AS9=1),3,IF(AND(MAX(AV9:AY9)<=2,AS9=1),2,IF(AND(MAX(AV9:AY9)>1,AS9=0),2,1))) -> 1
A10: 9 | B10: P803 | C10: 0 | H10: P803 | I10: Ductile Iron | Q10: P803 | R10: 169.1279 | S10: 6 | T10: 130 | V10: 0 | W10: 0 | X10: P803 | Y10: 0 | Z10: 6 | AA10: 169.13 | AB10: 130 | AC10: 0 | AD10: 0 | AE10: 0 | AF10: 0 | AG10: 1 | AH10: 0 | AI10: 0 | AJ10: 0 | AK10: 0 | AL10: 0 | AM10: 0 | AN10: 0 | AO10: 0 | AP10: 0 | AQ10: 169.1279 | AR10: 0 | AS10: =_xlfn.XLOOKUP(B10,InstallDate!$H$2:$H$389,InstallDate!$BE$2:$BE$389) -> 0 | AT10: =IF(COUNTIF(AR10:AS10,1)=0,0,SUM(AR10:AS10)/COUNTIF(AR10:AS10,1)) -> 0 | AU10: =AC10/MAX($AC$2:$AC$389) -> 0 | AV10: =IF($AU10>=_xlfn.PERCENTILE.INC($AU$2:$AU$369,AV$1),4,0) -> 0 | AW10: =IF($AU10>=_xlfn.PERCENTILE.INC($AU$2:$AU$369,AW$1),3,0) -> 0 | AX10: =IF($AU10>=_xlfn.PERCENTILE.INC($AU$2:$AU$369,AX$1),2,0) -> 0 | AY10: =IF(SUM(AV10:AX10)<1,1,0) -> 1 | AZ10: =IF(AND(MAX(AV10:AY10)>2,AS10=1),3,IF(AND(MAX(AV10:AY10)<=2,AS10=1),2,IF(AND(MAX(AV10:AY10)>1,AS10=0),2,1))) -> 1
A11: 10 | B11: P805 | C11: 0 | H11: P805 | I11: Ductile Iron | Q11: P805 | R11: 14.144057 | S11: 6 | T11: 130 | V11: 0 | W11: 0 | X11: P805 | Y11: 0 | Z11: 6 | AA11: 14.14 | AB11: 130 | AC11: 0 | AD11: 0 | AE11: 0 | AF11: 0 | AG11: 1 | AH11: 0 | AI11: 0 | AJ11: 0 | AK11: 0 | AL11: 0 | AM11: 0 | AN11: 0 | AO11: 0 | AP11: 0 | AQ11: 14.144057 | AR11: 0 | AS11: =_xlfn.XLOOKUP(B11,InstallDate!$H$2:$H$389,InstallDate!$BE$2:$BE$389) -> 0 | AT11: =IF(COUNTIF(AR11:AS11,1)=0,0,SUM(AR11:AS11)/COUNTIF(AR11:AS11,1)) -> 0 | AU11: =AC11/MAX($AC$2:$AC$389) -> 0 | AV11: =IF($AU11>=_xlfn.PERCENTILE.INC($AU$2:$AU$369,AV$1),4,0) -> 0 | AW11: =IF($AU11>=_xlfn.PERCENTILE.INC($AU$2:$AU$369,AW$1),3,0) -> 0 | AX11: =IF($AU11>=_xlfn.PERCENTILE.INC($AU$2:$AU$369,AX$1),2,0) -> 0 | AY11: =IF(SUM(AV11:AX11)<1,1,0) -> 1 | AZ11: =IF(AND(MAX(AV11:AY11)>2,AS11=1),3,IF(AND(MAX(AV11:AY11)<=2,AS11=1),2,IF(AND(MAX(AV11:AY11)>1,AS11=0),2,1))) -> 1
A12: 11 | B12: P807 | C12: 0 | H12: P807 | I12: Ductile Iron | Q12: P807 | R12: 23.356306 | S12: 6 | T12: 130 | V12: 0 | W12: 0 | X12: P807 | Y12: 0 | Z12: 6 | AA12: 23.36 | AB12: 130 | AC12: 0 | AD12: 0 | AE12: 0 | AF12: 0 | AG12: 1 | AH12: 0 | AI12: 0 | AJ12: 0 | AK12: 0 | AL12: 0 | AM12: 0 | AN12: 0 | AO12: 0 | AP12: 0 | AQ12: 23.356306 | AR12: 0 | AS12: =_xlfn.XLOOKUP(B12,InstallDate!$H$2:$H$389,InstallDate!$BE$2:$BE$389) -> 0 | AT12: =IF(COUNTIF(AR12:AS12,1)=0,0,SUM(AR12:AS12)/COUNTIF(AR12:AS12,1)) -> 0 | AU12: =AC12/MAX($AC$2:$AC$389) -> 0 | AV12: =IF($AU12>=_xlfn.PERCENTILE.INC($AU$2:$AU$369,AV$1),4,0) -> 0 | AW12: =IF($AU12>=_xlfn.PERCENTILE.INC($AU$2:$AU$369,AW$1),3,0) -> 0 | AX12: =IF($AU12>=_xlfn.PERCENTILE.INC($AU$2:$AU$369,AX$1),2,0) -> 0 | AY12: =IF(SUM(AV12:AX12)<1,1,0) -> 1 | AZ12: =IF(AND(MAX(AV12:AY12)>2,AS12=1),3,IF(AND(MAX(AV12:AY12)<=2,AS12=1),2,IF(AND(MAX(AV12:AY12)>1,AS12=0),2,1))) -> 1
A13: 12 | B13: P809 | C13: 0 | H13: P809 | I13: Ductile Iron | Q13: P809 | R13: 12.924218 | S13: 6 | T13: 130 | V13: 0 | W13: 0 | X13: P809 | Y13: 0 | Z13: 6 | AA13: 12.92 | AB13: 130 | AC13: 0 | AD13: 0 | AE13: 0 | AF13: 0 | AG13: 1 | AH13: 0 | AI13: 0 | AJ13: 0 | AK13: 0 | AL13: 0 | AM13: 0 | AN13: 0 | AO13: 0 | AP13: 0 | AQ13: 12.924218 | AR13: 0 | AS13: =_xlfn.XLOOKUP(B13,InstallDate!$H$2:$H$389,InstallDate!$BE$2:$BE$389) -> 0 | AT13: =IF(COUNTIF(AR13:AS13,1)=0,0,SUM(AR13:AS13)/COUNTIF(AR13:AS13,1)) -> 0 | AU13: =AC13/MAX($AC$2:$AC$389) -> 0 | AV13: =IF($AU13>=_xlfn.PERCENTILE.INC($AU$2:$AU$369,AV$1),4,0) -> 0 | AW13: =IF($AU13>=_xlfn.PERCENTILE.INC($AU$2:$AU$369,AW$1),3,0) -> 0 | AX13: =IF($AU13>=_xlfn.PERCENTILE.INC($AU$2:$AU$369,AX$1),2,0) -> 0 | AY13: =IF(SUM(AV13:AX13)<1,1,0) -> 1 | AZ13: =IF(AND(MAX(AV13:AY13)>2,AS13=1),3,IF(AND(MAX(AV13:AY13)<=2,AS13=1),2,IF(AND(MAX(AV13:AY13)>1,AS13=0),2,1))) -> 1
A14: 13 | B14: P811 | C14: 0 | H14: P811 | I14: Ductile Iron | Q14: P811 | R14: 64.144728 | S14: 6 | T14: 130 | V14: 0 | W14: 0 | X14: P811 | Y14: 0 | Z14: 6 | AA14: 64.14 | AB14: 130 | AC14: 0 | AD14: 0 | AE14: 0 | AF14: 0 | AG14: 1 | AH14: 0 | AI14: 0 | AJ14: 0 | AK14: 0 | AL14: 0 | AM14: 0 | AN14: 0 | AO14: 0 | AP14: 0 | AQ14: 64.144728 | AR14: 0 | AS14: =_xlfn.XLOOKUP(B14,InstallDate!$H$2:$H$389,InstallDate!$BE$2:$BE$389) -> 0 | AT14: =IF(COUNTIF(AR14:AS14,1)=0,0,SUM(AR14:AS14)/COUNTIF(AR14:AS14,1)) -> 0 | AU14: =AC14/MAX($AC$2:$AC$389) -> 0 | AV14: =IF($AU14>=_xlfn.PERCENTILE.INC($AU$2:$AU$369,AV$1),4,0) -> 0 | AW14: =IF($AU14>=_xlfn.PERCENTILE.INC($AU$2:$AU$369,AW$1),3,0) -> 0 | AX14: =IF($AU14>=_xlfn.PERCENTILE.INC($AU$2:$AU$369,AX$1),2,0) -> 0 | AY14: =IF(SUM(AV14:AX14)<1,1,0) -> 1 | AZ14: =IF(AND(MAX(AV14:AY14)>2,AS14=1),3,IF(AND(MAX(AV14:AY14)<=2,AS14=1),2,IF(AND(MAX(AV14:AY14)>1,AS14=0),2,1))) -> 1
A15: 14 | B15: P813 | C15: 0 | H15: P813 | I15: Ductile Iron | Q15: P813 | R15: 43.590494 | S15: 6 | T15: 130 | V15: 0 | W15: 0 | X15: P813 | Y15: 0 | Z15: 6 | AA15: 43.59 | AB15: 130 | AC15: 0 | AD15: 0 | AE15: 0 | AF15: 0 | AG15: 1 | AH15: 0 | AI15: 0 | AJ15: 0 | AK15: 0 | AL15: 0 | AM15: 0 | AN15: 0 | AO15: 0 | AP15: 0 | AQ15: 43.590494 | AR15: 0 | AS15: =_xlfn.XLOOKUP(B15,InstallDate!$H$2:$H$389,InstallDate!$BE$2:$BE$389) -> 0 | AT15: =IF(COUNTIF(AR15:AS15,1)=0,0,SUM(AR15:AS15)/COUNTIF(AR15:AS15,1)) -> 0 | AU15: =AC15/MAX($AC$2:$AC$389) -> 0 | AV15: =IF($AU15>=_xlfn.PERCENTILE.INC($AU$2:$AU$369,AV$1),4,0) -> 0 | AW15: =IF($AU15>=_xlfn.PERCENTILE.INC($AU$2:$AU$369,AW$1),3,0) -> 0 | AX15: =IF($AU15>=_xlfn.PERCENTILE.INC($AU$2:$AU$369,AX$1),2,0) -> 0 | AY15: =IF(SUM(AV15:AX15)<1,1,0) -> 1 | AZ15: =IF(AND(MAX(AV15:AY15)>2,AS15=1),3,IF(AND(MAX(AV15:AY15)<=2,AS15=1),2,IF(AND(MAX(AV15:AY15)>1,AS15=0),2,1))) -> 1
A16: 15 | B16: P815 | C16: 0 | H16: P815 | I16: Ductile Iron | Q16: P815 | R16: 6.0643549 | S16: 6 | T16: 130 | V16: 0 | W16: 0 | X16: P815 | Y16: 0 | Z16: 6 | AA16: 6.06 | AB16: 130 | AC16: 0 | AD16: 0 | AE16: 0 | AF16: 0 | AG16: 1 | AH16: 0 | AI16: 0 | AJ16: 0 | AK16: 0 | AL16: 0 | AM16: 0 | AN16: 0 | AO16: 0 | AP16: 0 | AQ16: 6.0643549 | AR16: 0 | AS16: =_xlfn.XLOOKUP(B16,InstallDate!$H$2:$H$389,InstallDate!$BE$2:$BE$389) -> 0 | AT16: =IF(COUNTIF(AR16:AS16,1)=0,0,SUM(AR16:AS16)/COUNTIF(AR16:AS16,1)) -> 0 | AU16: =AC16/MAX($AC$2:$AC$389) -> 0 | AV16: =IF($AU16>=_xlfn.PERCENTILE.INC($AU$2:$AU$369,AV$1),4,0) -> 0 | AW16: =IF($AU16>=_xlfn.PERCENTILE.INC($AU$2:$AU$369,AW$1),3,0) -> 0 | AX16: =IF($AU16>=_xlfn.PERCENTILE.INC($AU$2:$AU$369,AX$1),2,0) -> 0 | AY16: =IF(SUM(AV16:AX16)<1,1,0) -> 1 | AZ16: =IF(AND(MAX(AV16:AY16)>2,AS16=1),3,IF(AND(MAX(AV16:AY16)<=2,AS16=1),2,IF(AND(MAX(AV16:AY16)>1,AS16=0),2,1))) -> 1
A17: 16 | B17: P817 | C17: 0 | H17: P817 | I17: Ductile Iron | Q17: P817 | R17: 36.335399 | S17: 6 | T17: 130 | V17: 0 | W17: 0 | X17: P817 | Y17: 0 | Z17: 6 | AA17: 36.34 | AB17: 130 | AC17: 0 | AD17: 0 | AE17: 0 | AF17: 0 | AG17: 1 | AH17: 0 | AI17: 0 | AJ17: 0 | AK17: 0 | AL17: 0 | AM17: 0 | AN17: 0 | AO17: 0 | AP17: 0 | AQ17: 36.335399 | AR17: 0 | AS17: =_xlfn.XLOOKUP(B17,InstallDate!$H$2:$H$389,InstallDate!$BE$2:$BE$389) -> 0 | AT17: =IF(COUNTIF(AR17:AS17,1)=0,0,SUM(AR17:AS17)/COUNTIF(AR17:AS17,1)) -> 0 | AU17: =AC17/MAX($AC$2:$AC$389) -> 0 | AV17: =IF($AU17>=_xlfn.PERCENTILE.INC($AU$2:$AU$369,AV$1),4,0) -> 0 | AW17: =IF($AU17>=_xlfn.PERCENTILE.INC($AU$2:$AU$369,AW$1),3,0) -> 0 | AX17: =IF($AU17>=_xlfn.PERCENTILE.INC($AU$2:$AU$369,AX$1),2,0) -> 0 | AY17: =IF(SUM(AV17:AX17)<1,1,0) -> 1 | AZ17: =IF(AND(MAX(AV17:AY17)>2,AS17=1),3,IF(AND(MAX(AV17:AY17)<=2,AS17=1),2,IF(AND(MAX(AV17:AY17)>1,AS17=0),2,1))) -> 1
A18: 17 | B18: P819 | C18: 0 | H18: P819 | I18: Ductile Iron | Q18: P819 | R18: 94.01854 | S18: 6 | T18: 130 | V18: 0 | W18: 0 | X18: P819 | Y18: 0 | Z18: 6 | AA18: 94.02 | AB18: 130 | AC18: 0 | AD18: 0 | AE18: 0 | AF18: 0 | AG18: 1 | AH18: 0 | AI18: 0 | AJ18: 0 | AK18: 0 | AL18: 0 | AM18: 0 | AN18: 0 | AO18: 0 | AP18: 0 | AQ18: 94.01854 | AR18: 0 | AS18: =_xlfn.XLOOKUP(B18,InstallDate!$H$2:$H$389,InstallDate!$BE$2:$BE$389) -> 0 | AT18: =IF(COUNTIF(AR18:AS18,1)=0,0,SUM(AR18:AS18)/COUNTIF(AR18:AS18,1)) -> 0 | AU18: =AC18/MAX($AC$2:$AC$389) -> 0 | AV18: =IF($AU18>=_xlfn.PERCENTILE.INC($AU$2:$AU$369,AV$1),4,0) -> 0 | AW18: =IF($AU18>=_xlfn.PERCENTILE.INC($AU$2:$AU$369,AW$1),3,0) -> 0 | AX18: =IF($AU18>=_xlfn.PERCENTILE.INC($AU$2:$AU$369,AX$1),2,0) -> 0 | AY18: =IF(SUM(AV18:AX18)<1,1,0) -> 1 | AZ18: =IF(AND(MAX(AV18:AY18)>2,AS18=1),3,IF(AND(MAX(AV18:AY18)<=2,AS18=1),2,IF(AND(MAX(AV18:AY18)>1,AS18=0),2,1))) -> 1
A19: 18 | B19: P821 | C19: 0 | H19: P821 | I19: Ductile Iron | Q19: P821 | R19: 90.921988 | S19: 6 | T19: 130 | V19: 0 | W19: 0 | X19: P821 | Y19: 0 | Z19: 6 | AA19: 90.92 | AB19: 130 | AC19: 0 | AD19: 0 | AE19: 0 | AF19: 0 | AG19: 1 | AH19: 0 | AI19: 0 | AJ19: 0 | AK19: 0 | AL19: 0 | AM19: 0 | AN19: 0 | AO19: 0 | AP19: 0 | AQ19: 90.921988 | AR19: 0 | AS19: =_xlfn.XLOOKUP(B19,InstallDate!$H$2:$H$389,InstallDate!$BE$2:$BE$389) -> 0 | AT19: =IF(COUNTIF(AR19:AS19,1)=0,0,SUM(AR19:AS19)/COUNTIF(AR19:AS19,1)) -> 0 | AU19: =AC19/MAX($AC$2:$AC$389) -> 0 | AV19: =IF($AU19>=_xlfn.PERCENTILE.INC($AU$2:$AU$369,AV$1),4,0) -> 0 | AW19: =IF($AU19>=_xlfn.PERCENTILE.INC($AU$2:$AU$369,AW$1),3,0) -> 0 | AX19: =IF($AU19>=_xlfn.PERCENTILE.INC($AU$2:$AU$369,AX$1),2,0) -> 0 | AY19: =IF(SUM(AV19:AX19)<1,1,0) -> 1 | AZ19: =IF(AND(MAX(AV19:AY19)>2,AS19=1),3,IF(AND(MAX(AV19:AY19)<=2,AS19=1),2,IF(AND(MAX(AV19:AY19)>1,AS19=0),2,1))) -> 1
A20: 19 | B20: P823 | C20: 0 | H20: P823 | I20: Ductile Iron | Q20: P823 | R20: 28.538196 | S20: 6 | T20: 130 | V20: 0 | W20: 0 | X20: P823 | Y20: 0 | Z20: 6 | AA20: 28.54 | AB20: 130 | AC20: 0 | AD20: 0 | AE20: 0 | AF20: 0 | AG20: 1 | AH20: 0 | AI20: 0 | AJ20: 0 | AK20: 0 | AL20: 0 | AM20: 0 | AN20: 0 | AO20: 0 | AP20: 0 | AQ20: 28.538196 | AR20: 0 | AS20: =_xlfn.XLOOKUP(B20,InstallDate!$H$2:$H$389,InstallDate!$BE$2:$BE$389) -> 0 | AT20: =IF(COUNTIF(AR20:AS20,1)=0,0,SUM(AR20:AS20)/COUNTIF(AR20:AS20,1)) -> 0 | AU20: =AC20/MAX($AC$2:$AC$389) -> 0 | AV20: =IF($AU20>=_xlfn.PERCENTILE.INC($AU$2:$AU$369,AV$1),4,0) -> 0 | AW20: =IF($AU20>=_xlfn.PERCENTILE.INC($AU$2:$AU$369,AW$1),3,0) -> 0 | AX20: =IF($AU20>=_xlfn.PERCENTILE.INC($AU$2:$AU$369,AX$1),2,0) -> 0 | AY20: =IF(SUM(AV20:AX20)<1,1,0) -> 1 | AZ20: =IF(AND(MAX(AV20:AY20)>2,AS20=1),3,IF(AND(MAX(AV20:AY20)<=2,AS20=1),2,IF(AND(MAX(AV20:AY20)>1,AS20=0),2,1))) -> 1
... A129: 128 | B129: P1041 | C129: 0 | H129: P1041 | I129: Asbestos Cement | Q129: P1041 | R129: 26.673927 | S129: 6 | T129: 130 | V129: 0 | W129: 0 | X129: P1041 | Y129: 1 | Z129: 6 | AA129: 26.67 | AB129: 130 | AC129: 1.39 | AD129: 0.02 | AE129: 0 | AF129: 0 | AG129: 1 | AH129: 1.39 | AI129: 1.39 | AJ129: 1.39 | AK129: 0.02 | AL129: 0.02 | AM129: 0.02 | AN129: 0 | AO129: 0 | AP129: 0 | AQ129: 26.673927 | AR129: 0 | AS129: =_xlfn.XLOOKUP(B129,InstallDate!$H$2:$H$389,InstallDate!$BE$2:$BE$389) -> 0 | AT129: =IF(COUNTIF(AR129:AS129,1)=0,0,SUM(AR129:AS129)/COUNTIF(AR129:AS129,1)) -> 0 | AU129: =AC129/MAX($AC$2:$AC$389) -> 0.011161969 | AV129: =IF($AU129>=_xlfn.PERCENTILE.INC($AU$2:$AU$369,AV$1),4,0) -> 0 | AW129: =IF($AU129>=_xlfn.PERCENTILE.INC($AU$2:$AU$369,AW$1),3,0) -> 0 | AX129: =IF($AU129>=_xlfn.PERCENTILE.INC($AU$2:$AU$369,AX$1),2,0) -> 0 | AY129: =IF(SUM(AV129:AX129)<1,1,0) -> 1 | AZ129: =IF(AND(MAX(AV129:AY129)>2,AS129=1),3,IF(AND(MAX(AV129:AY129)<=2,AS129=1),2,IF(AND(MAX(AV129:AY129)>1,AS129=0),2,1))) -> 1
A130: 129 | B130: P1045 | C130: 0 | H130: P1045 | Q130: P1045 | R130: 641 | S130: 6 | T130: 130 | U130: 0 | V130: 0 | W130: 0 | X130: P1045 | Y130: 1 | Z130: 6 | AA130: 641 | AB130: 130 | AC130: 1.39 | AD130: 0.02 | AE130: 0 | AF130: 0 | AG130: 1 | AH130: 1.39 | AI130: 1.39 | AJ130: 1.39 | AK130: 0.02 | AL130: 0.02 | AM130: 0.02 | AN130: 0 | AO130: 0 | AP130: 0 | AQ130: 614.08345 | AR130: 0 | AS130: =_xlfn.XLOOKUP(B130,InstallDate!$H$2:$H$389,InstallDate!$BE$2:$BE$389) -> 0 | AT130: =IF(COUNTIF(AR130:AS130,1)=0,0,SUM(AR130:AS130)/COUNTIF(AR130:AS130,1)) -> 0 | AU130: =AC130/MAX($AC$2:$AC$389) -> 0.011161969 | AV130: =IF($AU130>=_xlfn.PERCENTILE.INC($AU$2:$AU$369,AV$1),4,0) -> 0 | AW130: =IF($AU130>=_xlfn.PERCENTILE.INC($AU$2:$AU$369,AW$1),3,0) -> 0 | AX130: =IF($AU130>=_xlfn.PERCENTILE.INC($AU$2:$AU$369,AX$1),2,0) -> 0 | AY130: =IF(SUM(AV130:AX130)<1,1,0) -> 1 | AZ130: =IF(AND(MAX(AV130:AY130)>2,AS130=1),3,IF(AND(MAX(AV130:AY130)<=2,AS130=1),2,IF(AND(MAX(AV130:AY130)>1,AS130=0),2,1))) -> 1
A131: 130 | B131: P1047 | C131: 0 | H131: P1047 | I131: Asbestos Cement | Q131: P1047 | R131: 378.26525 | S131: 6 | T131: 130 | V131: 0 | W131: 0 | X131: P1047 | Y131: 1 | Z131: 6 | AA131: 378.27 | AB131: 130 | AC131: 1.39 | AD131: 0.02 | AE131: 0 | AF131: 0 | AG131: 1 | AH131: 1.39 | AI131: 1.39 | AJ131: 1.39 | AK131: 0.02 | AL131: 0.02 | AM131: 0.02 | AN131: 0 | AO131: 0 | AP131: 0 | AQ131: 378.26525 | AR131: 0 | AS131: =_xlfn.XLOOKUP(B131,InstallDate!$H$2:$H$389,InstallDate!$BE$2:$BE$389) -> 0 | AT131: =IF(COUNTIF(AR131:AS131,1)=0,0,SUM(AR131:AS131)/COUNTIF(AR131:AS131,1)) -> 0 | AU131: =AC131/MAX($AC$2:$AC$389) -> 0.011161969 | AV131: =IF($AU131>=_xlfn.PERCENTILE.INC($AU$2:$AU$369,AV$1),4,0) -> 0 | AW131: =IF($AU131>=_xlfn.PERCENTILE.INC($AU$2:$AU$369,AW$1),3,0) -> 0 | AX131: =IF($AU131>=_xlfn.PERCENTILE.INC($AU$2:$AU$369,AX$1),2,0) -> 0 | AY131: =IF(SUM(AV131:AX131)<1,1,0) -> 1 | AZ131: =IF(AND(MAX(AV131:AY131)>2,AS131=1),3,IF(AND(MAX(AV131:AY131)<=2,AS131=1),2,IF(AND(MAX(AV131:AY131)>1,AS131=0),2,1))) -> 1
A132: 131 | B132: P1049 | C132: 0 | H132: P1049 | I132: Cast Iron | Q132: P1049 | R132: 22.167175 | S132: 6 | T132: 130 | V132: 0 | W132: 0 | X132: P1049 | Y132: -1 | Z132: 6 | AA132: 22.17 | AB132: 130 | AC132: 18.01 | AD132: 0.2 | AE132: 0 | AF132: 0.04 | AG132: 1 | AH132: 18.01 | AI132: 18.01 | AJ132: 18.01 | AK132: 0.2 | AL132: 0.2 | AM132: 0.2 | AN132: 0 | AO132: 0 | AP132: 0 | AQ132: 22.167175 | AR132: 0 | AS132: =_xlfn.XLOOKUP(B132,InstallDate!$H$2:$H$389,InstallDate!$BE$2:$BE$389) -> 0 | AT132: =IF(COUNTIF(AR132:AS132,1)=0,0,SUM(AR132:AS132)/COUNTIF(AR132:AS132,1)) -> 0 | AU132: =AC132/MAX($AC$2:$AC$389) -> 0.14462379 | AV132: =IF($AU132>=_xlfn.PERCENTILE.INC($AU$2:$AU$369,AV$1),4,0) -> 0 | AW132: =IF($AU132>=_xlfn.PERCENTILE.INC($AU$2:$AU$369,AW$1),3,0) -> 0 | AX132: =IF($AU132>=_xlfn.PERCENTILE.INC($AU$2:$AU$369,AX$1),2,0) -> 2 | AY132: =IF(SUM(AV132:AX132)<1,1,0) -> 0 | AZ132: =IF(AND(MAX(AV132:AY132)>2,AS132=1),3,IF(AND(MAX(AV132:AY132)<=2,AS132=1),2,IF(AND(MAX(AV132:AY132)>1,AS132=0),2,1))) -> 2
A133: 132 | B133: P1051 | C133: 0 | H133: P1051 | I133: Cast Iron | Q133: P1051 | R133: 287.34181 | S133: 6 | T133: 130 | V133: 0 | W133: 0 | X133: P1051 | Y133: -1 | Z133: 6 | AA133: 287.34 | AB133: 130 | AC133: 18.29 | AD133: 0.21 | AE133: 0.01 | AF133: 0.04 | AG133: 1 | AH133: 18.29 | AI133: 18.29 | AJ133: 18.29 | AK133: 0.21 | AL133: 0.21 | AM133: 0.21 | AN133: 0.01 | AO133: 0.01 | AP133: 0.01 | AQ133: 287.34181 | AR133: 0 | AS133: =_xlfn.XLOOKUP(B133,InstallDate!$H$2:$H$389,InstallDate!$BE$2:$BE$389) -> 0 | AT133: =IF(COUNTIF(AR133:AS133,1)=0,0,SUM(AR133:AS133)/COUNTIF(AR133:AS133,1)) -> 0 | AU133: =AC133/MAX($AC$2:$AC$389) -> 0.14687224 | AV133: =IF($AU133>=_xlfn.PERCENTILE.INC($AU$2:$AU$369,AV$1),4,0) -> 0 | AW133: =IF($AU133>=_xlfn.PERCENTILE.INC($AU$2:$AU$369,AW$1),3,0) -> 0 | AX133: =IF($AU133>=_xlfn.PERCENTILE.INC($AU$2:$AU$369,AX$1),2,0) -> 2 | AY133: =IF(SUM(AV133:AX133)<1,1,0) -> 0 | AZ133: =IF(AND(MAX(AV133:AY133)>2,AS133=1),3,IF(AND(MAX(AV133:AY133)<=2,AS133=1),2,IF(AND(MAX(AV133:AY133)>1,AS133=0),2,1))) -> 2
A134: 133 | B134: P1053 | C134: 0 | H134: P1053 | I134: Cast Iron | Q134: P1053 | R134: 87.760714 | S134: 6 | T134: 130 | V134: 0 | W134: 0 | X134: P1053 | Y134: -1 | Z134: 6 | AA134: 87.76 | AB134: 130 | AC134: 18.57 | AD134: 0.21 | AE134: 0 | AF134: 0.05 | AG134: 1 | AH134: 18.57 | AI134: 18.57 | AJ134: 18.57 | AK134: 0.21 | AL134: 0.21 | AM134: 0.21 | AN134: 0 | AO134: 0 | AP134: 0 | AQ134: 87.760714 | AR134: 0 | AS134: =_xlfn.XLOOKUP(B134,InstallDate!$H$2:$H$389,InstallDate!$BE$2:$BE$389) -> 0 | AT134: =IF(COUNTIF(AR134:AS134,1)=0,0,SUM(AR134:AS134)/COUNTIF(AR134:AS134,1)) -> 0 | AU134: =AC134/MAX($AC$2:$AC$389) -> 0.14912069 | AV134: =IF($AU134>=_xlfn.PERCENTILE.INC($AU$2:$AU$369,AV$1),4,0) -> 0 | AW134: =IF($AU134>=_xlfn.PERCENTILE.INC($AU$2:$AU$369,AW$1),3,0) -> 0 | AX134: =IF($AU134>=_xlfn.PERCENTILE.INC($AU$2:$AU$369,AX$1),2,0) -> 2 | AY134: =IF(SUM(AV134:AX134)<1,1,0) -> 0 | AZ134: =IF(AND(MAX(AV134:AY134)>2,AS134=1),3,IF(AND(MAX(AV134:AY134)<=2,AS134=1),2,IF(AND(MAX(AV134:AY134)>1,AS134=0),2,1))) -> 2
A135: 134 | B135: P1055 | C135: 0 | H135: P1055 | I135: Cast Iron | Q135: P1055 | R135: 50.641312 | S135: 6 | T135: 130 | V135: 0 | W135: 0 | X135: P1055 | Y135: -1 | Z135: 6 | AA135: 50.64 | AB135: 130 | AC135: 19.26 | AD135: 0.22 | AE135: 0 | AF135: 0.05 | AG135: 1 | AH135: 19.26 | AI135: 19.26 | AJ135: 19.26 | AK135: 0.22 | AL135: 0.22 | AM135: 0.22 | AN135: 0 | AO135: 0 | AP135: 0 | AQ135: 50.641312 | AR135: 0 | AS135: =_xlfn.XLOOKUP(B135,InstallDate!$H$2:$H$389,InstallDate!$BE$2:$BE$389) -> 0 | AT135: =IF(COUNTIF(AR135:AS135,1)=0,0,SUM(AR135:AS135)/COUNTIF(AR135:AS135,1)) -> 0 | AU135: =AC135/MAX($AC$2:$AC$389) -> 0.15466153 | AV135: =IF($AU135>=_xlfn.PERCENTILE.INC($AU$2:$AU$369,AV$1),4,0) -> 0 | AW135: =IF($AU135>=_xlfn.PERCENTILE.INC($AU$2:$AU$369,AW$1),3,0) -> 0 | AX135: =IF($AU135>=_xlfn.PERCENTILE.INC($AU$2:$AU$369,AX$1),2,0) -> 2 | AY135: =IF(SUM(AV135:AX135)<1,1,0) -> 0 | AZ135: =IF(AND(MAX(AV135:AY135)>2,AS135=1),3,IF(AND(MAX(AV135:AY135)<=2,AS135=1),2,IF(AND(MAX(AV135:AY135)>1,AS135=0),2,1))) -> 2
A136: 135 | B136: P1057 | C136: 0 | H136: P1057 | I136: Cast Iron | Q136: P1057 | R136: 29.594034 | S136: 6 | T136: 130 | V136: 0 | W136: 0 | X136: P1057 | Y136: -1 | Z136: 6 | AA136: 29.59 | AB136: 130 | AC136: 1.39 | AD136: 0.02 | AE136: 0 | AF136: 0 | AG136: 1 | AH136: 1.39 | AI136: 1.39 | AJ136: 1.39 | AK136: 0.02 | AL136: 0.02 | AM136: 0.02 | AN136: 0 | AO136: 0 | AP136: 0 | AQ136: 29.594034 | AR136: 1 | AS136: =_xlfn.XLOOKUP(B136,InstallDate!$H$2:$H$389,InstallDate!$BE$2:$BE$389) -> 1 | AT136: =IF(COUNTIF(AR136:AS136,1)=0,0,SUM(AR136:AS136)/COUNTIF(AR136:AS136,1)) -> 1 | AU136: =AC136/MAX($AC$2:$AC$389) -> 0.011161969 | AV136: =IF($AU136>=_xlfn.PERCENTILE.INC($AU$2:$AU$369,AV$1),4,0) -> 0 | AW136: =IF($AU136>=_xlfn.PERCENTILE.INC($AU$2:$AU$369,AW$1),3,0) -> 0 | AX136: =IF($AU136>=_xlfn.PERCENTILE.INC($AU$2:$AU$369,AX$1),2,0) -> 0 | AY136: =IF(SUM(AV136:AX136)<1,1,0) -> 1 | AZ136: =IF(AND(MAX(AV136:AY136)>2,AS136=1),3,IF(AND(MAX(AV136:AY136)<=2,AS136=1),2,IF(AND(MAX(AV136:AY136)>1,AS136=0),2,1))) -> 2
A137: 136 | B137: P1059 | C137: 0 | H137: P1059 | I137: Cast Iron | Q137: P1059 | R137: 91.930452 | S137: 6 | T137: 130 | V137: 0 | W137: 0 | X137: P1059 | Y137: -1 | Z137: 6 | AA137: 91.93 | AB137: 130 | AC137: 1.39 | AD137: 0.02 | AE137: 0 | AF137: 0 | AG137: 1 | AH137: 1.39 | AI137: 1.39 | AJ137: 1.39 | AK137: 0.02 | AL137: 0.02 | AM137: 0.02 | AN137: 0 | AO137: 0 | AP137: 0 | AQ137: 91.930452 | AR137: 1 | AS137: =_xlfn.XLOOKUP(B137,InstallDate!$H$2:$H$389,InstallDate!$BE$2:$BE$389) -> 1 | AT137: =IF(COUNTIF(AR137:AS137,1)=0,0,SUM(AR137:AS137)/COUNTIF(AR137:AS137,1)) -> 1 | AU137: =AC137/MAX($AC$2:$AC$389) -> 0.011161969 | AV137: =IF($AU137>=_xlfn.PERCENTILE.INC($AU$2:$AU$369,AV$1),4,0) -> 0 | AW137: =IF($AU137>=_xlfn.PERCENTILE.INC($AU$2:$AU$369,AW$1),3,0) -> 0 | AX137: =IF($AU137>=_xlfn.PERCENTILE.INC($AU$2:$AU$369,AX$1),2,0) -> 0 | AY137: =IF(SUM(AV137:AX137)<1,1,0) -> 1 | AZ137: =IF(AND(MAX(AV137:AY137)>2,AS137=1),3,IF(AND(MAX(AV137:AY137)<=2,AS137=1),2,IF(AND(MAX(AV137:AY137)>1,AS137=0),2,1))) -> 2
A138: 137 | B138: P1061 | C138: 0 | H138: P1061 | I138: Cast Iron | Q138: P1061 | R138: 530.42279 | S138: 6 | T138: 130 | V138: 0 | W138: 0 | X138: P1061 | Y138: -1 | Z138: 6 | AA138: 530.42 | AB138: 130 | AC138: 23.66 | AD138: 0.27 | AE138: 0.04 | AF138: 0.07 | AG138: 1 | AH138: 23.66 | AI138: 23.66 | AJ138: 23.66 | AK138: 0.27 | AL138: 0.27 | AM138: 0.27 | AN138: 0.04 | AO138: 0.04 | AP138: 0.04 | AQ138: 530.42279 | AR138: 1 | AS138: =_xlfn.XLOOKUP(B138,InstallDate!$H$2:$H$389,InstallDate!$BE$2:$BE$389) -> 0 | AT138: =IF(COUNTIF(AR138:AS138,1)=0,0,SUM(AR138:AS138)/COUNTIF(AR138:AS138,1)) -> 1 | AU138: =AC138/MAX($AC$2:$AC$389) -> 0.18999438 | AV138: =IF($AU138>=_xlfn.PERCENTILE.INC($AU$2:$AU$369,AV$1),4,0) -> 0 | AW138: =IF($AU138>=_xlfn.PERCENTILE.INC($AU$2:$AU$369,AW$1),3,0) -> 3 | AX138: =IF($AU138>=_xlfn.PERCENTILE.INC($AU$2:$AU$369,AX$1),2,0) -> 2 | AY138: =IF(SUM(AV138:AX138)<1,1,0) -> 0 | AZ138: =IF(AND(MAX(AV138:AY138)>2,AS138=1),3,IF(AND(MAX(AV138:AY138)<=2,AS138=1),2,IF(AND(MAX(AV138:AY138)>1,AS138=0),2,1))) -> 2
A139: 138 | B139: P1063 | C139: 0 | H139: P1063 | I139: Cast Iron | Q139: P1063 | R139: 32.062249 | S139: 6 | T139: 130 | V139: 0 | W139: 0 | X139: P1063 | Y139: 1 | Z139: 6 | AA139: 32.06 | AB139: 130 | AC139: 4.63 | AD139: 0.05 | AE139: 0 | AF139: 0 | AG139: 1 | AH139: 4.63 | AI139: 4.63 | AJ139: 4.63 | AK139: 0.05 | AL139: 0.05 | AM139: 0.05 | AN139: 0 | AO139: 0 | AP139: 0 | AQ139: 32.062249 | AR139: 0 | AS139: =_xlfn.XLOOKUP(B139,InstallDate!$H$2:$H$389,InstallDate!$BE$2:$BE$389) -> 1 | AT139: =IF(COUNTIF(AR139:AS139,1)=0,0,SUM(AR139:AS139)/COUNTIF(AR139:AS139,1)) -> 1 | AU139: =AC139/MAX($AC$2:$AC$389) -> 0.037179796 | AV139: =IF($AU139>=_xlfn.PERCENTILE.INC($AU$2:$AU$369,AV$1),4,0) -> 0 | AW139: =IF($AU139>=_xlfn.PERCENTILE.INC($AU$2:$AU$369,AW$1),3,0) -> 0 | AX139: =IF($AU139>=_xlfn.PERCENTILE.INC($AU$2:$AU$369,AX$1),2,0) -> 2 | AY139: =IF(SUM(AV139:AX139)<1,1,0) -> 0 | AZ139: =IF(AND(MAX(AV139:AY139)>2,AS139=1),3,IF(AND(MAX(AV139:AY139)<=2,AS139=1),2,IF(AND(MAX(AV139:AY139)>1,AS139=0),2,1))) -> 2
A140: 139 | B140: P1065 | C140: 0 | H140: P1065 | I140: Cast Iron | Q140: P1065 | R140: 157.04672 | S140: 6 | T140: 130 | V140: 0 | W140: 0 | X140: P1065 | Y140: 1 | Z140: 6 | AA140: 157.05 | AB140: 130 | AC140: 4.63 | AD140: 0.05 | AE140: 0 | AF140: 0 | AG140: 1 | AH140: 4.63 | AI140: 4.63 | AJ140: 4.63 | AK140: 0.05 | AL140: 0.05 | AM140: 0.05 | AN140: 0 | AO140: 0 | AP140: 0 | AQ140: 157.04672 | AR140: 0 | AS140: =_xlfn.XLOOKUP(B140,InstallDate!$H$2:$H$389,InstallDate!$BE$2:$BE$389) -> 0 | AT140: =IF(COUNTIF(AR140:AS140,1)=0,0,SUM(AR140:AS140)/COUNTIF(AR140:AS140,1)) -> 0 | AU140: =AC140/MAX($AC$2:$AC$389) -> 0.037179796 | AV140: =IF($AU140>=_xlfn.PERCENTILE.INC($AU$2:$AU$369,AV$1),4,0) -> 0 | AW140: =IF($AU140>=_xlfn.PERCENTILE.INC($AU$2:$AU$369,AW$1),3,0) -> 0 | AX140: =IF($AU140>=_xlfn.PERCENTILE.INC($AU$2:$AU$369,AX$1),2,0) -> 2 | AY140: =IF(SUM(AV140:AX140)<1,1,0) -> 0 | AZ140: =IF(AND(MAX(AV140:AY140)>2,AS140=1),3,IF(AND(MAX(AV140:AY140)<=2,AS140=1),2,IF(AND(MAX(AV140:AY140)>1,AS140=0),2,1))) -> 2
A141: 140 | B141: P1067 | C141: 0 | H141: P1067 | I141: Cast Iron | Q141: P1067 | R141: 626.91723 | S141: 6 | T141: 130 | V141: 0 | W141: 0 | X141: P1067 | Y141: 1 | Z141: 6 | AA141: 626.92 | AB141: 130 | AC141: 2.82 | AD141: 0.03 | AE141: 0 | AF141: 0 | AG141: 1 | AH141: 2.82 | AI141: 2.82 | AJ141: 2.82 | AK141: 0.03 | AL141: 0.03 | AM141: 0.03 | AN141: 0 | AO141: 0 | AP141: 0 | AQ141: 626.91723 | AR141: 0 | AS141: =_xlfn.XLOOKUP(B141,InstallDate!$H$2:$H$389,InstallDate!$BE$2:$BE$389) -> 1 | AT141: =IF(COUNTIF(AR141:AS141,1)=0,0,SUM(AR141:AS141)/COUNTIF(AR141:AS141,1)) -> 1 | AU141: =AC141/MAX($AC$2:$AC$389) -> 0.022645146 | AV141: =IF($AU141>=_xlfn.PERCENTILE.INC($AU$2:$AU$369,AV$1),4,0) -> 0 | AW141: =IF($AU141>=_xlfn.PERCENTILE.INC($AU$2:$AU$369,AW$1),3,0) -> 0 | AX141: =IF($AU141>=_xlfn.PERCENTILE.INC($AU$2:$AU$369,AX$1),2,0) -> 0 | AY141: =IF(SUM(AV141:AX141)<1,1,0) -> 1 | AZ141: =IF(AND(MAX(AV141:AY141)>2,AS141=1),3,IF(AND(MAX(AV141:AY141)<=2,AS141=1),2,IF(AND(MAX(AV141:AY141)>1,AS141=0),2,1))) -> 2
A142: 141 | B142: P1069 | C142: 0 | H142: P1069 | I142: Cast Iron | Q142: P1069 | R142: 39.018149 | S142: 6 | T142: 130 | V142: 0 | W142: 0 | X142: P1069 | Y142: -1 | Z142: 6 | AA142: 39.02 | AB142: 130 | AC142: 30.24 | AD142: 0.34 | AE142: 0 | AF142: 0.11 | AG142: 1 | AH142: 30.24 | AI142: 30.24 | AJ142: 30.24 | AK142: 0.34 | AL142: 0.34 | AM142: 0.34 | AN142: 0 | AO142: 0 | AP142: 0 | AQ142: 39.018149 | AR142: 1 | AS142: =_xlfn.XLOOKUP(B142,InstallDate!$H$2:$H$389,InstallDate!$BE$2:$BE$389) -> 1 | AT142: =IF(COUNTIF(AR142:AS142,1)=0,0,SUM(AR142:AS142)/COUNTIF(AR142:AS142,1)) -> 1 | AU142: =AC142/MAX($AC$2:$AC$389) -> 0.24283305 | AV142: =IF($AU142>=_xlfn.PERCENTILE.INC($AU$2:$AU$369,AV$1),4,0) -> 0 | AW142: =IF($AU142>=_xlfn.PERCENTILE.INC($AU$2:$AU$369,AW$1),3,0) -> 3 | AX142: =IF($AU142>=_xlfn.PERCENTILE.INC($AU$2:$AU$369,AX$1),2,0) -> 2 | AY142: =IF(SUM(AV142:AX142)<1,1,0) -> 0 | AZ142: =IF(AND(MAX(AV142:AY142)>2,AS142=1),3,IF(AND(MAX(AV142:AY142)<=2,AS142=1),2,IF(AND(MAX(AV142:AY142)>1,AS142=0),2,1))) -> 3
... A262: 261 | B262: P1309 | C262: 0 | H262: P1309 | I262: Cast iron | Q262: P1309 | R262: 25.228003 | S262: 8 | T262: 130 | V262: 0 | W262: 0 | X262: P1309 | Y262: 1 | Z262: 8 | AA262: 25.23 | AB262: 130 | AC262: 48.18 | AD262: 0.31 | AE262: 0 | AF262: 0.07 | AG262: 1 | AH262: 48.18 | AI262: 48.18 | AJ262: 48.18 | AK262: 0.31 | AL262: 0.31 | AM262: 0.31 | AN262: 0 | AO262: 0 | AP262: 0 | AQ262: 25.228003 | AR262: 0 | AS262: =_xlfn.XLOOKUP(B262,InstallDate!$H$2:$H$389,InstallDate!$BE$2:$BE$389) -> 1 | AT262: =IF(COUNTIF(AR262:AS262,1)=0,0,SUM(AR262:AS262)/COUNTIF(AR262:AS262,1)) -> 1 | AU262: =AC262/MAX($AC$2:$AC$389) -> 0.38689472 | AV262: =IF($AU262>=_xlfn.PERCENTILE.INC($AU$2:$AU$369,AV$1),4,0) -> 4 | AW262: =IF($AU262>=_xlfn.PERCENTILE.INC($AU$2:$AU$369,AW$1),3,0) -> 3 | AX262: =IF($AU262>=_xlfn.PERCENTILE.INC($AU$2:$AU$369,AX$1),2,0) -> 2 | AY262: =IF(SUM(AV262:AX262)<1,1,0) -> 0 | AZ262: =IF(AND(MAX(AV262:AY262)>2,AS262=1),3,IF(AND(MAX(AV262:AY262)<=2,AS262=1),2,IF(AND(MAX(AV262:AY262)>1,AS262=0),2,1))) -> 3
A263: 262 | B263: P1311 | C263: 0 | H263: P1311 | Q263: P1311 | R263: 180 | S263: 8 | T263: 130 | U263: 0 | V263: 0 | W263: 0 | X263: P1311 | Y263: -1 | Z263: 8 | AA263: 180 | AB263: 130 | AC263: 48.18 | AD263: 0.31 | AE263: 0.01 | AF263: 0.07 | AG263: 1 | AH263: 48.18 | AI263: 48.18 | AJ263: 48.18 | AK263: 0.31 | AL263: 0.31 | AM263: 0.31 | AN263: 0.01 | AO263: 0.01 | AP263: 0.01 | AQ263: 170.87545 | AR263: 0 | AS263: =_xlfn.XLOOKUP(B263,InstallDate!$H$2:$H$389,InstallDate!$BE$2:$BE$389) -> 0 | AT263: =IF(COUNTIF(AR263:AS263,1)=0,0,SUM(AR263:AS263)/COUNTIF(AR263:AS263,1)) -> 0 | AU263: =AC263/MAX($AC$2:$AC$389) -> 0.38689472 | AV263: =IF($AU263>=_xlfn.PERCENTILE.INC($AU$2:$AU$369,AV$1),4,0) -> 4 | AW263: =IF($AU263>=_xlfn.PERCENTILE.INC($AU$2:$AU$369,AW$1),3,0) -> 3 | AX263: =IF($AU263>=_xlfn.PERCENTILE.INC($AU$2:$AU$369,AX$1),2,0) -> 2 | AY263: =IF(SUM(AV263:AX263)<1,1,0) -> 0 | AZ263: =IF(AND(MAX(AV263:AY263)>2,AS263=1),3,IF(AND(MAX(AV263:AY263)<=2,AS263=1),2,IF(AND(MAX(AV263:AY263)>1,AS263=0),2,1))) -> 2
A264: 263 | B264: P1313 | C264: 0 | H264: P1313 | I264: Cast Iron | Q264: P1313 | R264: 125.45734 | S264: 6 | T264: 130 | V264: 0 | W264: 0 | X264: P1313 | Y264: 0 | Z264: 6 | AA264: 125.46 | AB264: 130 | AC264: 0 | AD264: 0 | AE264: 0 | AF264: 0 | AG264: 1 | AH264: 0 | AI264: 0 | AJ264: 0 | AK264: 0 | AL264: 0 | AM264: 0 | AN264: 0 | AO264: 0 | AP264: 0 | AQ264: 125.45734 | AR264: 0 | AS264: =_xlfn.XLOOKUP(B264,InstallDate!$H$2:$H$389,InstallDate!$BE$2:$BE$389) -> 0 | AT264: =IF(COUNTIF(AR264:AS264,1)=0,0,SUM(AR264:AS264)/COUNTIF(AR264:AS264,1)) -> 0 | AU264: =AC264/MAX($AC$2:$AC$389) -> 0 | AV264: =IF($AU264>=_xlfn.PERCENTILE.INC($AU$2:$AU$369,AV$1),4,0) -> 0 | AW264: =IF($AU264>=_xlfn.PERCENTILE.INC($AU$2:$AU$369,AW$1),3,0) -> 0 | AX264: =IF($AU264>=_xlfn.PERCENTILE.INC($AU$2:$AU$369,AX$1),2,0) -> 0 | AY264: =IF(SUM(AV264:AX264)<1,1,0) -> 1 | AZ264: =IF(AND(MAX(AV264:AY264)>2,AS264=1),3,IF(AND(MAX(AV264:AY264)<=2,AS264=1),2,IF(AND(MAX(AV264:AY264)>1,AS264=0),2,1))) -> 1
A265: 264 | B265: P1315 | C265: 0 | H265: P1315 | I265: Ductile Iron | Q265: P1315 | R265: 172.4637 | S265: 8 | T265: 130 | V265: 0 | W265: 0 | X265: P1315 | Y265: 0 | Z265: 8 | AA265: 172.46 | AB265: 130 | AC265: 0 | AD265: 0 | AE265: 0 | AF265: 0 | AG265: 1 | AH265: 0 | AI265: 0 | AJ265: 0 | AK265: 0 | AL265: 0 | AM265: 0 | AN265: 0 | AO265: 0 | AP265: 0 | AQ265: 172.4637 | AR265: 0 | AS265: =_xlfn.XLOOKUP(B265,InstallDate!$H$2:$H$389,InstallDate!$BE$2:$BE$389) -> 1 | AT265: =IF(COUNTIF(AR265:AS265,1)=0,0,SUM(AR265:AS265)/COUNTIF(AR265:AS265,1)) -> 1 | AU265: =AC265/MAX($AC$2:$AC$389) -> 0 | AV265: =IF($AU265>=_xlfn.PERCENTILE.INC($AU$2:$AU$369,AV$1),4,0) -> 0 | AW265: =IF($AU265>=_xlfn.PERCENTILE.INC($AU$2:$AU$369,AW$1),3,0) -> 0 | AX265: =IF($AU265>=_xlfn.PERCENTILE.INC($AU$2:$AU$369,AX$1),2,0) -> 0 | AY265: =IF(SUM(AV265:AX265)<1,1,0) -> 1 | AZ265: =IF(AND(MAX(AV265:AY265)>2,AS265=1),3,IF(AND(MAX(AV265:AY265)<=2,AS265=1),2,IF(AND(MAX(AV265:AY265)>1,AS265=0),2,1))) -> 2
A266: 265 | B266: P1317 | C266: 0 | H266: P1317 | I266: Ductile Iron | Q266: P1317 | R266: 135.56561 | S266: 6 | T266: 130 | V266: 0 | W266: 0 | X266: P1317 | Y266: 0 | Z266: 6 | AA266: 135.57 | AB266: 130 | AC266: 0 | AD266: 0 | AE266: 0 | AF266: 0 | AG266: 1 | AH266: 0 | AI266: 0 | AJ266: 0 | AK266: 0 | AL266: 0 | AM266: 0 | AN266: 0 | AO266: 0 | AP266: 0 | AQ266: 135.56561 | AR266: 0 | AS266: =_xlfn.XLOOKUP(B266,InstallDate!$H$2:$H$389,InstallDate!$BE$2:$BE$389) -> 0 | AT266: =IF(COUNTIF(AR266:AS266,1)=0,0,SUM(AR266:AS266)/COUNTIF(AR266:AS266,1)) -> 0 | AU266: =AC266/MAX($AC$2:$AC$389) -> 0 | AV266: =IF($AU266>=_xlfn.PERCENTILE.INC($AU$2:$AU$369,AV$1),4,0) -> 0 | AW266: =IF($AU266>=_xlfn.PERCENTILE.INC($AU$2:$AU$369,AW$1),3,0) -> 0 | AX266: =IF($AU266>=_xlfn.PERCENTILE.INC($AU$2:$AU$369,AX$1),2,0) -> 0 | AY266: =IF(SUM(AV266:AX266)<1,1,0) -> 1 | AZ266: =IF(AND(MAX(AV266:AY266)>2,AS266=1),3,IF(AND(MAX(AV266:AY266)<=2,AS266=1),2,IF(AND(MAX(AV266:AY266)>1,AS266=0),2,1))) -> 1
A267: 266 | B267: P1319 | C267: 0 | H267: P1319 | I267: Asbestos Cement | Q267: P1319 | R267: 39.561407 | S267: 6 | T267: 130 | V267: 0 | W267: 0 | X267: P1319 | Y267: 1 | Z267: 6 | AA267: 39.56 | AB267: 130 | AC267: 1.11 | AD267: 0.01 | AE267: 0 | AF267: 0 | AG267: 1 | AH267: 1.11 | AI267: 1.11 | AJ267: 1.11 | AK267: 0.01 | AL267: 0.01 | AM267: 0.01 | AN267: 0 | AO267: 0 | AP267: 0 | AQ267: 39.561407 | AR267: 0 | AS267: =_xlfn.XLOOKUP(B267,InstallDate!$H$2:$H$389,InstallDate!$BE$2:$BE$389) -> 1 | AT267: =IF(COUNTIF(AR267:AS267,1)=0,0,SUM(AR267:AS267)/COUNTIF(AR267:AS267,1)) -> 1 | AU267: =AC267/MAX($AC$2:$AC$389) -> 0.0089135148 | AV267: =IF($AU267>=_xlfn.PERCENTILE.INC($AU$2:$AU$369,AV$1),4,0) -> 0 | AW267: =IF($AU267>=_xlfn.PERCENTILE.INC($AU$2:$AU$369,AW$1),3,0) -> 0 | AX267: =IF($AU267>=_xlfn.PERCENTILE.INC($AU$2:$AU$369,AX$1),2,0) -> 0 | AY267: =IF(SUM(AV267:AX267)<1,1,0) -> 1 | AZ267: =IF(AND(MAX(AV267:AY267)>2,AS267=1),3,IF(AND(MAX(AV267:AY267)<=2,AS267=1),2,IF(AND(MAX(AV267:AY267)>1,AS267=0),2,1))) -> 2
...

Sheet Sheet1
A1: PipeID | B1: Material | C1: Age | D1: Length | E1: Diameter | F1: Condition | G1: CoF_Value
A2: =Louisa_wConduits_Input_CSV!B2 -> P787 | B2: =_xlfn.XLOOKUP(A2,[1]Conduits_Condition!$A$2:$A$389,[1]Conduits_Condition!$B$2:$B$389) -> DI | C2: =YEAR(TODAY())-_xlfn.XLOOKUP(A2,InstallDate!$B$2:$B$389,InstallDate!$BD$2:$BD$389) -> 96 | D2: =Louisa_wConduits_Input_CSV!R2 -> 49.271155 | E2: =Louisa_wConduits_Input_CSV!S2 -> 6 | F2: =_xlfn.XLOOKUP(A2,[1]LEYP_Input!A$2:A$389,[1]LEYP_Input!$C$2:$C$389) -> 1 | G2: =Louisa_wConduits_Input_CSV!AZ2 -> 1
A3: =Louisa_wConduits_Input_CSV!B3 -> P789 | B3: =_xlfn.XLOOKUP(A3,[1]Conduits_Condition!$A$2:$A$389,[1]Conduits_Condition!$B$2:$B$389) -> DI | C3: =YEAR(TODAY())-_xlfn.XLOOKUP(A3,InstallDate!$B$2:$B$389,InstallDate!$BD$2:$BD$389) -> 96 | D3: =Louisa_wConduits_Input_CSV!R3 -> 37.541067 | E3: =Louisa_wConduits_Input_CSV!S3 -> 6 | F3: =_xlfn.XLOOKUP(A3,[1]LEYP_Input!A$2:A$389,[1]LEYP_Input!$C$2:$C$389) -> 1 | G3: =Louisa_wConduits_Input_CSV!AZ3 -> 1
A4: =Louisa_wConduits_Input_CSV!B4 -> P791 | B4: =_xlfn.XLOOKUP(A4,[1]Conduits_Condition!$A$2:$A$389,[1]Conduits_Condition!$B$2:$B$389) -> DI | C4: =YEAR(TODAY())-_xlfn.XLOOKUP(A4,InstallDate!$B$2:$B$389,InstallDate!$BD$2:$BD$389) -> 96 | D4: =Louisa_wConduits_Input_CSV!R4 -> 22.046684 | E4: =Louisa_wConduits_Input_CSV!S4 -> 6 | F4: =_xlfn.XLOOKUP(A4,[1]LEYP_Input!A$2:A$389,[1]LEYP_Input!$C$2:$C$389) -> 1 | G4: =Louisa_wConduits_Input_CSV!AZ4 -> 1
A5: =Louisa_wConduits_Input_CSV!B5 -> P793 | B5: =_xlfn.XLOOKUP(A5,[1]Conduits_Condition!$A$2:$A$389,[1]Conduits_Condition!$B$2:$B$389) -> DI | C5: =YEAR(TODAY())-_xlfn.XLOOKUP(A5,InstallDate!$B$2:$B$389,InstallDate!$BD$2:$BD$389) -> 96 | D5: =Louisa_wConduits_Input_CSV!R5 -> 25.52698 | E5: =Louisa_wConduits_Input_CSV!S5 -> 6 | F5: =_xlfn.XLOOKUP(A5,[1]LEYP_Input!A$2:A$389,[1]LEYP_Input!$C$2:$C$389) -> 1 | G5: =Louisa_wConduits_Input_CSV!AZ5 -> 1
A6: =Louisa_wConduits_Input_CSV!B6 -> P795 | B6: =_xlfn.XLOOKUP(A6,[1]Conduits_Condition!$A$2:$A$389,[1]Conduits_Condition!$B$2:$B$389) -> DI | C6: =YEAR(TODAY())-_xlfn.XLOOKUP(A6,InstallDate!$B$2:$B$389,InstallDate!$BD$2:$BD$389) -> 96 | D6: =Louisa_wConduits_Input_CSV!R6 -> 30.261047 | E6: =Louisa_wConduits_Input_CSV!S6 -> 6 | F6: =_xlfn.XLOOKUP(A6,[1]LEYP_Input!A$2:A$389,[1]LEYP_Input!$C$2:$C$389) -> 1 | G6: =Louisa_wConduits_Input_CSV!AZ6 -> 1
A7: =Louisa_wConduits_Input_CSV!B7 -> P797 | B7: =_xlfn.XLOOKUP(A7,[1]Conduits_Condition!$A$2:$A$389,[1]Conduits_Condition!$B$2:$B$389) -> DI | C7: =YEAR(TODAY())-_xlfn.XLOOKUP(A7,InstallDate!$B$2:$B$389,InstallDate!$BD$2:$BD$389) -> 96 | D7: =Louisa_wConduits_Input_CSV!R7 -> 28.800563 | E7: =Louisa_wConduits_Input_CSV!S7 -> 6 | F7: =_xlfn.XLOOKUP(A7,[1]LEYP_Input!A$2:A$389,[1]LEYP_Input!$C$2:$C$389) -> 1 | G7: =Louisa_wConduits_Input_CSV!AZ7 -> 1
A8: =Louisa_wConduits_Input_CSV!B8 -> P799 | B8: =_xlfn.XLOOKUP(A8,[1]Conduits_Condition!$A$2:$A$389,[1]Conduits_Condition!$B$2:$B$389) -> DI | C8: =YEAR(TODAY())-_xlfn.XLOOKUP(A8,InstallDate!$B$2:$B$389,InstallDate!$BD$2:$BD$389) -> 96 | D8: =Louisa_wConduits_Input_CSV!R8 -> 29.686093 | E8: =Louisa_wConduits_Input_CSV!S8 -> 6 | F8: =_xlfn.XLOOKUP(A8,[1]LEYP_Input!A$2:A$389,[1]LEYP_Input!$C$2:$C$389) -> 1 | G8: =Louisa_wConduits_Input_CSV!AZ8 -> 1
A9: =Louisa_wConduits_Input_CSV!B9 -> P801 | B9: =_xlfn.XLOOKUP(A9,[1]Conduits_Condition!$A$2:$A$389,[1]Conduits_Condition!$B$2:$B$389) -> DI | C9: =YEAR(TODAY())-_xlfn.XLOOKUP(A9,InstallDate!$B$2:$B$389,InstallDate!$BD$2:$BD$389) -> 96 | D9: =Louisa_wConduits_Input_CSV!R9 -> 23.980235 | E9: =Louisa_wConduits_Input_CSV!S9 -> 6 | F9: =_xlfn.XLOOKUP(A9,[1]LEYP_Input!A$2:A$389,[1]LEYP_Input!$C$2:$C$389) -> 1 | G9: =Louisa_wConduits_Input_CSV!AZ9 -> 1
A10: =Louisa_wConduits_Input_CSV!B10 -> P803 | B10: =_xlfn.XLOOKUP(A10,[1]Conduits_Condition!$A$2:$A$389,[1]Conduits_Condition!$B$2:$B$389) -> DI | C10: =YEAR(TODAY())-_xlfn.XLOOKUP(A10,InstallDate!$B$2:$B$389,InstallDate!$BD$2:$BD$389) -> 76 | D10: =Louisa_wConduits_Input_CSV!R10 -> 169.1279 | E10: =Louisa_wConduits_Input_CSV!S10 -> 6 | F10: =_xlfn.XLOOKUP(A10,[1]LEYP_Input!A$2:A$389,[1]LEYP_Input!$C$2:$C$389) -> 1 | G10: =Louisa_wConduits_Input_CSV!AZ10 -> 1
A11: =Louisa_wConduits_Input_CSV!B11 -> P805 | B11: =_xlfn.XLOOKUP(A11,[1]Conduits_Condition!$A$2:$A$389,[1]Conduits_Condition!$B$2:$B$389) -> DI | C11: =YEAR(TODAY())-_xlfn.XLOOKUP(A11,InstallDate!$B$2:$B$389,InstallDate!$BD$2:$BD$389) -> 96 | D11: =Louisa_wConduits_Input_CSV!R11 -> 14.144057 | E11: =Louisa_wConduits_Input_CSV!S11 -> 6 | F11: =_xlfn.XLOOKUP(A11,[1]LEYP_Input!A$2:A$389,[1]LEYP_Input!$C$2:$C$389) -> 1 | G11: =Louisa_wConduits_Input_CSV!AZ11 -> 1
A12: =Louisa_wConduits_Input_CSV!B12 -> P807 | B12: =_xlfn.XLOOKUP(A12,[1]Conduits_Condition!$A$2:$A$389,[1]Conduits_Condition!$B$2:$B$389) -> DI | C12: =YEAR(TODAY())-_xlfn.XLOOKUP(A12,InstallDate!$B$2:$B$389,InstallDate!$BD$2:$BD$389) -> 46 | D12: =Louisa_wConduits_Input_CSV!R12 -> 23.356306 | E12: =Louisa_wConduits_Input_CSV!S12 -> 6 | F12: =_xlfn.XLOOKUP(A12,[1]LEYP_Input!A$2:A$389,[1]LEYP_Input!$C$2:$C$389) -> 1 | G12: =Louisa_wConduits_Input_CSV!AZ12 -> 1
A13: =Louisa_wConduits_Input_CSV!B13 -> P809 | B13: =_xlfn.XLOOKUP(A13,[1]Conduits_Condition!$A$2:$A$389,[1]Conduits_Condition!$B$2:$B$389) -> DI | C13: =YEAR(TODAY())-_xlfn.XLOOKUP(A13,InstallDate!$B$2:$B$389,InstallDate!$BD$2:$BD$389) -> 46 | D13: =Louisa_wConduits_Input_CSV!R13 -> 12.924218 | E13: =Louisa_wConduits_Input_CSV!S13 -> 6 | F13: =_xlfn.XLOOKUP(A13,[1]LEYP_Input!A$2:A$389,[1]LEYP_Input!$C$2:$C$389) -> 1 | G13: =Louisa_wConduits_Input_CSV!AZ13 -> 1
... A389: =Louisa_wConduits_Input_CSV!B389 -> P2337 | B389: =_xlfn.XLOOKUP(A389,[1]Conduits_Condition!$A$2:$A$389,[1]Conduits_Condition!$B$2:$B$389) -> PVC | C389: =YEAR(TODAY())-_xlfn.XLOOKUP(A389,InstallDate!$B$2:$B$389,InstallDate!$BD$2:$BD$389) -> 26 | D389: =Louisa_wConduits_Input_CSV!R389 -> 100 | E389: =Louisa_wConduits_Input_CSV!S389 -> 6 | F389: =_xlfn.XLOOKUP(A389,[1]LEYP_Input!A$2:A$389,[1]LEYP_Input!$C$2:$C$389) -> 2 | G389: =Louisa_wConduits_Input_CSV!AZ389 -> 3

Sheet InstallDate
A1: wPipes_Nominal_Flow.OBJECTID | B1: wPipes_Nominal_Flow.MOID | C1: wPipes_Nominal_Flow.MOTYPE | D1: wPipes_Nominal_Flow.SELCODE | E1: wPipes_Nominal_Flow.DSPCODE | F1: wPipes_Nominal_Flow.UDFTYPE | G1: wPipes_Nominal_Flow.LDMTYPE | H1: wPipes_Nominal_Flow.ID | I1: wPipes_Nominal_Flow.DESCRIPT | J1: wPipes_Nominal_Flow.YR_INST | K1: wPipes_Nominal_Flow.YR_RETIRE | L1: wPipes_Nominal_Flow.ZONE | M1: wPipes_Nominal_Flow.MATERIAL | N1: wPipes_Nominal_Flow.LINING | O1: wPipes_Nominal_Flow.COST_ID | P1: wPipes_Nominal_Flow.PHASE | Q1: wPipes_Nominal_Flow.ID_1 | R1: wPipes_Nominal_Flow.LENGTH | S1: wPipes_Nominal_Flow.DIAMETER | T1: wPipes_Nominal_Flow.ROUGHNESS | U1: wPipes_Nominal_Flow.MINORLOSS | V1: wPipes_Nominal_Flow.TOTALIZER | W1: wPipes_Nominal_Flow.CHK_VALVE | X1: wPipes_Nominal_Flow.ID_12 | Y1: wPipes_Nominal_Flow.DIRECTION | Z1: wPipes_Nominal_Flow.RUN_DIAM | AA1: wPipes_Nominal_Flow.RUN_LENGTH | AB1: wPipes_Nominal_Flow.RUN_ROUGH | AC1: wPipes_Nominal_Flow.FLOW | AD1: wPipes_Nominal_Flow.VELOCITY | AE1: wPipes_Nominal_Flow.HEADLOSS | AF1: wPipes_Nominal_Flow.HL1000 | AG1: wPipes_Nominal_Flow.STATUS | AH1: wPipes_Nominal_Flow.MAX_FLOW | AI1: wPipes_Nominal_Flow.MIN_FLOW | AJ1: wPipes_Nominal_Flow.AVE_FLOW | AK1: wPipes_Nominal_Flow.MAX_VELOC | AL1: wPipes_Nominal_Flow.MIN_VELOC | AM1: wPipes_Nominal_Flow.AVE_VELOC | AN1: wPipes_Nominal_Flow.MAX_HDLOSS | AO1: wPipes_Nominal_Flow.MIN_HDLOSS | AP1: wPipes_Nominal_Flow.AVE_HDLOSS | AQ1: wPipes_Nominal_Flow.SHAPE_Length | AR1: wPipes_Nominal_Flow.Crtical_Xing | AS1: wPipes_Nominal_Flow_AddSpatialJoin_1.OBJECTID | AT1: wPipes_Nominal_Flow_AddSpatialJoin_1.Join_Count | AU1: wPipes_Nominal_Flow_AddSpatialJoin_1.TARGET_FID | AV1: wPipes_Nominal_Flow_AddSpatialJoin_1.DIA | AW1: wPipes_Nominal_Flow_AddSpatialJoin_1.LABEL | AX1: wPipes_Nominal_Flow_AddSpatialJoin_1.MATERIAL | AY1: wPipes_Nominal_Flow_AddSpatialJoin_1.NOTES | AZ1: wPipes_Nominal_Flow_AddSpatialJoin_1.START_ID | BA1: wPipes_Nominal_Flow_AddSpatialJoin_1.START_NODE | BB1: wPipes_Nominal_Flow_AddSpatialJoin_1.STOP_ID | BC1: wPipes_Nominal_Flow_AddSpatialJoin_1.STOP_NODE | BD1: wPipes_Nominal_Flow_AddSpatialJoin_1.INSTR_YR | BE1: wPipes_Nominal_Flow_AddSpatialJoin_1.CRITICAL_PIPE | BF1: wPipes_Nominal_Flow_AddSpatialJoin_1.SHAPE_Length
A2: 1 | B2: P787 | C2: 0 | H2: P787 | I2: Ductile Iron | Q2: P787 | R2: 49.271155 | S2: 6 | T2: 130 | V2: 0 | W2: 0 | X2: P787 | Y2: 0 | Z2: 6 | AA2: 49.27 | AB2: 130 | AC2: 0 | AD2: 0 | AE2: 0 | AF2: 0 | AG2: 1 | AH2: 0 | AI2: 0 | AJ2: 0 | AK2: 0 | AL2: 0 | AM2: 0 | AN2: 0 | AO2: 0 | AP2: 0 | AQ2: 49.271155 | AR2: 0 | AS2: 1 | AT2: 1 | AU2: 1 | AV2: 6 | AW2: L-1 | AX2: Ductile Iron | AZ2: 1505 | BA2: H-5 | BB2: 1674 | BC2: J-673 | BD2: 1930 | BE2: 0 | BF2: 49.271011
A3: 2 | B3: P789 | C3: 0 | H3: P789 | I3: Ductile Iron | Q3: P789 | R3: 37.541067 | S3: 6 | T3: 130 | V3: 0 | W3: 0 | X3: P789 | Y3: 0 | Z3: 6 | AA3: 37.54 | AB3: 130 | AC3: 0 | AD3: 0 | AE3: 0 | AF3: 0 | AG3: 1 | AH3: 0 | AI3: 0 | AJ3: 0 | AK3: 0 | AL3: 0 | AM3: 0 | AN3: 0 | AO3: 0 | AP3: 0 | AQ3: 37.541067 | AR3: 0 | AS3: 2 | AT3: 1 | AU3: 2 | AV3: 6 | AW3: L-2 | AX3: Ductile Iron | AZ3: 1506 | BA3: H-6 | BB3: 855 | BC3: J-533 | BD3: 1930 | BE3: 0 | BF3: 37.541311
A4: 3 | B4: P791 | C4: 0 | H4: P791 | I4: Ductile Iron | Q4: P791 | R4: 22.046684 | S4: 6 | T4: 130 | V4: 0 | W4: 0 | X4: P791 | Y4: 0 | Z4: 6 | AA4: 22.05 | AB4: 130 | AC4: 0 | AD4: 0 | AE4: 0 | AF4: 0 | AG4: 1 | AH4: 0 | AI4: 0 | AJ4: 0 | AK4: 0 | AL4: 0 | AM4: 0 | AN4: 0 | AO4: 0 | AP4: 0 | AQ4: 22.046684 | AR4: 0 | AS4: 3 | AT4: 1 | AU4: 3 | AV4: 6 | AW4: L-3 | AX4: Ductile Iron | AZ4: 1507 | BA4: H-7 | BB4: 1675 | BC4: J-674 | BD4: 1930 | BE4: 0 | BF4: 22.04643
A5: 4 | B5: P793 | C5: 0 | H5: P793 | I5: Ductile Iron | Q5: P793 | R5: 25.52698 | S5: 6 | T5: 130 | V5: 0 | W5: 0 | X5: P793 | Y5: 0 | Z5: 6 | AA5: 25.53 | AB5: 130 | AC5: 0 | AD5: 0 | AE5: 0 | AF5: 0 | AG5: 1 | AH5: 0 | AI5: 0 | AJ5: 0 | AK5: 0 | AL5: 0 | AM5: 0 | AN5: 0 | AO5: 0 | AP5: 0 | AQ5: 25.52698 | AR5: 0 | AS5: 4 | AT5: 1 | AU5: 4 | AV5: 6 | AW5: L-4 | AX5: Ductile Iron | AZ5: 1508 | BA5: H-8 | BB5: 1676 | BC5: J-675 | BD5: 1930 | BE5: 0 | BF5: 25.526843
A6: 5 | B6: P795 | C6: 0 | H6: P795 | I6: Ductile Iron | Q6: P795 | R6: 30.261047 | S6: 6 | T6: 130 | V6: 0 | W6: 0 | X6: P795 | Y6: 0 | Z6: 6 | AA6: 30.26 | AB6: 130 | AC6: 0 | AD6: 0 | AE6: 0 | AF6: 0 | AG6: 1 | AH6: 0 | AI6: 0 | AJ6: 0 | AK6: 0 | AL6: 0 | AM6: 0 | AN6: 0 | AO6: 0 | AP6: 0 | AQ6: 30.261047 | AR6: 0 | AS6: 5 | AT6: 1 | AU6: 5 | AV6: 6 | AW6: L-5 | AX6: Ductile Iron | AZ6: 1509 | BA6: H-9 | BB6: 1677 | BC6: J-676 | BD6: 1930 | BE6: 0 | BF6: 30.260771
A7: 6 | B7: P797 | C7: 0 | H7: P797 | I7: Ductile Iron | Q7: P797 | R7: 28.800563 | S7: 6 | T7: 130 | V7: 0 | W7: 0 | X7: P797 | Y7: 0 | Z7: 6 | AA7: 28.8 | AB7: 130 | AC7: 0 | AD7: 0 | AE7: 0 | AF7: 0 | AG7: 1 | AH7: 0 | AI7: 0 | AJ7: 0 | AK7: 0 | AL7: 0 | AM7: 0 | AN7: 0 | AO7: 0 | AP7: 0 | AQ7: 28.800563 | AR7: 0 | AS7: 6 | AT7: 1 | AU7: 6 | AV7: 6 | AW7: L-6 | AX7: Ductile Iron | AZ7: 1510 | BA7: H-10 | BB7: 1678 | BC7: J-677 | BD7: 1930 | BE7: 0 | BF7: 28.800282
A8: 7 | B8: P799 | C8: 0 | H8: P799 | I8: Ductile Iron | Q8: P799 | R8: 29.686093 | S8: 6 | T8: 130 | V8: 0 | W8: 0 | X8: P799 | Y8: 0 | Z8: 6 | AA8: 29.69 | AB8: 130 | AC8: 0 | AD8: 0 | AE8: 0 | AF8: 0 | AG8: 1 | AH8: 0 | AI8: 0 | AJ8: 0 | AK8: 0 | AL8: 0 | AM8: 0 | AN8: 0 | AO8: 0 | AP8: 0 | AQ8: 29.686093 | AR8: 0 | AS8: 7 | AT8: 1 | AU8: 7 | AV8: 6 | AW8: L-7 | AX8: Ductile Iron | AZ8: 1511 | BA8: H-11 | BB8: 1679 | BC8: J-678 | BD8: 1930 | BE8: 0 | BF8: 29.685964
A9: 8 | B9: P801 | C9: 0 | H9: P801 | I9: Ductile Iron | Q9: P801 | R9: 23.980235 | S9: 6 | T9: 130 | V9: 0 | W9: 0 | X9: P801 | Y9: 0 | Z9: 6 | AA9: 23.98 | AB9: 130 | AC9: 0 | AD9: 0 | AE9: 0 | AF9: 0 | AG9: 1 | AH9: 0 | AI9: 0 | AJ9: 0 | AK9: 0 | AL9: 0 | AM9: 0 | AN9: 0 | AO9: 0 | AP9: 0 | AQ9: 23.980235 | AR9: 0 | AS9: 8 | AT9: 1 | AU9: 8 | AV9: 6 | AW9: L-8 | AX9: Ductile Iron | AZ9: 1512 | BA9: H-12 | BB9: 1001 | BC9: J-626 | BD9: 1930 | BE9: 0 | BF9: 23.980277
A10: 9 | B10: P803 | C10: 0 | H10: P803 | I10: Ductile Iron | Q10: P803 | R10: 169.1279 | S10: 6 | T10: 130 | V10: 0 | W10: 0 | X10: P803 | Y10: 0 | Z10: 6 | AA10: 169.13 | AB10: 130 | AC10: 0 | AD10: 0 | AE10: 0 | AF10: 0 | AG10: 1 | AH10: 0 | AI10: 0 | AJ10: 0 | AK10: 0 | AL10: 0 | AM10: 0 | AN10: 0 | AO10: 0 | AP10: 0 | AQ10: 169.1279 | AR10: 0 | AS10: 9 | AT10: 1 | AU10: 9 | AV10: 8 | AW10: Pipes_DWG-127(2)(2)(2) | AX10: Asbestos Cement | AZ10: 1680 | BA10: J-679 | BB10: 866 | BC10: J-540 | BD10: 1950 | BE10: 0 | BF10: 549.34873
A11: 10 | B11: P805 | C11: 0 | H11: P805 | I11: Ductile Iron | Q11: P805 | R11: 14.144057 | S11: 6 | T11: 130 | V11: 0 | W11: 0 | X11: P805 | Y11: 0 | Z11: 6 | AA11: 14.14 | AB11: 130 | AC11: 0 | AD11: 0 | AE11: 0 | AF11: 0 | AG11: 1 | AH11: 0 | AI11: 0 | AJ11: 0 | AK11: 0 | AL11: 0 | AM11: 0 | AN11: 0 | AO11: 0 | AP11: 0 | AQ11: 14.144057 | AR11: 0 | AS11: 10 | AT11: 1 | AU11: 10 | AV11: 6 | AW11: L-10 | AX11: Ductile Iron | AZ11: 1514 | BA11: H-14 | BB11: 944 | BC11: J-591 | BD11: 1930 | BE11: 0 | BF11: 14.144113
A12: 11 | B12: P807 | C12: 0 | H12: P807 | I12: Ductile Iron | Q12: P807 | R12: 23.356306 | S12: 6 | T12: 130 | V12: 0 | W12: 0 | X12: P807 | Y12: 0 | Z12: 6 | AA12: 23.36 | AB12: 130 | AC12: 0 | AD12: 0 | AE12: 0 | AF12: 0 | AG12: 1 | AH12: 0 | AI12: 0 | AJ12: 0 | AK12: 0 | AL12: 0 | AM12: 0 | AN12: 0 | AO12: 0 | AP12: 0 | AQ12: 23.356306 | AR12: 0 | AS12: 11 | AT12: 1 | AU12: 11 | AV12: 6 | AW12: Pipes_DWG-84(2)(2)(1)(1) | AX12: PVC | AZ12: 905 | BA12: J-566 | BB12: 1681 | BC12: J-680 | BD12: 1980 | BE12: 0 | BF12: 66.359591
A13: 12 | B13: P809 | C13: 0 | H13: P809 | I13: Ductile Iron | Q13: P809 | R13: 12.924218 | S13: 6 | T13: 130 | V13: 0 | W13: 0 | X13: P809 | Y13: 0 | Z13: 6 | AA13: 12.92 | AB13: 130 | AC13: 0 | AD13: 0 | AE13: 0 | AF13: 0 | AG13: 1 | AH13: 0 | AI13: 0 | AJ13: 0 | AK13: 0 | AL13: 0 | AM13: 0 | AN13: 0 | AO13: 0 | AP13: 0 | AQ13: 12.924218 | AR13: 0 | AS13: 12 | AT13: 1 | AU13: 12 | AV13: 6 | AW13: Pipes_DWG-84(2)(1)(1) | AX13: PVC | AZ13: 1041 | BA13: J-646 | BB13: 1682 | BC13: J-681 | BD13: 1980 | BE13: 0 | BF13: 275.02126
... A129: 128 | B129: P1041 | C129: 0 | H129: P1041 | I129: Asbestos Cement | Q129: P1041 | R129: 26.673927 | S129: 6 | T129: 130 | V129: 0 | W129: 0 | X129: P1041 | Y129: 1 | Z129: 6 | AA129: 26.67 | AB129: 130 | AC129: 1.39 | AD129: 0.02 | AE129: 0 | AF129: 0 | AG129: 1 | AH129: 1.39 | AI129: 1.39 | AJ129: 1.39 | AK129: 0.02 | AL129: 0.02 | AM129: 0.02 | AN129: 0 | AO129: 0 | AP129: 0 | AQ129: 26.673927 | AR129: 0 | AS129: 128 | AT129: 1 | AU129: 128 | AV129: 6 | AW129: Pipes_DWG-110(2)(2) | AX129: Asbestos Cement | AZ129: 1693 | BA129: J-692 | BB129: 893 | BC129: J-558 | BD129: 1950 | BE129: 0 | BF129: 641.33283
A130: 129 | B130: P1045 | C130: 0 | H130: P1045 | Q130: P1045 | R130: 641 | S130: 6 | T130: 130 | U130: 0 | V130: 0 | W130: 0 | X130: P1045 | Y130: 1 | Z130: 6 | AA130: 641 | AB130: 130 | AC130: 1.39 | AD130: 0.02 | AE130: 0 | AF130: 0 | AG130: 1 | AH130: 1.39 | AI130: 1.39 | AJ130: 1.39 | AK130: 0.02 | AL130: 0.02 | AM130: 0.02 | AN130: 0 | AO130: 0 | AP130: 0 | AQ130: 614.08345 | AR130: 0 | AS130: 129 | AT130: 1 | AU130: 129 | AV130: 6 | AW130: Pipes_DWG-110(2)(2) | AX130: Asbestos Cement | AZ130: 1693 | BA130: J-692 | BB130: 893 | BC130: J-558 | BD130: 1950 | BE130: 0 | BF130: 641.33283
A131: 130 | B131: P1047 | C131: 0 | H131: P1047 | I131: Asbestos Cement | Q131: P1047 | R131: 378.26525 | S131: 6 | T131: 130 | V131: 0 | W131: 0 | X131: P1047 | Y131: 1 | Z131: 6 | AA131: 378.27 | AB131: 130 | AC131: 1.39 | AD131: 0.02 | AE131: 0 | AF131: 0 | AG131: 1 | AH131: 1.39 | AI131: 1.39 | AJ131: 1.39 | AK131: 0.02 | AL131: 0.02 | AM131: 0.02 | AN131: 0 | AO131: 0 | AP131: 0 | AQ131: 378.26525 | AR131: 0 | AS131: 130 | AT131: 1 | AU131: 130 | AV131: 6 | AW131: L-28 | AX131: Ductile Iron | AZ131: 1532 | BA131: H-32 | BB131: 894 | BC131: J-559 | BD131: 1930 | BE131: 0 | BF131: 56.958055
A132: 131 | B132: P1049 | C132: 0 | H132: P1049 | I132: Cast Iron | Q132: P1049 | R132: 22.167175 | S132: 6 | T132: 130 | V132: 0 | W132: 0 | X132: P1049 | Y132: -1 | Z132: 6 | AA132: 22.17 | AB132: 130 | AC132: 18.01 | AD132: 0.2 | AE132: 0 | AF132: 0.04 | AG132: 1 | AH132: 18.01 | AI132: 18.01 | AJ132: 18.01 | AK132: 0.2 | AL132: 0.2 | AM132: 0.2 | AN132: 0 | AO132: 0 | AP132: 0 | AQ132: 22.167175 | AR132: 0 | AS132: 131 | AT132: 1 | AU132: 131 | AV132: 6 | AW132: L-24 | AX132: Ductile Iron | AZ132: 1528 | BA132: H-28 | BB132: 1692 | BC132: J-691 | BD132: 1930 | BE132: 0 | BF132: 13.749245
A133: 132 | B133: P1051 | C133: 0 | H133: P1051 | I133: Cast Iron | Q133: P1051 | R133: 287.34181 | S133: 6 | T133: 130 | V133: 0 | W133: 0 | X133: P1051 | Y133: -1 | Z133: 6 | AA133: 287.34 | AB133: 130 | AC133: 18.29 | AD133: 0.21 | AE133: 0.01 | AF133: 0.04 | AG133: 1 | AH133: 18.29 | AI133: 18.29 | AJ133: 18.29 | AK133: 0.21 | AL133: 0.21 | AM133: 0.21 | AN133: 0.01 | AO133: 0.01 | AP133: 0.01 | AQ133: 287.34181 | AR133: 0 | AS133: 132 | AT133: 1 | AU133: 132 | AV133: 6 | AW133: L-23 | AX133: Ductile Iron | AZ133: 1527 | BA133: H-27 | BB133: 1691 | BC133: J-690 | BD133: 1930 | BE133: 0 | BF133: 13.388312
A134: 133 | B134: P1053 | C134: 0 | H134: P1053 | I134: Cast Iron | Q134: P1053 | R134: 87.760714 | S134: 6 | T134: 130 | V134: 0 | W134: 0 | X134: P1053 | Y134: -1 | Z134: 6 | AA134: 87.76 | AB134: 130 | AC134: 18.57 | AD134: 0.21 | AE134: 0 | AF134: 0.05 | AG134: 1 | AH134: 18.57 | AI134: 18.57 | AJ134: 18.57 | AK134: 0.21 | AL134: 0.21 | AM134: 0.21 | AN134: 0 | AO134: 0 | AP134: 0 | AQ134: 87.760714 | AR134: 0 | AS134: 133 | AT134: 1 | AU134: 133 | AV134: 6 | AW134: Pipes_DWG-85 | AX134: Ductile Iron | AZ134: 840 | BA134: J-523 | BB134: 841 | BC134: J-524 | BD134: 1930 | BE134: 0 | BF134: 84.748866
A135: 134 | B135: P1055 | C135: 0 | H135: P1055 | I135: Cast Iron | Q135: P1055 | R135: 50.641312 | S135: 6 | T135: 130 | V135: 0 | W135: 0 | X135: P1055 | Y135: -1 | Z135: 6 | AA135: 50.64 | AB135: 130 | AC135: 19.26 | AD135: 0.22 | AE135: 0 | AF135: 0.05 | AG135: 1 | AH135: 19.26 | AI135: 19.26 | AJ135: 19.26 | AK135: 0.22 | AL135: 0.22 | AM135: 0.22 | AN135: 0 | AO135: 0 | AP135: 0 | AQ135: 50.641312 | AR135: 0 | AS135: 134 | AT135: 1 | AU135: 134 | AV135: 6 | AW135: Pipes_DWG-85 | AX135: Ductile Iron | AZ135: 840 | BA135: J-523 | BB135: 841 | BC135: J-524 | BD135: 1930 | BE135: 0 | BF135: 84.748866
A136: 135 | B136: P1057 | C136: 0 | H136: P1057 | I136: Cast Iron | Q136: P1057 | R136: 29.594034 | S136: 6 | T136: 130 | V136: 0 | W136: 0 | X136: P1057 | Y136: -1 | Z136: 6 | AA136: 29.59 | AB136: 130 | AC136: 1.39 | AD136: 0.02 | AE136: 0 | AF136: 0 | AG136: 1 | AH136: 1.39 | AI136: 1.39 | AJ136: 1.39 | AK136: 0.02 | AL136: 0.02 | AM136: 0.02 | AN136: 0 | AO136: 0 | AP136: 0 | AQ136: 29.594034 | AR136: 1 | AS136: 135 | AT136: 1 | AU136: 135 | AV136: 6 | AW136: Pipes_DWG-112(2)(1) | AX136: Cast Iron | AZ136: 971 | BA136: J-607 | BB136: 955 | BC136: J-598 | BD136: 1930 | BE136: 1 | BF136: 121.52453
A137: 136 | B137: P1059 | C137: 0 | H137: P1059 | I137: Cast Iron | Q137: P1059 | R137: 91.930452 | S137: 6 | T137: 130 | V137: 0 | W137: 0 | X137: P1059 | Y137: -1 | Z137: 6 | AA137: 91.93 | AB137: 130 | AC137: 1.39 | AD137: 0.02 | AE137: 0 | AF137: 0 | AG137: 1 | AH137: 1.39 | AI137: 1.39 | AJ137: 1.39 | AK137: 0.02 | AL137: 0.02 | AM137: 0.02 | AN137: 0 | AO137: 0 | AP137: 0 | AQ137: 91.930452 | AR137: 1 | AS137: 136 | AT137: 1 | AU137: 136 | AV137: 6 | AW137: Pipes_DWG-107(2)(2) | AX137: Cast Iron | AZ137: 1690 | BA137: J-689 | BB137: 955 | BC137: J-598 | BD137: 1930 | BE137: 1 | BF137: 311.94435
A138: 137 | B138: P1061 | C138: 0 | H138: P1061 | I138: Cast Iron | Q138: P1061 | R138: 530.42279 | S138: 6 | T138: 130 | V138: 0 | W138: 0 | X138: P1061 | Y138: -1 | Z138: 6 | AA138: 530.42 | AB138: 130 | AC138: 23.66 | AD138: 0.27 | AE138: 0.04 | AF138: 0.07 | AG138: 1 | AH138: 23.66 | AI138: 23.66 | AJ138: 23.66 | AK138: 0.27 | AL138: 0.27 | AM138: 0.27 | AN138: 0.04 | AO138: 0.04 | AP138: 0.04 | AQ138: 530.42279 | AR138: 1 | AS138: 137 | AT138: 1 | AU138: 137 | AV138: 6 | AW138: L-22 | AX138: Ductile Iron | AZ138: 1526 | BA138: H-26 | BB138: 955 | BC138: J-598 | BD138: 1930 | BE138: 0 | BF138: 10.041727
A139: 138 | B139: P1063 | C139: 0 | H139: P1063 | I139: Cast Iron | Q139: P1063 | R139: 32.062249 | S139: 6 | T139: 130 | V139: 0 | W139: 0 | X139: P1063 | Y139: 1 | Z139: 6 | AA139: 32.06 | AB139: 130 | AC139: 4.63 | AD139: 0.05 | AE139: 0 | AF139: 0 | AG139: 1 | AH139: 4.63 | AI139: 4.63 | AJ139: 4.63 | AK139: 0.05 | AL139: 0.05 | AM139: 0.05 | AN139: 0 | AO139: 0 | AP139: 0 | AQ139: 32.062249 | AR139: 0 | AS139: 138 | AT139: 1 | AU139: 138 | AV139: 6 | AW139: Pipes_DWG-113(1) | AX139: Cast Iron | AZ139: 969 | BA139: J-606 | BB139: 1697 | BC139: J-696 | BD139: 1930 | BE139: 1 | BF139: 189.10888
