Workbook

Sheet Conduits_Condition
A1: PIPE_ID | B1: MATERIAL | C1: PIPE_ID_1 | D1: No_Action | E1: Inst_Yr | F1: Rehab_Yr | G1: Age | H1: Condition | I1: 0 | J1: =I1+1 -> 1 | K1: =J1+1 -> 2 | L1: =K1+1 -> 3 | M1: =L1+1 -> 4 | N1: =M1+1 -> 5 | O1: =N1+1 -> 6 | P1: =O1+1 -> 7 | Q1: =P1+1 -> 8 | ... DD1: =DC1+1 -> 99
A2: P787 | B2: DI | C2: P787 | D2: 0 | E2: 1930 | G2: =IF(ISNUMBER(F2),(YEAR(TODAY())-(F2)),YEAR(TODAY())-E2) -> 96 | H2: =_xlfn.LET( _xlpm.score,_xlfn.XLOOKUP(G2,DecayFns!$A$2:$A$289,DecayFns!$N$2:$N$289), IF(D2=1,IF(_xlpm.score=6,_xlpm.score,_xlpm.score+1),IF(_xlpm.score=1,_xlpm.score,_xlpm.score-1) )) -> 1 | I2: {=H2-_xlfn.XLOOKUP(I$1,Cdel!$B$1:$KC$1,IF(ROUNDUP(H2,0)=6,Cdel!$B$8:$KC$8,IF(ROUNDUP(H2,0)=5,Cdel!$B$9:$KC$9,IF(ROUNDUP(H2,0)=4,Cdel!$B$10:$KC$10,IF(ROUNDUP(H2,0)=3,Cdel!$B$11:$KC$11,IF(ROUNDUP(H2,0)=2,Cdel!$B$12:$KC$12,IF(ROUNDUP(H2,0)=1,Cdel!$B$13:$KC$13)))))))} -> 1 | J2: {=I2-_xlfn.XLOOKUP(J$1,Cdel!$B$1:$KC$1,IF(ROUNDUP(I2,0)=6,Cdel!$B$8:$KC$8,IF(ROUNDUP(I2,0)=5,Cdel!$B$9:$KC$9,IF(ROUNDUP(I2,0)=4,Cdel!$B$10:$KC$10,IF(ROUNDUP(I2,0)=3,Cdel!$B$11:$KC$11,IF(ROUNDUP(I2,0)=2,Cdel!$B$12:$KC$12,IF(ROUNDUP(I2,0)=1,Cdel!$B$13:$KC$13)))))))} -> 0.97233735 | K2: {=J2-_xlfn.XLOOKUP(K$1,Cdel!$B$1:$KC$1,IF(ROUNDUP(J2,0)=6,Cdel!$B$8:$KC$8,IF(ROUNDUP(J2,0)=5,Cdel!$B$9:$KC$9,IF(ROUNDUP(J2,0)=4,Cdel!$B$10:$KC$10,IF(ROUNDUP(J2,0)=3,Cdel!$B$11:$KC$11,IF(ROUNDUP(J2,0)=2,Cdel!$B$12:$KC$12,IF(ROUNDUP(J2,0)=1,Cdel!$B$13:$KC$13)))))))} -> 0.94543993 | L2: {=K2-_xlfn.XLOOKUP(L$1,Cdel!$B$1:$KC$1,IF(ROUNDUP(K2,0)=6,Cdel!$B$8:$KC$8,IF(ROUNDUP(K2,0)=5,Cdel!$B$9:$KC$9,IF(ROUNDUP(K2,0)=4,Cdel!$B$10:$KC$10,IF(ROUNDUP(K2,0)=3,Cdel!$B$11:$KC$11,IF(ROUNDUP(K2,0)=2,Cdel!$B$12:$KC$12,IF(ROUNDUP(K2,0)=1,Cdel!$B$13:$KC$13)))))))} -> 0.91928656 | M2: {=L2-_xlfn.XLOOKUP(M$1,Cdel!$B$1:$KC$1,IF(ROUNDUP(L2,0)=6,Cdel!$B$8:$KC$8,IF(ROUNDUP(L2,0)=5,Cdel!$B$9:$KC$9,IF(ROUNDUP(L2,0)=4,Cdel!$B$10:$KC$10,IF(ROUNDUP(L2,0)=3,Cdel!$B$11:$KC$11,IF(ROUNDUP(L2,0)=2,Cdel!$B$12:$KC$12,IF(ROUNDUP(L2,0)=1,Cdel!$B$13:$KC$13)))))))} -> 0.89385666 | N2: {=M2-_xlfn.XLOOKUP(N$1,Cdel!$B$1:$KC$1,IF(ROUNDUP(M2,0)=6,Cdel!$B$8:$KC$8,IF(ROUNDUP(M2,0)=5,Cdel!$B$9:$KC$9,IF(ROUNDUP(M2,0)=4,Cdel!$B$10:$KC$10,IF(ROUNDUP(M2,0)=3,Cdel!$B$11:$KC$11,IF(ROUNDUP(M2,0)=2,Cdel!$B$12:$KC$12,IF(ROUNDUP(M2,0)=1,Cdel!$B$13:$KC$13)))))))} -> 0.86913022 | O2: {=N2-_xlfn.XLOOKUP(O$1,Cdel!$B$1:$KC$1,IF(ROUNDUP(N2,0)=6,Cdel!$B$8:$KC$8,IF(ROUNDUP(N2,0)=5,Cdel!$B$9:$KC$9,IF(ROUNDUP(N2,0)=4,Cdel!$B$10:$KC$10,IF(ROUNDUP(N2,0)=3,Cdel!$B$11:$KC$11,IF(ROUNDUP(N2,0)=2,Cdel!$B$12:$KC$12,IF(ROUNDUP(N2,0)=1,Cdel!$B$13:$KC$13)))))))} -> 0.84508778 | P2: {=O2-_xlfn.XLOOKUP(P$1,Cdel!$B$1:$KC$1,IF(ROUNDUP(O2,0)=6,Cdel!$B$8:$KC$8,IF(ROUNDUP(O2,0)=5,Cdel!$B$9:$KC$9,IF(ROUNDUP(O2,0)=4,Cdel!$B$10:$KC$10,IF(ROUNDUP(O2,0)=3,Cdel!$B$11:$KC$11,IF(ROUNDUP(O2,0)=2,Cdel!$B$12:$KC$12,IF(ROUNDUP(O2,0)=1,Cdel!$B$13:$KC$13)))))))} -> 0.82171041 | ... DD2: {=DC2-_xlfn.XLOOKUP(DD$1,Cdel!$B$1:$KC$1,IF(ROUNDUP(DC2,0)=6,Cdel!$B$8:$KC$8,IF(ROUNDUP(DC2,0)=5,Cdel!$B$9:$KC$9,IF(ROUNDUP(DC2,0)=4,Cdel!$B$10:$KC$10,IF(ROUNDUP(DC2,0)=3,Cdel!$B$11:$KC$11,IF(ROUNDUP(DC2,0)=2,Cdel!$B$12:$KC$12,IF(ROUNDUP(DC2,0)=1,Cdel!$B$13:$KC$13)))))))} -> 0.062212841
A3: P789 | B3: DI | C3: P789 | D3: 0 | E3: 1930 | G3: =IF(ISNUMBER(F3),(YEAR(TODAY())-(F3)),YEAR(TODAY())-E3) -> 96 | H3: =_xlfn.LET( _xlpm.score,_xlfn.XLOOKUP(G3,DecayFns!$A$2:$A$289,DecayFns!$N$2:$N$289), IF(D3=1,IF(_xlpm.score=6,_xlpm.score,_xlpm.score+1),IF(_xlpm.score=1,_xlpm.score,_xlpm.score-1) )) -> 1 | I3: {=H3-_xlfn.XLOOKUP(I$1,Cdel!$B$1:$KC$1,IF(ROUNDUP(H3,0)=6,Cdel!$B$8:$KC$8,IF(ROUNDUP(H3,0)=5,Cdel!$B$9:$KC$9,IF(ROUNDUP(H3,0)=4,Cdel!$B$10:$KC$10,IF(ROUNDUP(H3,0)=3,Cdel!$B$11:$KC$11,IF(ROUNDUP(H3,0)=2,Cdel!$B$12:$KC$12,IF(ROUNDUP(H3,0)=1,Cdel!$B$13:$KC$13)))))))} -> 1 | J3: {=I3-_xlfn.XLOOKUP(J$1,Cdel!$B$1:$KC$1,IF(ROUNDUP(I3,0)=6,Cdel!$B$8:$KC$8,IF(ROUNDUP(I3,0)=5,Cdel!$B$9:$KC$9,IF(ROUNDUP(I3,0)=4,Cdel!$B$10:$KC$10,IF(ROUNDUP(I3,0)=3,Cdel!$B$11:$KC$11,IF(ROUNDUP(I3,0)=2,Cdel!$B$12:$KC$12,IF(ROUNDUP(I3,0)=1,Cdel!$B$13:$KC$13)))))))} -> 0.97233735 | K3: {=J3-_xlfn.XLOOKUP(K$1,Cdel!$B$1:$KC$1,IF(ROUNDUP(J3,0)=6,Cdel!$B$8:$KC$8,IF(ROUNDUP(J3,0)=5,Cdel!$B$9:$KC$9,IF(ROUNDUP(J3,0)=4,Cdel!$B$10:$KC$10,IF(ROUNDUP(J3,0)=3,Cdel!$B$11:$KC$11,IF(ROUNDUP(J3,0)=2,Cdel!$B$12:$KC$12,IF(ROUNDUP(J3,0)=1,Cdel!$B$13:$KC$13)))))))} -> 0.94543993 | L3: {=K3-_xlfn.XLOOKUP(L$1,Cdel!$B$1:$KC$1,IF(ROUNDUP(K3,0)=6,Cdel!$B$8:$KC$8,IF(ROUNDUP(K3,0)=5,Cdel!$B$9:$KC$9,IF(ROUNDUP(K3,0)=4,Cdel!$B$10:$KC$10,IF(ROUNDUP(K3,0)=3,Cdel!$B$11:$KC$11,IF(ROUNDUP(K3,0)=2,Cdel!$B$12:$KC$12,IF(ROUNDUP(K3,0)=1,Cdel!$B$13:$KC$13)))))))} -> 0.91928656 | M3: {=L3-_xlfn.XLOOKUP(M$1,Cdel!$B$1:$KC$1,IF(ROUNDUP(L3,0)=6,Cdel!$B$8:$KC$8,IF(ROUNDUP(L3,0)=5,Cdel!$B$9:$KC$9,IF(ROUNDUP(L3,0)=4,Cdel!$B$10:$KC$10,IF(ROUNDUP(L3,0)=3,Cdel!$B$11:$KC$11,IF(ROUNDUP(L3,0)=2,Cdel!$B$12:$KC$12,IF(ROUNDUP(L3,0)=1,Cdel!$B$13:$KC$13)))))))} -> 0.89385666 | N3: {=M3-_xlfn.XLOOKUP(N$1,Cdel!$B$1:$KC$1,IF(ROUNDUP(M3,0)=6,Cdel!$B$8:$KC$8,IF(ROUNDUP(M3,0)=5,Cdel!$B$9:$KC$9,IF(ROUNDUP(M3,0)=4,Cdel!$B$10:$KC$10,IF(ROUNDUP(M3,0)=3,Cdel!$B$11:$KC$11,IF(ROUNDUP(M3,0)=2,Cdel!$B$12:$KC$12,IF(ROUNDUP(M3,0)=1,Cdel!$B$13:$KC$13)))))))} -> 0.86913022 | O3: {=N3-_xlfn.XLOOKUP(O$1,Cdel!$B$1:$KC$1,IF(ROUNDUP(N3,0)=6,Cdel!$B$8:$KC$8,IF(ROUNDUP(N3,0)=5,Cdel!$B$9:$KC$9,IF(ROUNDUP(N3,0)=4,Cdel!$B$10:$KC$10,IF(ROUNDUP(N3,0)=3,Cdel!$B$11:$KC$11,IF(ROUNDUP(N3,0)=2,Cdel!$B$12:$KC$12,IF(ROUNDUP(N3,0)=1,Cdel!$B$13:$KC$13)))))))} -> 0.84508778 | P3: {=O3-_xlfn.XLOOKUP(P$1,Cdel!$B$1:$KC$1,IF(ROUNDUP(O3,0)=6,Cdel!$B$8:$KC$8,IF(ROUNDUP(O3,0)=5,Cdel!$B$9:$KC$9,IF(ROUNDUP(O3,0)=4,Cdel!$B$10:$KC$10,IF(ROUNDUP(O3,0)=3,Cdel!$B$11:$KC$11,IF(ROUNDUP(O3,0)=2,Cdel!$B$12:$KC$12,IF(ROUNDUP(O3,0)=1,Cdel!$B$13:$KC$13)))))))} -> 0.82171041 | ... DD3: {=DC3-_xlfn.XLOOKUP(DD$1,Cdel!$B$1:$KC$1,IF(ROUNDUP(DC3,0)=6,Cdel!$B$8:$KC$8,IF(ROUNDUP(DC3,0)=5,Cdel!$B$9:$KC$9,IF(ROUNDUP(DC3,0)=4,Cdel!$B$10:$KC$10,IF(ROUNDUP(DC3,0)=3,Cdel!$B$11:$KC$11,IF(ROUNDUP(DC3,0)=2,Cdel!$B$12:$KC$12,IF(ROUNDUP(DC3,0)=1,Cdel!$B$13:$KC$13)))))))} -> 0.062212841
A4: P791 | B4: DI | C4: P791 | D4: 0 | E4: 1930 | G4: =IF(ISNUMBER(F4),(YEAR(TODAY())-(F4)),YEAR(TODAY())-E4) -> 96 | H4: =_xlfn.LET( _xlpm.score,_xlfn.XLOOKUP(G4,DecayFns!$A$2:$A$289,DecayFns!$N$2:$N$289), IF(D4=1,IF(_xlpm.score=6,_xlpm.score,_xlpm.score+1),IF(_xlpm.score=1,_xlpm.score,_xlpm.score-1) )) -> 1 | I4: {=H4-_xlfn.XLOOKUP(I$1,Cdel!$B$1:$KC$1,IF(ROUNDUP(H4,0)=6,Cdel!$B$8:$KC$8,IF(ROUNDUP(H4,0)=5,Cdel!$B$9:$KC$9,IF(ROUNDUP(H4,0)=4,Cdel!$B$10:$KC$10,IF(ROUNDUP(H4,0)=3,Cdel!$B$11:$KC$11,IF(ROUNDUP(H4,0)=2,Cdel!$B$12:$KC$12,IF(ROUNDUP(H4,0)=1,Cdel!$B$13:$KC$13)))))))} -> 1 | J4: {=I4-_xlfn.XLOOKUP(J$1,Cdel!$B$1:$KC$1,IF(ROUNDUP(I4,0)=6,Cdel!$B$8:$KC$8,IF(ROUNDUP(I4,0)=5,Cdel!$B$9:$KC$9,IF(ROUNDUP(I4,0)=4,Cdel!$B$10:$KC$10,IF(ROUNDUP(I4,0)=3,Cdel!$B$11:$KC$11,IF(ROUNDUP(I4,0)=2,Cdel!$B$12:$KC$12,IF(ROUNDUP(I4,0)=1,Cdel!$B$13:$KC$13)))))))} -> 0.97233735 | K4: {=J4-_xlfn.XLOOKUP(K$1,Cdel!$B$1:$KC$1,IF(ROUNDUP(J4,0)=6,Cdel!$B$8:$KC$8,IF(ROUNDUP(J4,0)=5,Cdel!$B$9:$KC$9,IF(ROUNDUP(J4,0)=4,Cdel!$B$10:$KC$10,IF(ROUNDUP(J4,0)=3,Cdel!$B$11:$KC$11,IF(ROUNDUP(J4,0)=2,Cdel!$B$12:$KC$12,IF(ROUNDUP(J4,0)=1,Cdel!$B$13:$KC$13)))))))} -> 0.94543993 | L4: {=K4-_xlfn.XLOOKUP(L$1,Cdel!$B$1:$KC$1,IF(ROUNDUP(K4,0)=6,Cdel!$B$8:$KC$8,IF(ROUNDUP(K4,0)=5,Cdel!$B$9:$KC$9,IF(ROUNDUP(K4,0)=4,Cdel!$B$10:$KC$10,IF(ROUNDUP(K4,0)=3,Cdel!$B$11:$KC$11,IF(ROUNDUP(K4,0)=2,Cdel!$B$12:$KC$12,IF(ROUNDUP(K4,0)=1,Cdel!$B$13:$KC$13)))))))} -> 0.91928656 | M4: {=L4-_xlfn.XLOOKUP(M$1,Cdel!$B$1:$KC$1,IF(ROUNDUP(L4,0)=6,Cdel!$B$8:$KC$8,IF(ROUNDUP(L4,0)=5,Cdel!$B$9:$KC$9,IF(ROUNDUP(L4,0)=4,Cdel!$B$10:$KC$10,IF(ROUNDUP(L4,0)=3,Cdel!$B$11:$KC$11,IF(ROUNDUP(L4,0)=2,Cdel!$B$12:$KC$12,IF(ROUNDUP(L4,0)=1,Cdel!$B$13:$KC$13)))))))} -> 0.89385666 | N4: {=M4-_xlfn.XLOOKUP(N$1,Cdel!$B$1:$KC$1,IF(ROUNDUP(M4,0)=6,Cdel!$B$8:$KC$8,IF(ROUNDUP(M4,0)=5,Cdel!$B$9:$KC$9,IF(ROUNDUP(M4,0)=4,Cdel!$B$10:$KC$10,IF(ROUNDUP(M4,0)=3,Cdel!$B$11:$KC$11,IF(ROUNDUP(M4,0)=2,Cdel!$B$12:$KC$12,IF(ROUNDUP(M4,0)=1,Cdel!$B$13:$KC$13)))))))} -> 0.86913022 | O4: {=N4-_xlfn.XLOOKUP(O$1,Cdel!$B$1:$KC$1,IF(ROUNDUP(N4,0)=6,Cdel!$B$8:$KC$8,IF(ROUNDUP(N4,0)=5,Cdel!$B$9:$KC$9,IF(ROUNDUP(N4,0)=4,Cdel!$B$10:$KC$10,IF(ROUNDUP(N4,0)=3,Cdel!$B$11:$KC$11,IF(ROUNDUP(N4,0)=2,Cdel!$B$12:$KC$12,IF(ROUNDUP(N4,0)=1,Cdel!$B$13:$KC$13)))))))} -> 0.84508778 | P4: {=O4-_xlfn.XLOOKUP(P$1,Cdel!$B$1:$KC$1,IF(ROUNDUP(O4,0)=6,Cdel!$B$8:$KC$8,IF(ROUNDUP(O4,0)=5,Cdel!$B$9:$KC$9,IF(ROUNDUP(O4,0)=4,Cdel!$B$10:$KC$10,IF(ROUNDUP(O4,0)=3,Cdel!$B$11:$KC$11,IF(ROUNDUP(O4,0)=2,Cdel!$B$12:$KC$12,IF(ROUNDUP(O4,0)=1,Cdel!$B$13:$KC$13)))))))} -> 0.82171041 | ... DD4: {=DC4-_xlfn.XLOOKUP(DD$1,Cdel!$B$1:$KC$1,IF(ROUNDUP(DC4,0)=6,Cdel!$B$8:$KC$8,IF(ROUNDUP(DC4,0)=5,Cdel!$B$9:$KC$9,IF(ROUNDUP(DC4,0)=4,Cdel!$B$10:$KC$10,IF(ROUNDUP(DC4,0)=3,Cdel!$B$11:$KC$11,IF(ROUNDUP(DC4,0)=2,Cdel!$B$12:$KC$12,IF(ROUNDUP(DC4,0)=1,Cdel!$B$13:$KC$13)))))))} -> 0.062212841
A5: P793 | B5: DI | C5: P793 | D5: 0 | E5: 1930 | G5: =IF(ISNUMBER(F5),(YEAR(TODAY())-(F5)),YEAR(TODAY())-E5) -> 96 | H5: =_xlfn.LET( _xlpm.score,_xlfn.XLOOKUP(G5,DecayFns!$A$2:$A$289,DecayFns!$N$2:$N$289), IF(D5=1,IF(_xlpm.score=6,_xlpm.score,_xlpm.score+1),IF(_xlpm.score=1,_xlpm.score,_xlpm.score-1) )) -> 1 | I5: {=H5-_xlfn.XLOOKUP(I$1,Cdel!$B$1:$KC$1,IF(ROUNDUP(H5,0)=6,Cdel!$B$8:$KC$8,IF(ROUNDUP(H5,0)=5,Cdel!$B$9:$KC$9,IF(ROUNDUP(H5,0)=4,Cdel!$B$10:$KC$10,IF(ROUNDUP(H5,0)=3,Cdel!$B$11:$KC$11,IF(ROUNDUP(H5,0)=2,Cdel!$B$12:$KC$12,IF(ROUNDUP(H5,0)=1,Cdel!$B$13:$KC$13)))))))} -> 1 | J5: {=I5-_xlfn.XLOOKUP(J$1,Cdel!$B$1:$KC$1,IF(ROUNDUP(I5,0)=6,Cdel!$B$8:$KC$8,IF(ROUNDUP(I5,0)=5,Cdel!$B$9:$KC$9,IF(ROUNDUP(I5,0)=4,Cdel!$B$10:$KC$10,IF(ROUNDUP(I5,0)=3,Cdel!$B$11:$KC$11,IF(ROUNDUP(I5,0)=2,Cdel!$B$12:$KC$12,IF(ROUNDUP(I5,0)=1,Cdel!$B$13:$KC$13)))))))} -> 0.97233735 | K5: {=J5-_xlfn.XLOOKUP(K$1,Cdel!$B$1:$KC$1,IF(ROUNDUP(J5,0)=6,Cdel!$B$8:$KC$8,IF(ROUNDUP(J5,0)=5,Cdel!$B$9:$KC$9,IF(ROUNDUP(J5,0)=4,Cdel!$B$10:$KC$10,IF(ROUNDUP(J5,0)=3,Cdel!$B$11:$KC$11,IF(ROUNDUP(J5,0)=2,Cdel!$B$12:$KC$12,IF(ROUNDUP(J5,0)=1,Cdel!$B$13:$KC$13)))))))} -> 0.94543993 | L5: {=K5-_xlfn.XLOOKUP(L$1,Cdel!$B$1:$KC$1,IF(ROUNDUP(K5,0)=6,Cdel!$B$8:$KC$8,IF(ROUNDUP(K5,0)=5,Cdel!$B$9:$KC$9,IF(ROUNDUP(K5,0)=4,Cdel!$B$10:$KC$10,IF(ROUNDUP(K5,0)=3,Cdel!$B$11:$KC$11,IF(ROUNDUP(K5,0)=2,Cdel!$B$12:$KC$12,IF(ROUNDUP(K5,0)=1,Cdel!$B$13:$KC$13)))))))} -> 0.91928656 | M5: {=L5-_xlfn.XLOOKUP(M$1,Cdel!$B$1:$KC$1,IF(ROUNDUP(L5,0)=6,Cdel!$B$8:$KC$8,IF(ROUNDUP(L5,0)=5,Cdel!$B$9:$KC$9,IF(ROUNDUP(L5,0)=4,Cdel!$B$10:$KC$10,IF(ROUNDUP(L5,0)=3,Cdel!$B$11:$KC$11,IF(ROUNDUP(L5,0)=2,Cdel!$B$12:$KC$12,IF(ROUNDUP(L5,0)=1,Cdel!$B$13:$KC$13)))))))} -> 0.89385666 | N5: {=M5-_xlfn.XLOOKUP(N$1,Cdel!$B$1:$KC$1,IF(ROUNDUP(M5,0)=6,Cdel!$B$8:$KC$8,IF(ROUNDUP(M5,0)=5,Cdel!$B$9:$KC$9,IF(ROUNDUP(M5,0)=4,Cdel!$B$10:$KC$10,IF(ROUNDUP(M5,0)=3,Cdel!$B$11:$KC$11,IF(ROUNDUP(M5,0)=2,Cdel!$B$12:$KC$12,IF(ROUNDUP(M5,0)=1,Cdel!$B$13:$KC$13)))))))} -> 0.86913022 | O5: {=N5-_xlfn.XLOOKUP(O$1,Cdel!$B$1:$KC$1,IF(ROUNDUP(N5,0)=6,Cdel!$B$8:$KC$8,IF(ROUNDUP(N5,0)=5,Cdel!$B$9:$KC$9,IF(ROUNDUP(N5,0)=4,Cdel!$B$10:$KC$10,IF(ROUNDUP(N5,0)=3,Cdel!$B$11:$KC$11,IF(ROUNDUP(N5,0)=2,Cdel!$B$12:$KC$12,IF(ROUNDUP(N5,0)=1,Cdel!$B$13:$KC$13)))))))} -> 0.84508778 | P5: {=O5-_xlfn.XLOOKUP(P$1,Cdel!$B$1:$KC$1,IF(ROUNDUP(O5,0)=6,Cdel!$B$8:$KC$8,IF(ROUNDUP(O5,0)=5,Cdel!$B$9:$KC$9,IF(ROUNDUP(O5,0)=4,Cdel!$B$10:$KC$10,IF(ROUNDUP(O5,0)=3,Cdel!$B$11:$KC$11,IF(ROUNDUP(O5,0)=2,Cdel!$B$12:$KC$12,IF(ROUNDUP(O5,0)=1,Cdel!$B$13:$KC$13)))))))} -> 0.82171041 | ... DD5: {=DC5-_xlfn.XLOOKUP(DD$1,Cdel!$B$1:$KC$1,IF(ROUNDUP(DC5,0)=6,Cdel!$B$8:$KC$8,IF(ROUNDUP(DC5,0)=5,Cdel!$B$9:$KC$9,IF(ROUNDUP(DC5,0)=4,Cdel!$B$10:$KC$10,IF(ROUNDUP(DC5,0)=3,Cdel!$B$11:$KC$11,IF(ROUNDUP(DC5,0)=2,Cdel!$B$12:$KC$12,IF(ROUNDUP(DC5,0)=1,Cdel!$B$13:$KC$13)))))))} -> 0.062212841
A6: P795 | B6: DI | C6: P795 | D6: 0 | E6: 1930 | G6: =IF(ISNUMBER(F6),(YEAR(TODAY())-(F6)),YEAR(TODAY())-E6) -> 96 | H6: =_xlfn.LET( _xlpm.score,_xlfn.XLOOKUP(G6,DecayFns!$A$2:$A$289,DecayFns!$N$2:$N$289), IF(D6=1,IF(_xlpm.score=6,_xlpm.score,_xlpm.score+1),IF(_xlpm.score=1,_xlpm.score,_xlpm.score-1) )) -> 1 | I6: {=H6-_xlfn.XLOOKUP(I$1,Cdel!$B$1:$KC$1,IF(ROUNDUP(H6,0)=6,Cdel!$B$8:$KC$8,IF(ROUNDUP(H6,0)=5,Cdel!$B$9:$KC$9,IF(ROUNDUP(H6,0)=4,Cdel!$B$10:$KC$10,IF(ROUNDUP(H6,0)=3,Cdel!$B$11:$KC$11,IF(ROUNDUP(H6,0)=2,Cdel!$B$12:$KC$12,IF(ROUNDUP(H6,0)=1,Cdel!$B$13:$KC$13)))))))} -> 1 | J6: {=I6-_xlfn.XLOOKUP(J$1,Cdel!$B$1:$KC$1,IF(ROUNDUP(I6,0)=6,Cdel!$B$8:$KC$8,IF(ROUNDUP(I6,0)=5,Cdel!$B$9:$KC$9,IF(ROUNDUP(I6,0)=4,Cdel!$B$10:$KC$10,IF(ROUNDUP(I6,0)=3,Cdel!$B$11:$KC$11,IF(ROUNDUP(I6,0)=2,Cdel!$B$12:$KC$12,IF(ROUNDUP(I6,0)=1,Cdel!$B$13:$KC$13)))))))} -> 0.97233735 | K6: {=J6-_xlfn.XLOOKUP(K$1,Cdel!$B$1:$KC$1,IF(ROUNDUP(J6,0)=6,Cdel!$B$8:$KC$8,IF(ROUNDUP(J6,0)=5,Cdel!$B$9:$KC$9,IF(ROUNDUP(J6,0)=4,Cdel!$B$10:$KC$10,IF(ROUNDUP(J6,0)=3,Cdel!$B$11:$KC$11,IF(ROUNDUP(J6,0)=2,Cdel!$B$12:$KC$12,IF(ROUNDUP(J6,0)=1,Cdel!$B$13:$KC$13)))))))} -> 0.94543993 | L6: {=K6-_xlfn.XLOOKUP(L$1,Cdel!$B$1:$KC$1,IF(ROUNDUP(K6,0)=6,Cdel!$B$8:$KC$8,IF(ROUNDUP(K6,0)=5,Cdel!$B$9:$KC$9,IF(ROUNDUP(K6,0)=4,Cdel!$B$10:$KC$10,IF(ROUNDUP(K6,0)=3,Cdel!$B$11:$KC$11,IF(ROUNDUP(K6,0)=2,Cdel!$B$12:$KC$12,IF(ROUNDUP(K6,0)=1,Cdel!$B$13:$KC$13)))))))} -> 0.91928656 | M6: {=L6-_xlfn.XLOOKUP(M$1,Cdel!$B$1:$KC$1,IF(ROUNDUP(L6,0)=6,Cdel!$B$8:$KC$8,IF(ROUNDUP(L6,0)=5,Cdel!$B$9:$KC$9,IF(ROUNDUP(L6,0)=4,Cdel!$B$10:$KC$10,IF(ROUNDUP(L6,0)=3,Cdel!$B$11:$KC$11,IF(ROUNDUP(L6,0)=2,Cdel!$B$12:$KC$12,IF(ROUNDUP(L6,0)=1,Cdel!$B$13:$KC$13)))))))} -> 0.89385666 | N6: {=M6-_xlfn.XLOOKUP(N$1,Cdel!$B$1:$KC$1,IF(ROUNDUP(M6,0)=6,Cdel!$B$8:$KC$8,IF(ROUNDUP(M6,0)=5,Cdel!$B$9:$KC$9,IF(ROUNDUP(M6,0)=4,Cdel!$B$10:$KC$10,IF(ROUNDUP(M6,0)=3,Cdel!$B$11:$KC$11,IF(ROUNDUP(M6,0)=2,Cdel!$B$12:$KC$12,IF(ROUNDUP(M6,0)=1,Cdel!$B$13:$KC$13)))))))} -> 0.86913022 | O6: {=N6-_xlfn.XLOOKUP(O$1,Cdel!$B$1:$KC$1,IF(ROUNDUP(N6,0)=6,Cdel!$B$8:$KC$8,IF(ROUNDUP(N6,0)=5,Cdel!$B$9:$KC$9,IF(ROUNDUP(N6,0)=4,Cdel!$B$10:$KC$10,IF(ROUNDUP(N6,0)=3,Cdel!$B$11:$KC$11,IF(ROUNDUP(N6,0)=2,Cdel!$B$12:$KC$12,IF(ROUNDUP(N6,0)=1,Cdel!$B$13:$KC$13)))))))} -> 0.84508778 | P6: {=O6-_xlfn.XLOOKUP(P$1,Cdel!$B$1:$KC$1,IF(ROUNDUP(O6,0)=6,Cdel!$B$8:$KC$8,IF(ROUNDUP(O6,0)=5,Cdel!$B$9:$KC$9,IF(ROUNDUP(O6,0)=4,Cdel!$B$10:$KC$10,IF(ROUNDUP(O6,0)=3,Cdel!$B$11:$KC$11,IF(ROUNDUP(O6,0)=2,Cdel!$B$12:$KC$12,IF(ROUNDUP(O6,0)=1,Cdel!$B$13:$KC$13)))))))} -> 0.82171041 | ... DD6: {=DC6-_xlfn.XLOOKUP(DD$1,Cdel!$B$1:$KC$1,IF(ROUNDUP(DC6,0)=6,Cdel!$B$8:$KC$8,IF(ROUNDUP(DC6,0)=5,Cdel!$B$9:$KC$9,IF(ROUNDUP(DC6,0)=4,Cdel!$B$10:$KC$10,IF(ROUNDUP(DC6,0)=3,Cdel!$B$11:$KC$11,IF(ROUNDUP(DC6,0)=2,Cdel!$B$12:$KC$12,IF(ROUNDUP(DC6,0)=1,Cdel!$B$13:$KC$13)))))))} -> 0.062212841
A7: P797 | B7: DI | C7: P797 | D7: 0 | E7: 1930 | G7: =IF(ISNUMBER(F7),(YEAR(TODAY())-(F7)),YEAR(TODAY())-E7) -> 96 | H7: =_xlfn.LET( _xlpm.score,_xlfn.XLOOKUP(G7,DecayFns!$A$2:$A$289,DecayFns!$N$2:$N$289), IF(D7=1,IF(_xlpm.score=6,_xlpm.score,_xlpm.score+1),IF(_xlpm.score=1,_xlpm.score,_xlpm.score-1) )) -> 1 | I7: {=H7-_xlfn.XLOOKUP(I$1,Cdel!$B$1:$KC$1,IF(ROUNDUP(H7,0)=6,Cdel!$B$8:$KC$8,IF(ROUNDUP(H7,0)=5,Cdel!$B$9:$KC$9,IF(ROUNDUP(H7,0)=4,Cdel!$B$10:$KC$10,IF(ROUNDUP(H7,0)=3,Cdel!$B$11:$KC$11,IF(ROUNDUP(H7,0)=2,Cdel!$B$12:$KC$12,IF(ROUNDUP(H7,0)=1,Cdel!$B$13:$KC$13)))))))} -> 1 | J7: {=I7-_xlfn.XLOOKUP(J$1,Cdel!$B$1:$KC$1,IF(ROUNDUP(I7,0)=6,Cdel!$B$8:$KC$8,IF(ROUNDUP(I7,0)=5,Cdel!$B$9:$KC$9,IF(ROUNDUP(I7,0)=4,Cdel!$B$10:$KC$10,IF(ROUNDUP(I7,0)=3,Cdel!$B$11:$KC$11,IF(ROUNDUP(I7,0)=2,Cdel!$B$12:$KC$12,IF(ROUNDUP(I7,0)=1,Cdel!$B$13:$KC$13)))))))} -> 0.97233735 | K7: {=J7-_xlfn.XLOOKUP(K$1,Cdel!$B$1:$KC$1,IF(ROUNDUP(J7,0)=6,Cdel!$B$8:$KC$8,IF(ROUNDUP(J7,0)=5,Cdel!$B$9:$KC$9,IF(ROUNDUP(J7,0)=4,Cdel!$B$10:$KC$10,IF(ROUNDUP(J7,0)=3,Cdel!$B$11:$KC$11,IF(ROUNDUP(J7,0)=2,Cdel!$B$12:$KC$12,IF(ROUNDUP(J7,0)=1,Cdel!$B$13:$KC$13)))))))} -> 0.94543993 | L7: {=K7-_xlfn.XLOOKUP(L$1,Cdel!$B$1:$KC$1,IF(ROUNDUP(K7,0)=6,Cdel!$B$8:$KC$8,IF(ROUNDUP(K7,0)=5,Cdel!$B$9:$KC$9,IF(ROUNDUP(K7,0)=4,Cdel!$B$10:$KC$10,IF(ROUNDUP(K7,0)=3,Cdel!$B$11:$KC$11,IF(ROUNDUP(K7,0)=2,Cdel!$B$12:$KC$12,IF(ROUNDUP(K7,0)=1,Cdel!$B$13:$KC$13)))))))} -> 0.91928656 | M7: {=L7-_xlfn.XLOOKUP(M$1,Cdel!$B$1:$KC$1,IF(ROUNDUP(L7,0)=6,Cdel!$B$8:$KC$8,IF(ROUNDUP(L7,0)=5,Cdel!$B$9:$KC$9,IF(ROUNDUP(L7,0)=4,Cdel!$B$10:$KC$10,IF(ROUNDUP(L7,0)=3,Cdel!$B$11:$KC$11,IF(ROUNDUP(L7,0)=2,Cdel!$B$12:$KC$12,IF(ROUNDUP(L7,0)=1,Cdel!$B$13:$KC$13)))))))} -> 0.89385666 | N7: {=M7-_xlfn.XLOOKUP(N$1,Cdel!$B$1:$KC$1,IF(ROUNDUP(M7,0)=6,Cdel!$B$8:$KC$8,IF(ROUNDUP(M7,0)=5,Cdel!$B$9:$KC$9,IF(ROUNDUP(M7,0)=4,Cdel!$B$10:$KC$10,IF(ROUNDUP(M7,0)=3,Cdel!$B$11:$KC$11,IF(ROUNDUP(M7,0)=2,Cdel!$B$12:$KC$12,IF(ROUNDUP(M7,0)=1,Cdel!$B$13:$KC$13)))))))} -> 0.86913022 | O7: {=N7-_xlfn.XLOOKUP(O$1,Cdel!$B$1:$KC$1,IF(ROUNDUP(N7,0)=6,Cdel!$B$8:$KC$8,IF(ROUNDUP(N7,0)=5,Cdel!$B$9:$KC$9,IF(ROUNDUP(N7,0)=4,Cdel!$B$10:$KC$10,IF(ROUNDUP(N7,0)=3,Cdel!$B$11:$KC$11,IF(ROUNDUP(N7,0)=2,Cdel!$B$12:$KC$12,IF(ROUNDUP(N7,0)=1,Cdel!$B$13:$KC$13)))))))} -> 0.84508778 | P7: {=O7-_xlfn.XLOOKUP(P$1,Cdel!$B$1:$KC$1,IF(ROUNDUP(O7,0)=6,Cdel!$B$8:$KC$8,IF(ROUNDUP(O7,0)=5,Cdel!$B$9:$KC$9,IF(ROUNDUP(O7,0)=4,Cdel!$B$10:$KC$10,IF(ROUNDUP(O7,0)=3,Cdel!$B$11:$KC$11,IF(ROUNDUP(O7,0)=2,Cdel!$B$12:$KC$12,IF(ROUNDUP(O7,0)=1,Cdel!$B$13:$KC$13)))))))} -> 0.82171041 | ... DD7: {=DC7-_xlfn.XLOOKUP(DD$1,Cdel!$B$1:$KC$1,IF(ROUNDUP(DC7,0)=6,Cdel!$B$8:$KC$8,IF(ROUNDUP(DC7,0)=5,Cdel!$B$9:$KC$9,IF(ROUNDUP(DC7,0)=4,Cdel!$B$10:$KC$10,IF(ROUNDUP(DC7,0)=3,Cdel!$B$11:$KC$11,IF(ROUNDUP(DC7,0)=2,Cdel!$B$12:$KC$12,IF(ROUNDUP(DC7,0)=1,Cdel!$B$13:$KC$13)))))))} -> 0.062212841
A8: P799 | B8: DI | C8: P799 | D8: 0 | E8: 1930 | G8: =IF(ISNUMBER(F8),(YEAR(TODAY())-(F8)),YEAR(TODAY())-E8) -> 96 | H8: =_xlfn.LET( _xlpm.score,_xlfn.XLOOKUP(G8,DecayFns!$A$2:$A$289,DecayFns!$N$2:$N$289), IF(D8=1,IF(_xlpm.score=6,_xlpm.score,_xlpm.score+1),IF(_xlpm.score=1,_xlpm.score,_xlpm.score-1) )) -> 1 | I8: {=H8-_xlfn.XLOOKUP(I$1,Cdel!$B$1:$KC$1,IF(ROUNDUP(H8,0)=6,Cdel!$B$8:$KC$8,IF(ROUNDUP(H8,0)=5,Cdel!$B$9:$KC$9,IF(ROUNDUP(H8,0)=4,Cdel!$B$10:$KC$10,IF(ROUNDUP(H8,0)=3,Cdel!$B$11:$KC$11,IF(ROUNDUP(H8,0)=2,Cdel!$B$12:$KC$12,IF(ROUNDUP(H8,0)=1,Cdel!$B$13:$KC$13)))))))} -> 1 | J8: {=I8-_xlfn.XLOOKUP(J$1,Cdel!$B$1:$KC$1,IF(ROUNDUP(I8,0)=6,Cdel!$B$8:$KC$8,IF(ROUNDUP(I8,0)=5,Cdel!$B$9:$KC$9,IF(ROUNDUP(I8,0)=4,Cdel!$B$10:$KC$10,IF(ROUNDUP(I8,0)=3,Cdel!$B$11:$KC$11,IF(ROUNDUP(I8,0)=2,Cdel!$B$12:$KC$12,IF(ROUNDUP(I8,0)=1,Cdel!$B$13:$KC$13)))))))} -> 0.97233735 | K8: {=J8-_xlfn.XLOOKUP(K$1,Cdel!$B$1:$KC$1,IF(ROUNDUP(J8,0)=6,Cdel!$B$8:$KC$8,IF(ROUNDUP(J8,0)=5,Cdel!$B$9:$KC$9,IF(ROUNDUP(J8,0)=4,Cdel!$B$10:$KC$10,IF(ROUNDUP(J8,0)=3,Cdel!$B$11:$KC$11,IF(ROUNDUP(J8,0)=2,Cdel!$B$12:$KC$12,IF(ROUNDUP(J8,0)=1,Cdel!$B$13:$KC$13)))))))} -> 0.94543993 | L8: {=K8-_xlfn.XLOOKUP(L$1,Cdel!$B$1:$KC$1,IF(ROUNDUP(K8,0)=6,Cdel!$B$8:$KC$8,IF(ROUNDUP(K8,0)=5,Cdel!$B$9:$KC$9,IF(ROUNDUP(K8,0)=4,Cdel!$B$10:$KC$10,IF(ROUNDUP(K8,0)=3,Cdel!$B$11:$KC$11,IF(ROUNDUP(K8,0)=2,Cdel!$B$12:$KC$12,IF(ROUNDUP(K8,0)=1,Cdel!$B$13:$KC$13)))))))} -> 0.91928656 | M8: {=L8-_xlfn.XLOOKUP(M$1,Cdel!$B$1:$KC$1,IF(ROUNDUP(L8,0)=6,Cdel!$B$8:$KC$8,IF(ROUNDUP(L8,0)=5,Cdel!$B$9:$KC$9,IF(ROUNDUP(L8,0)=4,Cdel!$B$10:$KC$10,IF(ROUNDUP(L8,0)=3,Cdel!$B$11:$KC$11,IF(ROUNDUP(L8,0)=2,Cdel!$B$12:$KC$12,IF(ROUNDUP(L8,0)=1,Cdel!$B$13:$KC$13)))))))} -> 0.89385666 | N8: {=M8-_xlfn.XLOOKUP(N$1,Cdel!$B$1:$KC$1,IF(ROUNDUP(M8,0)=6,Cdel!$B$8:$KC$8,IF(ROUNDUP(M8,0)=5,Cdel!$B$9:$KC$9,IF(ROUNDUP(M8,0)=4,Cdel!$B$10:$KC$10,IF(ROUNDUP(M8,0)=3,Cdel!$B$11:$KC$11,IF(ROUNDUP(M8,0)=2,Cdel!$B$12:$KC$12,IF(ROUNDUP(M8,0)=1,Cdel!$B$13:$KC$13)))))))} -> 0.86913022 | O8: {=N8-_xlfn.XLOOKUP(O$1,Cdel!$B$1:$KC$1,IF(ROUNDUP(N8,0)=6,Cdel!$B$8:$KC$8,IF(ROUNDUP(N8,0)=5,Cdel!$B$9:$KC$9,IF(ROUNDUP(N8,0)=4,Cdel!$B$10:$KC$10,IF(ROUNDUP(N8,0)=3,Cdel!$B$11:$KC$11,IF(ROUNDUP(N8,0)=2,Cdel!$B$12:$KC$12,IF(ROUNDUP(N8,0)=1,Cdel!$B$13:$KC$13)))))))} -> 0.84508778 | P8: {=O8-_xlfn.XLOOKUP(P$1,Cdel!$B$1:$KC$1,IF(ROUNDUP(O8,0)=6,Cdel!$B$8:$KC$8,IF(ROUNDUP(O8,0)=5,Cdel!$B$9:$KC$9,IF(ROUNDUP(O8,0)=4,Cdel!$B$10:$KC$10,IF(ROUNDUP(O8,0)=3,Cdel!$B$11:$KC$11,IF(ROUNDUP(O8,0)=2,Cdel!$B$12:$KC$12,IF(ROUNDUP(O8,0)=1,Cdel!$B$13:$KC$13)))))))} -> 0.82171041 | ... DD8: {=DC8-_xlfn.XLOOKUP(DD$1,Cdel!$B$1:$KC$1,IF(ROUNDUP(DC8,0)=6,Cdel!$B$8:$KC$8,IF(ROUNDUP(DC8,0)=5,Cdel!$B$9:$KC$9,IF(ROUNDUP(DC8,0)=4,Cdel!$B$10:$KC$10,IF(ROUNDUP(DC8,0)=3,Cdel!$B$11:$KC$11,IF(ROUNDUP(DC8,0)=2,Cdel!$B$12:$KC$12,IF(ROUNDUP(DC8,0)=1,Cdel!$B$13:$KC$13)))))))} -> 0.062212841
A9: P801 | B9: DI | C9: P801 | D9: 0 | E9: 1930 | G9: =IF(ISNUMBER(F9),(YEAR(TODAY())-(F9)),YEAR(TODAY())-E9) -> 96 | H9: =_xlfn.LET( _xlpm.score,_xlfn.XLOOKUP(G9,DecayFns!$A$2:$A$289,DecayFns!$N$2:$N$289), IF(D9=1,IF(_xlpm.score=6,_xlpm.score,_xlpm.score+1),IF(_xlpm.score=1,_xlpm.score,_xlpm.score-1) )) -> 1 | I9: {=H9-_xlfn.XLOOKUP(I$1,Cdel!$B$1:$KC$1,IF(ROUNDUP(H9,0)=6,Cdel!$B$8:$KC$8,IF(ROUNDUP(H9,0)=5,Cdel!$B$9:$KC$9,IF(ROUNDUP(H9,0)=4,Cdel!$B$10:$KC$10,IF(ROUNDUP(H9,0)=3,Cdel!$B$11:$KC$11,IF(ROUNDUP(H9,0)=2,Cdel!$B$12:$KC$12,IF(ROUNDUP(H9,0)=1,Cdel!$B$13:$KC$13)))))))} -> 1 | J9: {=I9-_xlfn.XLOOKUP(J$1,Cdel!$B$1:$KC$1,IF(ROUNDUP(I9,0)=6,Cdel!$B$8:$KC$8,IF(ROUNDUP(I9,0)=5,Cdel!$B$9:$KC$9,IF(ROUNDUP(I9,0)=4,Cdel!$B$10:$KC$10,IF(ROUNDUP(I9,0)=3,Cdel!$B$11:$KC$11,IF(ROUNDUP(I9,0)=2,Cdel!$B$12:$KC$12,IF(ROUNDUP(I9,0)=1,Cdel!$B$13:$KC$13)))))))} -> 0.97233735 | K9: {=J9-_xlfn.XLOOKUP(K$1,Cdel!$B$1:$KC$1,IF(ROUNDUP(J9,0)=6,Cdel!$B$8:$KC$8,IF(ROUNDUP(J9,0)=5,Cdel!$B$9:$KC$9,IF(ROUNDUP(J9,0)=4,Cdel!$B$10:$KC$10,IF(ROUNDUP(J9,0)=3,Cdel!$B$11:$KC$11,IF(ROUNDUP(J9,0)=2,Cdel!$B$12:$KC$12,IF(ROUNDUP(J9,0)=1,Cdel!$B$13:$KC$13)))))))} -> 0.94543993 | L9: {=K9-_xlfn.XLOOKUP(L$1,Cdel!$B$1:$KC$1,IF(ROUNDUP(K9,0)=6,Cdel!$B$8:$KC$8,IF(ROUNDUP(K9,0)=5,Cdel!$B$9:$KC$9,IF(ROUNDUP(K9,0)=4,Cdel!$B$10:$KC$10,IF(ROUNDUP(K9,0)=3,Cdel!$B$11:$KC$11,IF(ROUNDUP(K9,0)=2,Cdel!$B$12:$KC$12,IF(ROUNDUP(K9,0)=1,Cdel!$B$13:$KC$13)))))))} -> 0.91928656 | M9: {=L9-_xlfn.XLOOKUP(M$1,Cdel!$B$1:$KC$1,IF(ROUNDUP(L9,0)=6,Cdel!$B$8:$KC$8,IF(ROUNDUP(L9,0)=5,Cdel!$B$9:$KC$9,IF(ROUNDUP(L9,0)=4,Cdel!$B$10:$KC$10,IF(ROUNDUP(L9,0)=3,Cdel!$B$11:$KC$11,IF(ROUNDUP(L9,0)=2,Cdel!$B$12:$KC$12,IF(ROUNDUP(L9,0)=1,Cdel!$B$13:$KC$13)))))))} -> 0.89385666 | N9: {=M9-_xlfn.XLOOKUP(N$1,Cdel!$B$1:$KC$1,IF(ROUNDUP(M9,0)=6,Cdel!$B$8:$KC$8,IF(ROUNDUP(M9,0)=5,Cdel!$B$9:$KC$9,IF(ROUNDUP(M9,0)=4,Cdel!$B$10:$KC$10,IF(ROUNDUP(M9,0)=3,Cdel!$B$11:$KC$11,IF(ROUNDUP(M9,0)=2,Cdel!$B$12:$KC$12,IF(ROUNDUP(M9,0)=1,Cdel!$B$13:$KC$13)))))))} -> 0.86913022 | O9: {=N9-_xlfn.XLOOKUP(O$1,Cdel!$B$1:$KC$1,IF(ROUNDUP(N9,0)=6,Cdel!$B$8:$KC$8,IF(ROUNDUP(N9,0)=5,Cdel!$B$9:$KC$9,IF(ROUNDUP(N9,0)=4,Cdel!$B$10:$KC$10,IF(ROUNDUP(N9,0)=3,Cdel!$B$11:$KC$11,IF(ROUNDUP(N9,0)=2,Cdel!$B$12:$KC$12,IF(ROUNDUP(N9,0)=1,Cdel!$B$13:$KC$13)))))))} -> 0.84508778 | P9: {=O9-_xlfn.XLOOKUP(P$1,Cdel!$B$1:$KC$1,IF(ROUNDUP(O9,0)=6,Cdel!$B$8:$KC$8,IF(ROUNDUP(O9,0)=5,Cdel!$B$9:$KC$9,IF(ROUNDUP(O9,0)=4,Cdel!$B$10:$KC$10,IF(ROUNDUP(O9,0)=3,Cdel!$B$11:$KC$11,IF(ROUNDUP(O9,0)=2,Cdel!$B$12:$KC$12,IF(ROUNDUP(O9,0)=1,Cdel!$B$13:$KC$13)))))))} -> 0.82171041 | ... DD9: {=DC9-_xlfn.XLOOKUP(DD$1,Cdel!$B$1:$KC$1,IF(ROUNDUP(DC9,0)=6,Cdel!$B$8:$KC$8,IF(ROUNDUP(DC9,0)=5,Cdel!$B$9:$KC$9,IF(ROUNDUP(DC9,0)=4,Cdel!$B$10:$KC$10,IF(ROUNDUP(DC9,0)=3,Cdel!$B$11:$KC$11,IF(ROUNDUP(DC9,0)=2,Cdel!$B$12:$KC$12,IF(ROUNDUP(DC9,0)=1,Cdel!$B$13:$KC$13)))))))} -> 0.062212841
A10: P803 | B10: DI | C10: P803 | D10: 0 | E10: 1950 | G10: =IF(ISNUMBER(F10),(YEAR(TODAY())-(F10)),YEAR(TODAY())-E10) -> 76 | H10: =_xlfn.LET( _xlpm.score,_xlfn.XLOOKUP(G10,DecayFns!$A$2:$A$289,DecayFns!$N$2:$N$289), IF(D10=1,IF(_xlpm.score=6,_xlpm.score,_xlpm.score+1),IF(_xlpm.score=1,_xlpm.score,_xlpm.score-1) )) -> 1 | I10: {=H10-_xlfn.XLOOKUP(I$1,Cdel!$B$1:$KC$1,IF(ROUNDUP(H10,0)=6,Cdel!$B$8:$KC$8,IF(ROUNDUP(H10,0)=5,Cdel!$B$9:$KC$9,IF(ROUNDUP(H10,0)=4,Cdel!$B$10:$KC$10,IF(ROUNDUP(H10,0)=3,Cdel!$B$11:$KC$11,IF(ROUNDUP(H10,0)=2,Cdel!$B$12:$KC$12,IF(ROUNDUP(H10,0)=1,Cdel!$B$13:$KC$13)))))))} -> 1 | J10: {=I10-_xlfn.XLOOKUP(J$1,Cdel!$B$1:$KC$1,IF(ROUNDUP(I10,0)=6,Cdel!$B$8:$KC$8,IF(ROUNDUP(I10,0)=5,Cdel!$B$9:$KC$9,IF(ROUNDUP(I10,0)=4,Cdel!$B$10:$KC$10,IF(ROUNDUP(I10,0)=3,Cdel!$B$11:$KC$11,IF(ROUNDUP(I10,0)=2,Cdel!$B$12:$KC$12,IF(ROUNDUP(I10,0)=1,Cdel!$B$13:$KC$13)))))))} -> 0.97233735 | K10: {=J10-_xlfn.XLOOKUP(K$1,Cdel!$B$1:$KC$1,IF(ROUNDUP(J10,0)=6,Cdel!$B$8:$KC$8,IF(ROUNDUP(J10,0)=5,Cdel!$B$9:$KC$9,IF(ROUNDUP(J10,0)=4,Cdel!$B$10:$KC$10,IF(ROUNDUP(J10,0)=3,Cdel!$B$11:$KC$11,IF(ROUNDUP(J10,0)=2,Cdel!$B$12:$KC$12,IF(ROUNDUP(J10,0)=1,Cdel!$B$13:$KC$13)))))))} -> 0.94543993 | L10: {=K10-_xlfn.XLOOKUP(L$1,Cdel!$B$1:$KC$1,IF(ROUNDUP(K10,0)=6,Cdel!$B$8:$KC$8,IF(ROUNDUP(K10,0)=5,Cdel!$B$9:$KC$9,IF(ROUNDUP(K10,0)=4,Cdel!$B$10:$KC$10,IF(ROUNDUP(K10,0)=3,Cdel!$B$11:$KC$11,IF(ROUNDUP(K10,0)=2,Cdel!$B$12:$KC$12,IF(ROUNDUP(K10,0)=1,Cdel!$B$13:$KC$13)))))))} -> 0.91928656 | M10: {=L10-_xlfn.XLOOKUP(M$1,Cdel!$B$1:$KC$1,IF(ROUNDUP(L10,0)=6,Cdel!$B$8:$KC$8,IF(ROUNDUP(L10,0)=5,Cdel!$B$9:$KC$9,IF(ROUNDUP(L10,0)=4,Cdel!$B$10:$KC$10,IF(ROUNDUP(L10,0)=3,Cdel!$B$11:$KC$11,IF(ROUNDUP(L10,0)=2,Cdel!$B$12:$KC$12,IF(ROUNDUP(L10,0)=1,Cdel!$B$13:$KC$13)))))))} -> 0.89385666 | N10: {=M10-_xlfn.XLOOKUP(N$1,Cdel!$B$1:$KC$1,IF(ROUNDUP(M10,0)=6,Cdel!$B$8:$KC$8,IF(ROUNDUP(M10,0)=5,Cdel!$B$9:$KC$9,IF(ROUNDUP(M10,0)=4,Cdel!$B$10:$KC$10,IF(ROUNDUP(M10,0)=3,Cdel!$B$11:$KC$11,IF(ROUNDUP(M10,0)=2,Cdel!$B$12:$KC$12,IF(ROUNDUP(M10,0)=1,Cdel!$B$13:$KC$13)))))))} -> 0.86913022 | O10: {=N10-_xlfn.XLOOKUP(O$1,Cdel!$B$1:$KC$1,IF(ROUNDUP(N10,0)=6,Cdel!$B$8:$KC$8,IF(ROUNDUP(N10,0)=5,Cdel!$B$9:$KC$9,IF(ROUNDUP(N10,0)=4,Cdel!$B$10:$KC$10,IF(ROUNDUP(N10,0)=3,Cdel!$B$11:$KC$11,IF(ROUNDUP(N10,0)=2,Cdel!$B$12:$KC$12,IF(ROUNDUP(N10,0)=1,Cdel!$B$13:$KC$13)))))))} -> 0.84508778 | P10: {=O10-_xlfn.XLOOKUP(P$1,Cdel!$B$1:$KC$1,IF(ROUNDUP(O10,0)=6,Cdel!$B$8:$KC$8,IF(ROUNDUP(O10,0)=5,Cdel!$B$9:$KC$9,IF(ROUNDUP(O10,0)=4,Cdel!$B$10:$KC$10,IF(ROUNDUP(O10,0)=3,Cdel!$B$11:$KC$11,IF(ROUNDUP(O10,0)=2,Cdel!$B$12:$KC$12,IF(ROUNDUP(O10,0)=1,Cdel!$B$13:$KC$13)))))))} -> 0.82171041 | ... DD10: {=DC10-_xlfn.XLOOKUP(DD$1,Cdel!$B$1:$KC$1,IF(ROUNDUP(DC10,0)=6,Cdel!$B$8:$KC$8,IF(ROUNDUP(DC10,0)=5,Cdel!$B$9:$KC$9,IF(ROUNDUP(DC10,0)=4,Cdel!$B$10:$KC$10,IF(ROUNDUP(DC10,0)=3,Cdel!$B$11:$KC$11,IF(ROUNDUP(DC10,0)=2,Cdel!$B$12:$KC$12,IF(ROUNDUP(DC10,0)=1,Cdel!$B$13:$KC$13)))))))} -> 0.062212841
A11: P805 | B11: DI | C11: P805 | D11: 0 | E11: 1930 | G11: =IF(ISNUMBER(F11),(YEAR(TODAY())-(F11)),YEAR(TODAY())-E11) -> 96 | H11: =_xlfn.LET( _xlpm.score,_xlfn.XLOOKUP(G11,DecayFns!$A$2:$A$289,DecayFns!$N$2:$N$289), IF(D11=1,IF(_xlpm.score=6,_xlpm.score,_xlpm.score+1),IF(_xlpm.score=1,_xlpm.score,_xlpm.score-1) )) -> 1 | I11: {=H11-_xlfn.XLOOKUP(I$1,Cdel!$B$1:$KC$1,IF(ROUNDUP(H11,0)=6,Cdel!$B$8:$KC$8,IF(ROUNDUP(H11,0)=5,Cdel!$B$9:$KC$9,IF(ROUNDUP(H11,0)=4,Cdel!$B$10:$KC$10,IF(ROUNDUP(H11,0)=3,Cdel!$B$11:$KC$11,IF(ROUNDUP(H11,0)=2,Cdel!$B$12:$KC$12,IF(ROUNDUP(H11,0)=1,Cdel!$B$13:$KC$13)))))))} -> 1 | J11: {=I11-_xlfn.XLOOKUP(J$1,Cdel!$B$1:$KC$1,IF(ROUNDUP(I11,0)=6,Cdel!$B$8:$KC$8,IF(ROUNDUP(I11,0)=5,Cdel!$B$9:$KC$9,IF(ROUNDUP(I11,0)=4,Cdel!$B$10:$KC$10,IF(ROUNDUP(I11,0)=3,Cdel!$B$11:$KC$11,IF(ROUNDUP(I11,0)=2,Cdel!$B$12:$KC$12,IF(ROUNDUP(I11,0)=1,Cdel!$B$13:$KC$13)))))))} -> 0.97233735 | K11: {=J11-_xlfn.XLOOKUP(K$1,Cdel!$B$1:$KC$1,IF(ROUNDUP(J11,0)=6,Cdel!$B$8:$KC$8,IF(ROUNDUP(J11,0)=5,Cdel!$B$9:$KC$9,IF(ROUNDUP(J11,0)=4,Cdel!$B$10:$KC$10,IF(ROUNDUP(J11,0)=3,Cdel!$B$11:$KC$11,IF(ROUNDUP(J11,0)=2,Cdel!$B$12:$KC$12,IF(ROUNDUP(J11,0)=1,Cdel!$B$13:$KC$13)))))))} -> 0.94543993 | L11: {=K11-_xlfn.XLOOKUP(L$1,Cdel!$B$1:$KC$1,IF(ROUNDUP(K11,0)=6,Cdel!$B$8:$KC$8,IF(ROUNDUP(K11,0)=5,Cdel!$B$9:$KC$9,IF(ROUNDUP(K11,0)=4,Cdel!$B$10:$KC$10,IF(ROUNDUP(K11,0)=3,Cdel!$B$11:$KC$11,IF(ROUNDUP(K11,0)=2,Cdel!$B$12:$KC$12,IF(ROUNDUP(K11,0)=1,Cdel!$B$13:$KC$13)))))))} -> 0.91928656 | M11: {=L11-_xlfn.XLOOKUP(M$1,Cdel!$B$1:$KC$1,IF(ROUNDUP(L11,0)=6,Cdel!$B$8:$KC$8,IF(ROUNDUP(L11,0)=5,Cdel!$B$9:$KC$9,IF(ROUNDUP(L11,0)=4,Cdel!$B$10:$KC$10,IF(ROUNDUP(L11,0)=3,Cdel!$B$11:$KC$11,IF(ROUNDUP(L11,0)=2,Cdel!$B$12:$KC$12,IF(ROUNDUP(L11,0)=1,Cdel!$B$13:$KC$13)))))))} -> 0.89385666 | N11: {=M11-_xlfn.XLOOKUP(N$1,Cdel!$B$1:$KC$1,IF(ROUNDUP(M11,0)=6,Cdel!$B$8:$KC$8,IF(ROUNDUP(M11,0)=5,Cdel!$B$9:$KC$9,IF(ROUNDUP(M11,0)=4,Cdel!$B$10:$KC$10,IF(ROUNDUP(M11,0)=3,Cdel!$B$11:$KC$11,IF(ROUNDUP(M11,0)=2,Cdel!$B$12:$KC$12,IF(ROUNDUP(M11,0)=1,Cdel!$B$13:$KC$13)))))))} -> 0.86913022 | O11: {=N11-_xlfn.XLOOKUP(O$1,Cdel!$B$1:$KC$1,IF(ROUNDUP(N11,0)=6,Cdel!$B$8:$KC$8,IF(ROUNDUP(N11,0)=5,Cdel!$B$9:$KC$9,IF(ROUNDUP(N11,0)=4,Cdel!$B$10:$KC$10,IF(ROUNDUP(N11,0)=3,Cdel!$B$11:$KC$11,IF(ROUNDUP(N11,0)=2,Cdel!$B$12:$KC$12,IF(ROUNDUP(N11,0)=1,Cdel!$B$13:$KC$13)))))))} -> 0.84508778 | P11: {=O11-_xlfn.XLOOKUP(P$1,Cdel!$B$1:$KC$1,IF(ROUNDUP(O11,0)=6,Cdel!$B$8:$KC$8,IF(ROUNDUP(O11,0)=5,Cdel!$B$9:$KC$9,IF(ROUNDUP(O11,0)=4,Cdel!$B$10:$KC$10,IF(ROUNDUP(O11,0)=3,Cdel!$B$11:$KC$11,IF(ROUNDUP(O11,0)=2,Cdel!$B$12:$KC$12,IF(ROUNDUP(O11,0)=1,Cdel!$B$13:$KC$13)))))))} -> 0.82171041 | ... DD11: {=DC11-_xlfn.XLOOKUP(DD$1,Cdel!$B$1:$KC$1,IF(ROUNDUP(DC11,0)=6,Cdel!$B$8:$KC$8,IF(ROUNDUP(DC11,0)=5,Cdel!$B$9:$KC$9,IF(ROUNDUP(DC11,0)=4,Cdel!$B$10:$KC$10,IF(ROUNDUP(DC11,0)=3,Cdel!$B$11:$KC$11,IF(ROUNDUP(DC11,0)=2,Cdel!$B$12:$KC$12,IF(ROUNDUP(DC11,0)=1,Cdel!$B$13:$KC$13)))))))} -> 0.062212841
A12: P807 | B12: DI | C12: P807 | D12: 0 | E12: 1980 | G12: =IF(ISNUMBER(F12),(YEAR(TODAY())-(F12)),YEAR(TODAY())-E12) -> 46 | H12: =_xlfn.LET( _xlpm.score,_xlfn.XLOOKUP(G12,DecayFns!$A$2:$A$289,DecayFns!$N$2:$N$289), IF(D12=1,IF(_xlpm.score=6,_xlpm.score,_xlpm.score+1),IF(_xlpm.score=1,_xlpm.score,_xlpm.score-1) )) -> 1 | I12: {=H12-_xlfn.XLOOKUP(I$1,Cdel!$B$1:$KC$1,IF(ROUNDUP(H12,0)=6,Cdel!$B$8:$KC$8,IF(ROUNDUP(H12,0)=5,Cdel!$B$9:$KC$9,IF(ROUNDUP(H12,0)=4,Cdel!$B$10:$KC$10,IF(ROUNDUP(H12,0)=3,Cdel!$B$11:$KC$11,IF(ROUNDUP(H12,0)=2,Cdel!$B$12:$KC$12,IF(ROUNDUP(H12,0)=1,Cdel!$B$13:$KC$13)))))))} -> 1 | J12: {=I12-_xlfn.XLOOKUP(J$1,Cdel!$B$1:$KC$1,IF(ROUNDUP(I12,0)=6,Cdel!$B$8:$KC$8,IF(ROUNDUP(I12,0)=5,Cdel!$B$9:$KC$9,IF(ROUNDUP(I12,0)=4,Cdel!$B$10:$KC$10,IF(ROUNDUP(I12,0)=3,Cdel!$B$11:$KC$11,IF(ROUNDUP(I12,0)=2,Cdel!$B$12:$KC$12,IF(ROUNDUP(I12,0)=1,Cdel!$B$13:$KC$13)))))))} -> 0.97233735 | K12: {=J12-_xlfn.XLOOKUP(K$1,Cdel!$B$1:$KC$1,IF(ROUNDUP(J12,0)=6,Cdel!$B$8:$KC$8,IF(ROUNDUP(J12,0)=5,Cdel!$B$9:$KC$9,IF(ROUNDUP(J12,0)=4,Cdel!$B$10:$KC$10,IF(ROUNDUP(J12,0)=3,Cdel!$B$11:$KC$11,IF(ROUNDUP(J12,0)=2,Cdel!$B$12:$KC$12,IF(ROUNDUP(J12,0)=1,Cdel!$B$13:$KC$13)))))))} -> 0.94543993 | L12: {=K12-_xlfn.XLOOKUP(L$1,Cdel!$B$1:$KC$1,IF(ROUNDUP(K12,0)=6,Cdel!$B$8:$KC$8,IF(ROUNDUP(K12,0)=5,Cdel!$B$9:$KC$9,IF(ROUNDUP(K12,0)=4,Cdel!$B$10:$KC$10,IF(ROUNDUP(K12,0)=3,Cdel!$B$11:$KC$11,IF(ROUNDUP(K12,0)=2,Cdel!$B$12:$KC$12,IF(ROUNDUP(K12,0)=1,Cdel!$B$13:$KC$13)))))))} -> 0.91928656 | M12: {=L12-_xlfn.XLOOKUP(M$1,Cdel!$B$1:$KC$1,IF(ROUNDUP(L12,0)=6,Cdel!$B$8:$KC$8,IF(ROUNDUP(L12,0)=5,Cdel!$B$9:$KC$9,IF(ROUNDUP(L12,0)=4,Cdel!$B$10:$KC$10,IF(ROUNDUP(L12,0)=3,Cdel!$B$11:$KC$11,IF(ROUNDUP(L12,0)=2,Cdel!$B$12:$KC$12,IF(ROUNDUP(L12,0)=1,Cdel!$B$13:$KC$13)))))))} -> 0.89385666 | N12: {=M12-_xlfn.XLOOKUP(N$1,Cdel!$B$1:$KC$1,IF(ROUNDUP(M12,0)=6,Cdel!$B$8:$KC$8,IF(ROUNDUP(M12,0)=5,Cdel!$B$9:$KC$9,IF(ROUNDUP(M12,0)=4,Cdel!$B$10:$KC$10,IF(ROUNDUP(M12,0)=3,Cdel!$B$11:$KC$11,IF(ROUNDUP(M12,0)=2,Cdel!$B$12:$KC$12,IF(ROUNDUP(M12,0)=1,Cdel!$B$13:$KC$13)))))))} -> 0.86913022 | O12: {=N12-_xlfn.XLOOKUP(O$1,Cdel!$B$1:$KC$1,IF(ROUNDUP(N12,0)=6,Cdel!$B$8:$KC$8,IF(ROUNDUP(N12,0)=5,Cdel!$B$9:$KC$9,IF(ROUNDUP(N12,0)=4,Cdel!$B$10:$KC$10,IF(ROUNDUP(N12,0)=3,Cdel!$B$11:$KC$11,IF(ROUNDUP(N12,0)=2,Cdel!$B$12:$KC$12,IF(ROUNDUP(N12,0)=1,Cdel!$B$13:$KC$13)))))))} -> 0.84508778 | P12: {=O12-_xlfn.XLOOKUP(P$1,Cdel!$B$1:$KC$1,IF(ROUNDUP(O12,0)=6,Cdel!$B$8:$KC$8,IF(ROUNDUP(O12,0)=5,Cdel!$B$9:$KC$9,IF(ROUNDUP(O12,0)=4,Cdel!$B$10:$KC$10,IF(ROUNDUP(O12,0)=3,Cdel!$B$11:$KC$11,IF(ROUNDUP(O12,0)=2,Cdel!$B$12:$KC$12,IF(ROUNDUP(O12,0)=1,Cdel!$B$13:$KC$13)))))))} -> 0.82171041 | ... DD12: {=DC12-_xlfn.XLOOKUP(DD$1,Cdel!$B$1:$KC$1,IF(ROUNDUP(DC12,0)=6,Cdel!$B$8:$KC$8,IF(ROUNDUP(DC12,0)=5,Cdel!$B$9:$KC$9,IF(ROUNDUP(DC12,0)=4,Cdel!$B$10:$KC$10,IF(ROUNDUP(DC12,0)=3,Cdel!$B$11:$KC$11,IF(ROUNDUP(DC12,0)=2,Cdel!$B$12:$KC$12,IF(ROUNDUP(DC12,0)=1,Cdel!$B$13:$KC$13)))))))} -> 0.062212841
A13: P809 | B13: DI | C13: P809 | D13: 0 | E13: 1980 | G13: =IF(ISNUMBER(F13),(YEAR(TODAY())-(F13)),YEAR(TODAY())-E13) -> 46 | H13: =_xlfn.LET( _xlpm.score,_xlfn.XLOOKUP(G13,DecayFns!$A$2:$A$289,DecayFns!$N$2:$N$289), IF(D13=1,IF(_xlpm.score=6,_xlpm.score,_xlpm.score+1),IF(_xlpm.score=1,_xlpm.score,_xlpm.score-1) )) -> 1 | I13: {=H13-_xlfn.XLOOKUP(I$1,Cdel!$B$1:$KC$1,IF(ROUNDUP(H13,0)=6,Cdel!$B$8:$KC$8,IF(ROUNDUP(H13,0)=5,Cdel!$B$9:$KC$9,IF(ROUNDUP(H13,0)=4,Cdel!$B$10:$KC$10,IF(ROUNDUP(H13,0)=3,Cdel!$B$11:$KC$11,IF(ROUNDUP(H13,0)=2,Cdel!$B$12:$KC$12,IF(ROUNDUP(H13,0)=1,Cdel!$B$13:$KC$13)))))))} -> 1 | J13: {=I13-_xlfn.XLOOKUP(J$1,Cdel!$B$1:$KC$1,IF(ROUNDUP(I13,0)=6,Cdel!$B$8:$KC$8,IF(ROUNDUP(I13,0)=5,Cdel!$B$9:$KC$9,IF(ROUNDUP(I13,0)=4,Cdel!$B$10:$KC$10,IF(ROUNDUP(I13,0)=3,Cdel!$B$11:$KC$11,IF(ROUNDUP(I13,0)=2,Cdel!$B$12:$KC$12,IF(ROUNDUP(I13,0)=1,Cdel!$B$13:$KC$13)))))))} -> 0.97233735 | K13: {=J13-_xlfn.XLOOKUP(K$1,Cdel!$B$1:$KC$1,IF(ROUNDUP(J13,0)=6,Cdel!$B$8:$KC$8,IF(ROUNDUP(J13,0)=5,Cdel!$B$9:$KC$9,IF(ROUNDUP(J13,0)=4,Cdel!$B$10:$KC$10,IF(ROUNDUP(J13,0)=3,Cdel!$B$11:$KC$11,IF(ROUNDUP(J13,0)=2,Cdel!$B$12:$KC$12,IF(ROUNDUP(J13,0)=1,Cdel!$B$13:$KC$13)))))))} -> 0.94543993 | L13: {=K13-_xlfn.XLOOKUP(L$1,Cdel!$B$1:$KC$1,IF(ROUNDUP(K13,0)=6,Cdel!$B$8:$KC$8,IF(ROUNDUP(K13,0)=5,Cdel!$B$9:$KC$9,IF(ROUNDUP(K13,0)=4,Cdel!$B$10:$KC$10,IF(ROUNDUP(K13,0)=3,Cdel!$B$11:$KC$11,IF(ROUNDUP(K13,0)=2,Cdel!$B$12:$KC$12,IF(ROUNDUP(K13,0)=1,Cdel!$B$13:$KC$13)))))))} -> 0.91928656 | M13: {=L13-_xlfn.XLOOKUP(M$1,Cdel!$B$1:$KC$1,IF(ROUNDUP(L13,0)=6,Cdel!$B$8:$KC$8,IF(ROUNDUP(L13,0)=5,Cdel!$B$9:$KC$9,IF(ROUNDUP(L13,0)=4,Cdel!$B$10:$KC$10,IF(ROUNDUP(L13,0)=3,Cdel!$B$11:$KC$11,IF(ROUNDUP(L13,0)=2,Cdel!$B$12:$KC$12,IF(ROUNDUP(L13,0)=1,Cdel!$B$13:$KC$13)))))))} -> 0.89385666 | N13: {=M13-_xlfn.XLOOKUP(N$1,Cdel!$B$1:$KC$1,IF(ROUNDUP(M13,0)=6,Cdel!$B$8:$KC$8,IF(ROUNDUP(M13,0)=5,Cdel!$B$9:$KC$9,IF(ROUNDUP(M13,0)=4,Cdel!$B$10:$KC$10,IF(ROUNDUP(M13,0)=3,Cdel!$B$11:$KC$11,IF(ROUNDUP(M13,0)=2,Cdel!$B$12:$KC$12,IF(ROUNDUP(M13,0)=1,Cdel!$B$13:$KC$13)))))))} -> 0.86913022 | O13: {=N13-_xlfn.XLOOKUP(O$1,Cdel!$B$1:$KC$1,IF(ROUNDUP(N13,0)=6,Cdel!$B$8:$KC$8,IF(ROUNDUP(N13,0)=5,Cdel!$B$9:$KC$9,IF(ROUNDUP(N13,0)=4,Cdel!$B$10:$KC$10,IF(ROUNDUP(N13,0)=3,Cdel!$B$11:$KC$11,IF(ROUNDUP(N13,0)=2,Cdel!$B$12:$KC$12,IF(ROUNDUP(N13,0)=1,Cdel!$B$13:$KC$13)))))))} -> 0.84508778 | P13: {=O13-_xlfn.XLOOKUP(P$1,Cdel!$B$1:$KC$1,IF(ROUNDUP(O13,0)=6,Cdel!$B$8:$KC$8,IF(ROUNDUP(O13,0)=5,Cdel!$B$9:$KC$9,IF(ROUNDUP(O13,0)=4,Cdel!$B$10:$KC$10,IF(ROUNDUP(O13,0)=3,Cdel!$B$11:$KC$11,IF(ROUNDUP(O13,0)=2,Cdel!$B$12:$KC$12,IF(ROUNDUP(O13,0)=1,Cdel!$B$13:$KC$13)))))))} -> 0.82171041 | ... DD13: {=DC13-_xlfn.XLOOKUP(DD$1,Cdel!$B$1:$KC$1,IF(ROUNDUP(DC13,0)=6,Cdel!$B$8:$KC$8,IF(ROUNDUP(DC13,0)=5,Cdel!$B$9:$KC$9,IF(ROUNDUP(DC13,0)=4,Cdel!$B$10:$KC$10,IF(ROUNDUP(DC13,0)=3,Cdel!$B$11:$KC$11,IF(ROUNDUP(DC13,0)=2,Cdel!$B$12:$KC$12,IF(ROUNDUP(DC13,0)=1,Cdel!$B$13:$KC$13)))))))} -> 0.062212841
... A389: P2337 | B389: PVC | C389: P2337 | D389: 0 | E389: 2000 | G389: =IF(ISNUMBER(F389),(YEAR(TODAY())-(F389)),YEAR(TODAY())-E389) -> 26 | H389: =_xlfn.LET( _xlpm.score,_xlfn.XLOOKUP(G389,DecayFns!$A$2:$A$289,DecayFns!$N$2:$N$289), IF(D389=1,IF(_xlpm.score=6,_xlpm.score,_xlpm.score+1),IF(_xlpm.score=1,_xlpm.score,_xlpm.score-1) )) -> 2 | I389: {=H389-_xlfn.XLOOKUP(I$1,Cdel!$B$1:$KC$1,IF(ROUNDUP(H389,0)=6,Cdel!$B$8:$KC$8,IF(ROUNDUP(H389,0)=5,Cdel!$B$9:$KC$9,IF(ROUNDUP(H389,0)=4,Cdel!$B$10:$KC$10,IF(ROUNDUP(H389,0)=3,Cdel!$B$11:$KC$11,IF(ROUNDUP(H389,0)=2,Cdel!$B$12:$KC$12,IF(ROUNDUP(H389,0)=1,Cdel!$B$13:$KC$13)))))))} -> 2 | J389: {=I389-_xlfn.XLOOKUP(J$1,Cdel!$B$1:$KC$1,IF(ROUNDUP(I389,0)=6,Cdel!$B$8:$KC$8,IF(ROUNDUP(I389,0)=5,Cdel!$B$9:$KC$9,IF(ROUNDUP(I389,0)=4,Cdel!$B$10:$KC$10,IF(ROUNDUP(I389,0)=3,Cdel!$B$11:$KC$11,IF(ROUNDUP(I389,0)=2,Cdel!$B$12:$KC$12,IF(ROUNDUP(I389,0)=1,Cdel!$B$13:$KC$13)))))))} -> 1.9446747 | K389: {=J389-_xlfn.XLOOKUP(K$1,Cdel!$B$1:$KC$1,IF(ROUNDUP(J389,0)=6,Cdel!$B$8:$KC$8,IF(ROUNDUP(J389,0)=5,Cdel!$B$9:$KC$9,IF(ROUNDUP(J389,0)=4,Cdel!$B$10:$KC$10,IF(ROUNDUP(J389,0)=3,Cdel!$B$11:$KC$11,IF(ROUNDUP(J389,0)=2,Cdel!$B$12:$KC$12,IF(ROUNDUP(J389,0)=1,Cdel!$B$13:$KC$13)))))))} -> 1.8908799 | L389: {=K389-_xlfn.XLOOKUP(L$1,Cdel!$B$1:$KC$1,IF(ROUNDUP(K389,0)=6,Cdel!$B$8:$KC$8,IF(ROUNDUP(K389,0)=5,Cdel!$B$9:$KC$9,IF(ROUNDUP(K389,0)=4,Cdel!$B$10:$KC$10,IF(ROUNDUP(K389,0)=3,Cdel!$B$11:$KC$11,IF(ROUNDUP(K389,0)=2,Cdel!$B$12:$KC$12,IF(ROUNDUP(K389,0)=1,Cdel!$B$13:$KC$13)))))))} -> 1.8385731 | M389: {=L389-_xlfn.XLOOKUP(M$1,Cdel!$B$1:$KC$1,IF(ROUNDUP(L389,0)=6,Cdel!$B$8:$KC$8,IF(ROUNDUP(L389,0)=5,Cdel!$B$9:$KC$9,IF(ROUNDUP(L389,0)=4,Cdel!$B$10:$KC$10,IF(ROUNDUP(L389,0)=3,Cdel!$B$11:$KC$11,IF(ROUNDUP(L389,0)=2,Cdel!$B$12:$KC$12,IF(ROUNDUP(L389,0)=1,Cdel!$B$13:$KC$13)))))))} -> 1.7877133 | N389: {=M389-_xlfn.XLOOKUP(N$1,Cdel!$B$1:$KC$1,IF(ROUNDUP(M389,0)=6,Cdel!$B$8:$KC$8,IF(ROUNDUP(M389,0)=5,Cdel!$B$9:$KC$9,IF(ROUNDUP(M389,0)=4,Cdel!$B$10:$KC$10,IF(ROUNDUP(M389,0)=3,Cdel!$B$11:$KC$11,IF(ROUNDUP(M389,0)=2,Cdel!$B$12:$KC$12,IF(ROUNDUP(M389,0)=1,Cdel!$B$13:$KC$13)))))))} -> 1.7382604 | O389: {=N389-_xlfn.XLOOKUP(O$1,Cdel!$B$1:$KC$1,IF(ROUNDUP(N389,0)=6,Cdel!$B$8:$KC$8,IF(ROUNDUP(N389,0)=5,Cdel!$B$9:$KC$9,IF(ROUNDUP(N389,0)=4,Cdel!$B$10:$KC$10,IF(ROUNDUP(N389,0)=3,Cdel!$B$11:$KC$11,IF(ROUNDUP(N389,0)=2,Cdel!$B$12:$KC$12,IF(ROUNDUP(N389,0)=1,Cdel!$B$13:$KC$13)))))))} -> 1.6901756 | P389: {=O389-_xlfn.XLOOKUP(P$1,Cdel!$B$1:$KC$1,IF(ROUNDUP(O389,0)=6,Cdel!$B$8:$KC$8,IF(ROUNDUP(O389,0)=5,Cdel!$B$9:$KC$9,IF(ROUNDUP(O389,0)=4,Cdel!$B$10:$KC$10,IF(ROUNDUP(O389,0)=3,Cdel!$B$11:$KC$11,IF(ROUNDUP(O389,0)=2,Cdel!$B$12:$KC$12,IF(ROUNDUP(O389,0)=1,Cdel!$B$13:$KC$13)))))))} -> 1.6434208 | ... DD389: {=DC389-_xlfn.XLOOKUP(DD$1,Cdel!$B$1:$KC$1,IF(ROUNDUP(DC389,0)=6,Cdel!$B$8:$KC$8,IF(ROUNDUP(DC389,0)=5,Cdel!$B$9:$KC$9,IF(ROUNDUP(DC389,0)=4,Cdel!$B$10:$KC$10,IF(ROUNDUP(DC389,0)=3,Cdel!$B$11:$KC$11,IF(ROUNDUP(DC389,0)=2,Cdel!$B$12:$KC$12,IF(ROUNDUP(DC389,0)=1,Cdel!$B$13:$KC$13)))))))} -> 0.55814726

Sheet Cdel
A1: Year (t) | B1: 0 | C1: =B1+1 -> 1 | D1: =C1+1 -> 2 | E1: =D1+1 -> 3 | F1: =E1+1 -> 4 | G1: =F1+1 -> 5 | H1: =G1+1 -> 6 | I1: =H1+1 -> 7 | J1: =I1+1 -> 8 | ... KC1: =KB1+1 -> 287
A2: Condition(t_0) | B2: =N$18*EXP(-N$20*B$1) -> 6 | C2: =N$18*EXP(-N$20*C$1) -> 5.8340241 | D2: =N$18*EXP(-N$20*D$1) -> 5.6726396 | E2: =N$18*EXP(-N$20*E$1) -> 5.5157194 | F2: =N$18*EXP(-N$20*F$1) -> 5.36314 | G2: =N$18*EXP(-N$20*G$1) -> 5.2147813 | H2: =N$18*EXP(-N$20*H$1) -> 5.0705267 | I2: =N$18*EXP(-N$20*I$1) -> 4.9302625 | J2: =N$18*EXP(-N$20*J$1) -> 4.7938784 | K2: =N$18*EXP(-N$20*K$1) -> 4.661267 | L2: =N$18*EXP(-N$20*L$1) -> 4.532324 | M2: =N$18*EXP(-N$20*M$1) -> 4.4069479 | N2: =N$18*EXP(-N$20*N$1) -> 4.2850401 | O2: =N$18*EXP(-N$20*O$1) -> 4.1665046 | P2: =N$18*EXP(-N$20*P$1) -> 4.051248 | Q2: =N$18*EXP(-N$20*Q$1) -> 3.9391798 | R2: =N$18*EXP(-N$20*R$1) -> 3.8302116 | S2: =N$18*EXP(-N$20*S$1) -> 3.7242578 | T2: =N$18*EXP(-N$20*T$1) -> 3.621235 | U2: =N$18*EXP(-N$20*U$1) -> 3.5210621 | V2: =N$18*EXP(-N$20*V$1) -> 3.4236602 | W2: =N$18*EXP(-N$20*W$1) -> 3.3289527 | X2: =N$18*EXP(-N$20*X$1) -> 3.236865 | Y2: =N$18*EXP(-N$20*Y$1) -> 3.1473248 | Z2: =N$18*EXP(-N$20*Z$1) -> 3.0602614 | AA2: =N$18*EXP(-N$20*AA$1) -> 2.9756065 | AB2: =N$18*EXP(-N$20*AB$1) -> 2.8932934 | AC2: =N$18*EXP(-N$20*AC$1) -> 2.8132572 | AD2: =N$18*EXP(-N$20*AD$1) -> 2.7354351 | AE2: =N$18*EXP(-N$20*AE$1) -> 2.6597657 | AF2: =N$18*EXP(-N$20*AF$1) -> 2.5861895 | AG2: =N$18*EXP(-N$20*AG$1) -> 2.5146487 | AH2: =N$18*EXP(-N$20*AH$1) -> 2.4450869 | AI2: =N$18*EXP(-N$20*AI$1) -> 2.3774493 | AJ2: =N$18*EXP(-N$20*AJ$1) -> 2.3116827 | AK2: =N$18*EXP(-N$20*AK$1) -> 2.2477355 | AL2: =N$18*EXP(-N$20*AL$1) -> 2.1855572 | AM2: =N$18*EXP(-N$20*AM$1) -> 2.1250989 | AN2: =N$18*EXP(-N$20*AN$1) -> 2.066313 | AO2: =N$18*EXP(-N$20*AO$1) -> 2.0091533 | AP2: =N$18*EXP(-N$20*AP$1) -> 1.9535748 | AQ2: =N$18*EXP(-N$20*AQ$1) -> 1.8995338 | AR2: =N$18*EXP(-N$20*AR$1) -> 1.8469877 | AS2: =N$18*EXP(-N$20*AS$1) -> 1.7958951 | AT2: =N$18*EXP(-N$20*AT$1) -> 1.7462159 | AU2: =N$18*EXP(-N$20*AU$1) -> 1.6979109 | AV2: =N$18*EXP(-N$20*AV$1) -> 1.6509422 | AW2: =N$18*EXP(-N$20*AW$1) -> 1.6052728 | AX2: =N$18*EXP(-N$20*AX$1) -> 1.5608667 | AY2: =N$18*EXP(-N$20*AY$1) -> 1.517689 | AZ2: =N$18*EXP(-N$20*AZ$1) -> 1.4757057 | BA2: =N$18*EXP(-N$20*BA$1) -> 1.4348838 | BB2: =N$18*EXP(-N$20*BB$1) -> 1.3951911 | BC2: =N$18*EXP(-N$20*BC$1) -> 1.3565964 | BD2: =N$18*EXP(-N$20*BD$1) -> 1.3190694 | BE2: =N$18*EXP(-N$20*BE$1) -> 1.2825804 | BF2: =N$18*EXP(-N$20*BF$1) -> 1.2471008 | BG2: =N$18*EXP(-N$20*BG$1) -> 1.2126027 | BH2: =N$18*EXP(-N$20*BH$1) -> 1.1790589 | BI2: =N$18*EXP(-N$20*BI$1) -> 1.146443 | BJ2: =N$18*EXP(-N$20*BJ$1) -> 1.1147294 | BK2: =N$18*EXP(-N$20*BK$1) -> 1.083893 | BL2: =N$18*EXP(-N$20*BL$1) -> 1.0539097 | BM2: =N$18*EXP(-N$20*BM$1) -> 1.0247557 | BN2: =N$18*EXP(-N$20*BN$1) -> 0.99640829 | BO2: =N$18*EXP(-N$20*BO$1) -> 0.968845 | BP2: =N$18*EXP(-N$20*BP$1) -> 0.94204418 | BQ2: =N$18*EXP(-N$20*BQ$1) -> 0.91598475 | BR2: =N$18*EXP(-N$20*BR$1) -> 0.89064619 | BS2: =N$18*EXP(-N$20*BS$1) -> 0.86600856 | BT2: =N$18*EXP(-N$20*BT$1) -> 0.84205247 | BU2: =N$18*EXP(-N$20*BU$1) -> 0.81875907 | BV2: =N$18*EXP(-N$20*BV$1) -> 0.79611003 | BW2: =N$18*EXP(-N$20*BW$1) -> 0.77408752 | BX2: =N$18*EXP(-N$20*BX$1) -> 0.75267421 | BY2: =N$18*EXP(-N$20*BY$1) -> 0.73185325 | BZ2: =N$18*EXP(-N$20*BZ$1) -> 0.71160825 | CA2: =N$18*EXP(-N$20*CA$1) -> 0.69192328 | CB2: =N$18*EXP(-N$20*CB$1) -> 0.67278285 | CC2: =N$18*EXP(-N$20*CC$1) -> 0.6541719 | CD2: =N$18*EXP(-N$20*CD$1) -> 0.63607577 | CE2: =N$18*EXP(-N$20*CE$1) -> 0.61848023 | CF2: =N$18*EXP(-N$20*CF$1) -> 0.60137143 | CG2: =N$18*EXP(-N$20*CG$1) -> 0.58473591 | CH2: =N$18*EXP(-N$20*CH$1) -> 0.56856056 | CI2: =N$18*EXP(-N$20*CI$1) -> 0.55283267 | CJ2: =N$18*EXP(-N$20*CJ$1) -> 0.53753986 | CK2: =N$18*EXP(-N$20*CK$1) -> 0.52267008 | CL2: =N$18*EXP(-N$20*CL$1) -> 0.50821165 | CM2: =N$18*EXP(-N$20*CM$1) -> 0.49415317 | CN2: =N$18*EXP(-N$20*CN$1) -> 0.48048358 | CO2: =N$18*EXP(-N$20*CO$1) -> 0.46719214 | CP2: =N$18*EXP(-N$20*CP$1) -> 0.45426837 | CQ2: =N$18*EXP(-N$20*CQ$1) -> 0.4417021 | CR2: =N$18*EXP(-N$20*CR$1) -> 0.42948345 | CS2: =N$18*EXP(-N$20*CS$1) -> 0.4176028 | CT2: =N$18*EXP(-N$20*CT$1) -> 0.4060508 | CU2: =N$18*EXP(-N$20*CU$1) -> 0.39481836 | CV2: =N$18*EXP(-N$20*CV$1) -> 0.38389664 | CW2: =N$18*EXP(-N$20*CW$1) -> 0.37327705 | CX2: =N$18*EXP(-N$20*CX$1) -> 0.36295121 | CY2: =N$18*EXP(-N$20*CY$1) -> 0.35291102 | CZ2: =N$18*EXP(-N$20*CZ$1) -> 0.34314857 | DA2: =N$18*EXP(-N$20*DA$1) -> 0.33365617 | DB2: =N$18*EXP(-N$20*DB$1) -> 0.32442636 | DC2: =N$18*EXP(-N$20*DC$1) -> 0.31545187 | DD2: =N$18*EXP(-N$20*DD$1) -> 0.30672564 | DE2: =N$18*EXP(-N$20*DE$1) -> 0.29824079 | DF2: =N$18*EXP(-N$20*DF$1) -> 0.28999066 | DG2: =N$18*EXP(-N$20*DG$1) -> 0.28196875 | DH2: =N$18*EXP(-N$20*DH$1) -> 0.27416875 | DI2: =N$18*EXP(-N$20*DI$1) -> 0.26658452 | DJ2: =N$18*EXP(-N$20*DJ$1) -> 0.25921009 | DK2: =N$18*EXP(-N$20*DK$1) -> 0.25203965 | DL2: =N$18*EXP(-N$20*DL$1) -> 0.24506756 | DM2: =N$18*EXP(-N$20*DM$1) -> 0.23828835 | DN2: =N$18*EXP(-N$20*DN$1) -> 0.23169666 | DO2: =N$18*EXP(-N$20*DO$1) -> 0.22528732 | DP2: =N$18*EXP(-N$20*DP$1) -> 0.21905527 | DQ2: =N$18*EXP(-N$20*DQ$1) -> 0.21299563 | DR2: =N$18*EXP(-N$20*DR$1) -> 0.2071036 | DS2: =N$18*EXP(-N$20*DS$1) -> 0.20137457 | DT2: =N$18*EXP(-N$20*DT$1) -> 0.19580402 | DU2: =N$18*EXP(-N$20*DU$1) -> 0.19038756 | DV2: =N$18*EXP(-N$20*DV$1) -> 0.18512093 | DW2: =N$18*EXP(-N$20*DW$1) -> 0.18 | DX2: =N$18*EXP(-N$20*DX$1) -> 0.17502072 | DY2: =N$18*EXP(-N$20*DY$1) -> 0.17017919 | DZ2: =N$18*EXP(-N$20*DZ$1) -> 0.16547158 | EA2: =N$18*EXP(-N$20*EA$1) -> 0.1608942 | EB2: =N$18*EXP(-N$20*EB$1) -> 0.15644344 | EC2: =N$18*EXP(-N$20*EC$1) -> 0.1521158 | ED2: =N$18*EXP(-N$20*ED$1) -> 0.14790787 | EE2: =N$18*EXP(-N$20*EE$1) -> 0.14381635 | EF2: =N$18*EXP(-N$20*EF$1) -> 0.13983801 | EG2: =N$18*EXP(-N$20*EG$1) -> 0.13596972 | EH2: =N$18*EXP(-N$20*EH$1) -> 0.13220844 | EI2: =N$18*EXP(-N$20*EI$1) -> 0.1285512 | EJ2: =N$18*EXP(-N$20*EJ$1) -> 0.12499514 | EK2: =N$18*EXP(-N$20*EK$1) -> 0.12153744 | EL2: =N$18*EXP(-N$20*EL$1) -> 0.11817539 | EM2: =N$18*EXP(-N$20*EM$1) -> 0.11490635 | EN2: =N$18*EXP(-N$20*EN$1) -> 0.11172774 | EO2: =N$18*EXP(-N$20*EO$1) -> 0.10863705 | EP2: =N$18*EXP(-N$20*EP$1) -> 0.10563186 | EQ2: =N$18*EXP(-N$20*EQ$1) -> 0.10270981 | ER2: =N$18*EXP(-N$20*ER$1) -> 0.09986858 | ES2: =N$18*EXP(-N$20*ES$1) -> 0.097105951 | ET2: =N$18*EXP(-N$20*ET$1) -> 0.094419743 | EU2: =N$18*EXP(-N$20*EU$1) -> 0.091807843 | EV2: =N$18*EXP(-N$20*EV$1) -> 0.089268196 | EW2: =N$18*EXP(-N$20*EW$1) -> 0.086798801 | EX2: =N$18*EXP(-N$20*EX$1) -> 0.084397716 | EY2: =N$18*EXP(-N$20*EY$1) -> 0.082063052 | EZ2: =N$18*EXP(-N$20*EZ$1) -> 0.079792971 | FA2: =N$18*EXP(-N$20*FA$1) -> 0.077585686 | FB2: =N$18*EXP(-N$20*FB$1) -> 0.075439461 | FC2: =N$18*EXP(-N$20*FC$1) -> 0.073352606 | FD2: =N$18*EXP(-N$20*FD$1) -> 0.071323479 | FE2: =N$18*EXP(-N$20*FE$1) -> 0.069350482 | FF2: =N$18*EXP(-N$20*FF$1) -> 0.067432065 | FG2: =N$18*EXP(-N$20*FG$1) -> 0.065566715 | FH2: =N$18*EXP(-N$20*FH$1) -> 0.063752966 | FI2: =N$18*EXP(-N$20*FI$1) -> 0.061989391 | FJ2: =N$18*EXP(-N$20*FJ$1) -> 0.0602746 | FK2: =N$18*EXP(-N$20*FK$1) -> 0.058607245 | FL2: =N$18*EXP(-N$20*FL$1) -> 0.056986014 | FM2: =N$18*EXP(-N$20*FM$1) -> 0.05540963 | FN2: =N$18*EXP(-N$20*FN$1) -> 0.053876853 | FO2: =N$18*EXP(-N$20*FO$1) -> 0.052386476 | FP2: =N$18*EXP(-N$20*FP$1) -> 0.050937328 | FQ2: =N$18*EXP(-N$20*FQ$1) -> 0.049528266 | FR2: =N$18*EXP(-N$20*FR$1) -> 0.048158183 | FS2: =N$18*EXP(-N$20*FS$1) -> 0.046826001 | FT2: =N$18*EXP(-N$20*FT$1) -> 0.04553067 | FU2: =N$18*EXP(-N$20*FU$1) -> 0.044271171 | FV2: =N$18*EXP(-N$20*FV$1) -> 0.043046513 | FW2: =N$18*EXP(-N$20*FW$1) -> 0.041855733 | FX2: =N$18*EXP(-N$20*FX$1) -> 0.040697892 | FY2: =N$18*EXP(-N$20*FY$1) -> 0.039572081 | FZ2: =N$18*EXP(-N$20*FZ$1) -> 0.038477412 | GA2: =N$18*EXP(-N$20*GA$1) -> 0.037413025 | GB2: =N$18*EXP(-N$20*GB$1) -> 0.036378082 | GC2: =N$18*EXP(-N$20*GC$1) -> 0.035371768 | GD2: =N$18*EXP(-N$20*GD$1) -> 0.034393291 | GE2: =N$18*EXP(-N$20*GE$1) -> 0.033441882 | GF2: =N$18*EXP(-N$20*GF$1) -> 0.032516791 | GG2: =N$18*EXP(-N$20*GG$1) -> 0.03161729 | GH2: =N$18*EXP(-N$20*GH$1) -> 0.030742672 | GI2: =N$18*EXP(-N$20*GI$1) -> 0.029892249 | GJ2: =N$18*EXP(-N$20*GJ$1) -> 0.02906535 | GK2: =N$18*EXP(-N$20*GK$1) -> 0.028261326 | GL2: =N$18*EXP(-N$20*GL$1) -> 0.027479542 | GM2: =N$18*EXP(-N$20*GM$1) -> 0.026719386 | GN2: =N$18*EXP(-N$20*GN$1) -> 0.025980257 | GO2: =N$18*EXP(-N$20*GO$1) -> 0.025261574 | GP2: =N$18*EXP(-N$20*GP$1) -> 0.024562772 | GQ2: =N$18*EXP(-N$20*GQ$1) -> 0.023883301 | GR2: =N$18*EXP(-N$20*GR$1) -> 0.023222625 | GS2: =N$18*EXP(-N$20*GS$1) -> 0.022580226 | GT2: =N$18*EXP(-N$20*GT$1) -> 0.021955597 | GU2: =N$18*EXP(-N$20*GU$1) -> 0.021348247 | GV2: =N$18*EXP(-N$20*GV$1) -> 0.020757698 | GW2: =N$18*EXP(-N$20*GW$1) -> 0.020183486 | GX2: =N$18*EXP(-N$20*GX$1) -> 0.019625157 | GY2: =N$18*EXP(-N$20*GY$1) -> 0.019082273 | GZ2: =N$18*EXP(-N$20*GZ$1) -> 0.018554407 | HA2: =N$18*EXP(-N$20*HA$1) -> 0.018041143 | HB2: =N$18*EXP(-N$20*HB$1) -> 0.017542077 | HC2: =N$18*EXP(-N$20*HC$1) -> 0.017056817 | HD2: =N$18*EXP(-N$20*HD$1) -> 0.01658498 | HE2: =N$18*EXP(-N$20*HE$1) -> 0.016126196 | HF2: =N$18*EXP(-N$20*HF$1) -> 0.015680103 | HG2: =N$18*EXP(-N$20*HG$1) -> 0.015246349 | HH2: =N$18*EXP(-N$20*HH$1) -> 0.014824595 | HI2: =N$18*EXP(-N$20*HI$1) -> 0.014414508 | HJ2: =N$18*EXP(-N$20*HJ$1) -> 0.014015764 | HK2: =N$18*EXP(-N$20*HK$1) -> 0.013628051 | HL2: =N$18*EXP(-N$20*HL$1) -> 0.013251063 | HM2: =N$18*EXP(-N$20*HM$1) -> 0.012884504 | HN2: =N$18*EXP(-N$20*HN$1) -> 0.012528084 | HO2: =N$18*EXP(-N$20*HO$1) -> 0.012181524 | HP2: =N$18*EXP(-N$20*HP$1) -> 0.011844551 | HQ2: =N$18*EXP(-N$20*HQ$1) -> 0.011516899 | HR2: =N$18*EXP(-N$20*HR$1) -> 0.011198311 | HS2: =N$18*EXP(-N$20*HS$1) -> 0.010888536 | HT2: =N$18*EXP(-N$20*HT$1) -> 0.010587331 | HU2: =N$18*EXP(-N$20*HU$1) -> 0.010294457 | HV2: =N$18*EXP(-N$20*HV$1) -> 0.010009685 | HW2: =N$18*EXP(-N$20*HW$1) -> 0.0097327908 | HX2: =N$18*EXP(-N$20*HX$1) -> 0.0094635561 | HY2: =N$18*EXP(-N$20*HY$1) -> 0.0092017691 | HZ2: =N$18*EXP(-N$20*HZ$1) -> 0.0089472238 | IA2: =N$18*EXP(-N$20*IA$1) -> 0.0086997199 | IB2: =N$18*EXP(-N$20*IB$1) -> 0.0084590626 | IC2: =N$18*EXP(-N$20*IC$1) -> 0.0082250625 | ID2: =N$18*EXP(-N$20*ID$1) -> 0.0079975356 | IE2: =N$18*EXP(-N$20*IE$1) -> 0.0077763026 | IF2: =N$18*EXP(-N$20*IF$1) -> 0.0075611894 | IG2: =N$18*EXP(-N$20*IG$1) -> 0.0073520269 | IH2: =N$18*EXP(-N$20*IH$1) -> 0.0071486504 | II2: =N$18*EXP(-N$20*II$1) -> 0.0069508998 | IJ2: =N$18*EXP(-N$20*IJ$1) -> 0.0067586195 | IK2: =N$18*EXP(-N$20*IK$1) -> 0.0065716582 | IL2: =N$18*EXP(-N$20*IL$1) -> 0.0063898688 | IM2: =N$18*EXP(-N$20*IM$1) -> 0.0062131081 | IN2: =N$18*EXP(-N$20*IN$1) -> 0.0060412371 | IO2: =N$18*EXP(-N$20*IO$1) -> 0.0058741205 | IP2: =N$18*EXP(-N$20*IP$1) -> 0.0057116268 | IQ2: =N$18*EXP(-N$20*IQ$1) -> 0.005553628 | IR2: =N$18*EXP(-N$20*IR$1) -> 0.0054 | IS2: =N$18*EXP(-N$20*IS$1) -> 0.0052506217 | IT2: =N$18*EXP(-N$20*IT$1) -> 0.0051053756 | IU2: =N$18*EXP(-N$20*IU$1) -> 0.0049641474 | IV2: =N$18*EXP(-N$20*IV$1) -> 0.004826826 | IW2: =N$18*EXP(-N$20*IW$1) -> 0.0046933032 | IX2: =N$18*EXP(-N$20*IX$1) -> 0.004563474 | IY2: =N$18*EXP(-N$20*IY$1) -> 0.0044372362 | IZ2: =N$18*EXP(-N$20*IZ$1) -> 0.0043144905 | JA2: =N$18*EXP(-N$20*JA$1) -> 0.0041951403 | JB2: =N$18*EXP(-N$20*JB$1) -> 0.0040790916 | JC2: =N$18*EXP(-N$20*JC$1) -> 0.0039662532 | JD2: =N$18*EXP(-N$20*JD$1) -> 0.0038565361 | JE2: =N$18*EXP(-N$20*JE$1) -> 0.0037498541 | JF2: =N$18*EXP(-N$20*JF$1) -> 0.0036461232 | JG2: =N$18*EXP(-N$20*JG$1) -> 0.0035452618 | JH2: =N$18*EXP(-N$20*JH$1) -> 0.0034471905 | JI2: =N$18*EXP(-N$20*JI$1) -> 0.0033518321 | JJ2: =N$18*EXP(-N$20*JJ$1) -> 0.0032591115 | JK2: =N$18*EXP(-N$20*JK$1) -> 0.0031689559 | JL2: =N$18*EXP(-N$20*JL$1) -> 0.0030812942 | JM2: =N$18*EXP(-N$20*JM$1) -> 0.0029960574 | JN2: =N$18*EXP(-N$20*JN$1) -> 0.0029131785 | JO2: =N$18*EXP(-N$20*JO$1) -> 0.0028325923 | JP2: =N$18*EXP(-N$20*JP$1) -> 0.0027542353 | JQ2: =N$18*EXP(-N$20*JQ$1) -> 0.0026780459 | JR2: =N$18*EXP(-N$20*JR$1) -> 0.002603964 | JS2: =N$18*EXP(-N$20*JS$1) -> 0.0025319315 | JT2: =N$18*EXP(-N$20*JT$1) -> 0.0024618916 | JU2: =N$18*EXP(-N$20*JU$1) -> 0.0023937891 | JV2: =N$18*EXP(-N$20*JV$1) -> 0.0023275706 | JW2: =N$18*EXP(-N$20*JW$1) -> 0.0022631838 | JX2: =N$18*EXP(-N$20*JX$1) -> 0.0022005782 | JY2: =N$18*EXP(-N$20*JY$1) -> 0.0021397044 | JZ2: =N$18*EXP(-N$20*JZ$1) -> 0.0020805145 | KA2: =N$18*EXP(-N$20*KA$1) -> 0.0020229619 | KB2: =N$18*EXP(-N$20*KB$1) -> 0.0019670015 | KC2: =N$18*EXP(-N$20*KC$1) -> 0.001912589
